[{"timeToSleep":0,"data":{"e":"depthUpdate","E":1672242115715,"s":"TORNBUSD","U":113354265,"u":113354265,"b":[["4.25000000","2385.62000000"]],"a":[]}},{"timeToSleep":272,"data":{"lastUpdateId":113354265,"bids":[["4.34000000","2.22000000"],["4.33000000","17.46000000"],["4.32000000","10.46000000"],["4.31000000","55.81000000"],["4.30000000","163.32000000"],["4.29000000","475.45000000"],["4.28000000","1296.31000000"],["4.27000000","680.43000000"],["4.26000000","450.07000000"],["4.25000000","2385.62000000"],["4.24000000","346.06000000"],["4.23000000","827.29000000"],["4.22000000","1230.90000000"],["4.21000000","1476.80000000"],["4.20000000","1254.54000000"],["4.19000000","506.80000000"],["4.18000000","1047.07000000"],["4.17000000","180.30000000"],["4.16000000","297.45000000"],["4.15000000","1042.57000000"],["4.14000000","244.28000000"],["4.13000000","759.89000000"],["4.12000000","2020.84000000"],["4.11000000","397.37000000"],["4.10000000","1259.64000000"],["4.09000000","66.02000000"],["4.08000000","120.42000000"],["4.07000000","319.79000000"],["4.06000000","787.70000000"],["4.05000000","3932.72000000"],["4.04000000","285.68000000"],["4.03000000","549.14000000"],["4.02000000","105.01000000"],["4.01000000","308.36000000"],["4.00000000","26299.03000000"],["3.99000000","948.41000000"],["3.98000000","536.38000000"],["3.97000000","3313.99000000"],["3.96000000","23.34000000"],["3.95000000","1017.59000000"],["3.94000000","69.95000000"],["3.93000000","1339.05000000"],["3.92000000","1567.04000000"],["3.91000000","512.85000000"],["3.90000000","5030.23000000"],["3.89000000","128.56000000"],["3.88000000","553.61000000"],["3.87000000","3236.75000000"],["3.86000000","523.12000000"],["3.85000000","1144.32000000"],["3.84000000","304.61000000"],["3.83000000","1694.49000000"],["3.82000000","994.09000000"],["3.81000000","46.02000000"],["3.80000000","2803.39000000"],["3.79000000","253.67000000"],["3.78000000","338.04000000"],["3.77000000","173.66000000"],["3.76000000","294.79000000"],["3.75000000","270.68000000"],["3.74000000","288.99000000"],["3.73000000","1177.75000000"],["3.72000000","552.84000000"],["3.71000000","328.23000000"],["3.70000000","1442.17000000"],["3.69000000","25.71000000"],["3.68000000","17.04000000"],["3.67000000","104.66000000"],["3.66000000","891.14000000"],["3.65000000","2155.13000000"],["3.64000000","34.46000000"],["3.63000000","95.00000000"],["3.62000000","1902.06000000"],["3.61000000","12.38000000"],["3.60000000","958.21000000"],["3.59000000","23.22000000"],["3.58000000","2081.57000000"],["3.57000000","62.64000000"],["3.56000000","875.01000000"],["3.55000000","1195.88000000"],["3.54000000","30.89000000"],["3.53000000","1114.30000000"],["3.52000000","341.23000000"],["3.51000000","26.85000000"],["3.50000000","3995.12000000"],["3.49000000","22.46000000"],["3.48000000","49.68000000"],["3.47000000","5.81000000"],["3.46000000","13.84000000"],["3.45000000","1107.65000000"],["3.44000000","103.56000000"],["3.43000000","76.56000000"],["3.42000000","192.71000000"],["3.41000000","5043.20000000"],["3.40000000","2560.04000000"],["3.39000000","10.82000000"],["3.38000000","46.99000000"],["3.37000000","308.59000000"],["3.36000000","66.84000000"],["3.35000000","2327.79000000"],["3.34000000","293.77000000"],["3.33000000","3469.06000000"],["3.32000000","13.15000000"],["3.31000000","485.73000000"],["3.30000000","2369.96000000"],["3.29000000","28.05000000"],["3.27000000","22.17000000"],["3.26000000","18.60000000"],["3.25000000","368.19000000"],["3.24000000","26.73000000"],["3.23000000","896.59000000"],["3.22000000","68.41000000"],["3.21000000","28.83000000"],["3.20000000","393.27000000"],["3.19000000","19.16000000"],["3.18000000","9.32000000"],["3.17000000","15.11000000"],["3.16000000","9.84000000"],["3.15000000","629.77000000"],["3.14000000","76.52000000"],["3.13000000","13.91000000"],["3.12000000","20.76000000"],["3.11000000","9.83000000"],["3.10000000","373.95000000"],["3.08000000","38.62000000"],["3.07000000","18.27000000"],["3.06000000","15.40000000"],["3.05000000","35.62000000"],["3.03000000","15.81000000"],["3.02000000","23.07000000"],["3.01000000","10.16000000"],["3.00000000","1684.70000000"],["2.99000000","16.02000000"],["2.97000000","14.20000000"],["2.96000000","19.16000000"],["2.95000000","11.71000000"],["2.94000000","20.20000000"],["2.92000000","3.91000000"],["2.91000000","9.66000000"],["2.90000000","50.85000000"],["2.89000000","3.91000000"],["2.86000000","20.66000000"],["2.85000000","103.49000000"],["2.84000000","3.91000000"],["2.83000000","9.42000000"],["2.82000000","16.99000000"],["2.81000000","3.91000000"],["2.80000000","28.97000000"],["2.78000000","3.91000000"],["2.77000000","28.29000000"],["2.76000000","3.91000000"],["2.75000000","155.46000000"],["2.73000000","21.46000000"],["2.70000000","25.70000000"],["2.68000000","437.78000000"],["2.65000000","33.62000000"],["2.62000000","3.91000000"],["2.60000000","189.25000000"],["2.59000000","10.26000000"],["2.55000000","11.71000000"],["2.51000000","3.99000000"],["2.50000000","9023.23000000"],["2.45000000","11.71000000"],["2.43000000","4.20000000"],["2.40000000","11.71000000"],["2.39000000","9.20000000"],["2.35000000","11.71000000"],["2.30000000","11.71000000"],["2.25000000","56.15000000"],["2.23000000","30.48000000"],["2.21000000","19.88000000"],["2.20000000","11.71000000"],["2.15000000","11.71000000"],["2.12000000","4.72000000"],["2.10000000","11.71000000"],["2.05000000","11.71000000"],["2.00000000","1879.21000000"],["1.98000000","5.06000000"],["1.86000000","304.08000000"],["1.84000000","5.44000000"],["1.77000000","56.52000000"],["1.76000000","5.69000000"],["1.75000000","72.90000000"],["1.60000000","6.25000000"],["1.56000000","26.33000000"],["1.50000000","267.20000000"],["1.33000000","7.54000000"],["1.25000000","8.01000000"],["1.21000000","8.72000000"],["1.20000000","95.04000000"],["1.12000000","8.93000000"],["1.11000000","2702.68000000"],["1.06000000","9433.98000000"],["1.03000000","282.52000000"],["1.01000000","1116.87000000"],["1.00000000","852.20000000"],["0.95000000","10.53000000"],["0.77000000","1677.06000000"],["0.73000000","13.71000000"],["0.72000000","15.88000000"],["0.70000000","14.30000000"]],"asks":[["4.35000000","346.98000000"],["4.36000000","356.16000000"],["4.37000000","657.40000000"],["4.38000000","481.57000000"],["4.39000000","273.07000000"],["4.40000000","132.30000000"],["4.41000000","136.57000000"],["4.42000000","365.68000000"],["4.43000000","637.13000000"],["4.44000000","343.14000000"],["4.45000000","420.40000000"],["4.46000000","255.53000000"],["4.47000000","442.85000000"],["4.48000000","938.94000000"],["4.49000000","580.64000000"],["4.50000000","1320.81000000"],["4.51000000","5062.52000000"],["4.52000000","3478.79000000"],["4.53000000","47.14000000"],["4.54000000","17.38000000"],["4.55000000","172.67000000"],["4.56000000","11.50000000"],["4.57000000","40.31000000"],["4.58000000","257.82000000"],["4.59000000","34.30000000"],["4.60000000","2148.81000000"],["4.61000000","158.66000000"],["4.62000000","216.01000000"],["4.63000000","184.80000000"],["4.64000000","450.86000000"],["4.65000000","93.78000000"],["4.66000000","395.81000000"],["4.67000000","118.20000000"],["4.68000000","123.92000000"],["4.69000000","5420.75000000"],["4.70000000","948.76000000"],["4.71000000","66.38000000"],["4.72000000","42.81000000"],["4.73000000","7160.97000000"],["4.74000000","113.99000000"],["4.75000000","1898.34000000"],["4.76000000","90.50000000"],["4.77000000","47.69000000"],["4.78000000","178.76000000"],["4.79000000","5104.38000000"],["4.80000000","187.85000000"],["4.81000000","58.27000000"],["4.82000000","26.49000000"],["4.83000000","216.89000000"],["4.84000000","1559.32000000"],["4.85000000","2635.23000000"],["4.86000000","1205.92000000"],["4.87000000","28.78000000"],["4.88000000","2856.13000000"],["4.89000000","1219.15000000"],["4.90000000","4574.34000000"],["4.91000000","47.24000000"],["4.92000000","54.69000000"],["4.93000000","159.93000000"],["4.94000000","169.20000000"],["4.95000000","9881.37000000"],["4.96000000","47.25000000"],["4.97000000","21.32000000"],["4.98000000","705.11000000"],["4.99000000","7637.17000000"],["5.00000000","5693.39000000"],["5.01000000","6.20000000"],["5.02000000","27.16000000"],["5.03000000","35.48000000"],["5.04000000","36.36000000"],["5.05000000","63.55000000"],["5.06000000","29.83000000"],["5.07000000","1164.14000000"],["5.08000000","13.74000000"],["5.09000000","27.55000000"],["5.10000000","2030.91000000"],["5.11000000","38.61000000"],["5.12000000","33.93000000"],["5.13000000","173.70000000"],["5.14000000","4.98000000"],["5.15000000","60.86000000"],["5.16000000","132.81000000"],["5.17000000","21.20000000"],["5.18000000","302.22000000"],["5.19000000","20.99000000"],["5.20000000","1113.92000000"],["5.21000000","4.20000000"],["5.22000000","41.98000000"],["5.23000000","61.73000000"],["5.24000000","16.31000000"],["5.25000000","228.03000000"],["5.26000000","9.75000000"],["5.27000000","47.06000000"],["5.28000000","86.83000000"],["5.29000000","853.22000000"],["5.30000000","411.05000000"],["5.32000000","311.89000000"],["5.33000000","8.86000000"],["5.34000000","70.55000000"],["5.35000000","248.03000000"],["5.36000000","144.84000000"],["5.37000000","72.50000000"],["5.38000000","11.20000000"],["5.39000000","26.73000000"],["5.40000000","2957.69000000"],["5.41000000","23.15000000"],["5.42000000","8.35000000"],["5.43000000","71.54000000"],["5.44000000","10094.19000000"],["5.45000000","475.91000000"],["5.46000000","109.29000000"],["5.47000000","436.08000000"],["5.48000000","155.63000000"],["5.49000000","41.44000000"],["5.50000000","7733.96000000"],["5.51000000","36.57000000"],["5.52000000","28.35000000"],["5.53000000","424.85000000"],["5.54000000","7.39000000"],["5.55000000","294.72000000"],["5.56000000","13.96000000"],["5.57000000","5222.01000000"],["5.58000000","30.10000000"],["5.59000000","9.08000000"],["5.60000000","1642.21000000"],["5.61000000","11.73000000"],["5.62000000","17.41000000"],["5.63000000","51.74000000"],["5.64000000","44.53000000"],["5.65000000","95.76000000"],["5.66000000","12.93000000"],["5.67000000","23.45000000"],["5.68000000","2.56000000"],["5.69000000","373.85000000"],["5.70000000","4349.57000000"],["5.71000000","354.18000000"],["5.72000000","32.16000000"],["5.73000000","6.32000000"],["5.74000000","46.94000000"],["5.75000000","38.80000000"],["5.76000000","391.20000000"],["5.77000000","43.37000000"],["5.78000000","13.39000000"],["5.79000000","24.69000000"],["5.80000000","1470.05000000"],["5.81000000","17.41000000"],["5.82000000","307.56000000"],["5.83000000","19.90000000"],["5.84000000","894.33000000"],["5.85000000","25.18000000"],["5.86000000","53.68000000"],["5.87000000","114.24000000"],["5.88000000","287.21000000"],["5.89000000","226.54000000"],["5.90000000","348.60000000"],["5.91000000","1172.54000000"],["5.93000000","29.46000000"],["5.94000000","52.54000000"],["5.95000000","612.76000000"],["5.96000000","682.56000000"],["5.97000000","32.84000000"],["5.98000000","573.31000000"],["5.99000000","1527.18000000"],["6.00000000","8409.02000000"],["6.01000000","17.47000000"],["6.02000000","17.41000000"],["6.03000000","10.56000000"],["6.04000000","17.41000000"],["6.05000000","48.73000000"],["6.06000000","5.00000000"],["6.07000000","17.41000000"],["6.09000000","22.82000000"],["6.10000000","63.14000000"],["6.11000000","17.41000000"],["6.12000000","61.39000000"],["6.13000000","705.74000000"],["6.14000000","19.06000000"],["6.15000000","148.91000000"],["6.16000000","234.70000000"],["6.17000000","48.73000000"],["6.18000000","19.06000000"],["6.19000000","2.92000000"],["6.20000000","1488.79000000"],["6.21000000","22.82000000"],["6.22000000","24.38000000"],["6.23000000","97.36000000"],["6.24000000","21.87000000"],["6.25000000","91.22000000"],["6.26000000","1.65000000"],["6.27000000","5.41000000"],["6.28000000","27.85000000"],["6.29000000","14.23000000"],["6.30000000","1743.42000000"],["6.31000000","3.11000000"],["6.32000000","25.32000000"],["6.33000000","35.41000000"],["6.34000000","1.65000000"],["6.35000000","243.51000000"],["6.36000000","50.00000000"],["6.37000000","17.41000000"],["6.38000000","1.65000000"],["6.39000000","340.45000000"],["6.40000000","1278.90000000"],["6.42000000","37.70000000"],["6.44000000","10017.41000000"],["6.45000000","596.75000000"],["6.46000000","262.58000000"],["6.47000000","22.07000000"],["6.48000000","12.17000000"],["6.49000000","231.72000000"],["6.50000000","3320.41000000"],["6.51000000","22.82000000"],["6.52000000","11.50000000"],["6.53000000","17.41000000"],["6.54000000","23.52000000"],["6.55000000","107.97000000"],["6.56000000","18.94000000"],["6.57000000","7.87000000"],["6.58000000","35.66000000"],["6.59000000","5.00000000"],["6.60000000","742.78000000"],["6.62000000","90.30000000"],["6.63000000","102.54000000"],["6.65000000","22.41000000"],["6.66000000","1790.81000000"],["6.67000000","17.41000000"],["6.69000000","86.10000000"],["6.70000000","1417.85000000"],["6.71000000","14.90000000"],["6.72000000","152.08000000"],["6.73000000","4.62000000"],["6.75000000","63.58000000"],["6.76000000","77.29000000"],["6.77000000","1.49000000"],["6.78000000","52.64000000"],["6.79000000","24.69000000"],["6.80000000","1139.83000000"],["6.81000000","5.41000000"],["6.83000000","1.62000000"],["6.84000000","572.52000000"],["6.85000000","265.94000000"],["6.86000000","17.49000000"],["6.87000000","88.62000000"],["6.88000000","228.00000000"],["6.89000000","38.56000000"],["6.90000000","546.67000000"],["6.91000000","63.83000000"],["6.92000000","7.97000000"],["6.93000000","5.41000000"],["6.95000000","64.42000000"],["6.96000000","8.47000000"],["6.97000000","2.37000000"],["6.98000000","83.05000000"],["6.99000000","278.88000000"],["7.00000000","5378.10000000"],["7.03000000","9.93000000"],["7.05000000","9.94000000"],["7.06000000","5.41000000"],["7.07000000","12.15000000"],["7.08000000","1.74000000"],["7.09000000","220.95000000"],["7.10000000","1378.19000000"],["7.11000000","217.94000000"],["7.12000000","5.41000000"],["7.15000000","46.13000000"],["7.18000000","5.41000000"],["7.20000000","2272.32000000"],["7.22000000","5.64000000"],["7.23000000","138.14000000"],["7.24000000","5.41000000"],["7.25000000","203.00000000"],["7.26000000","180.25000000"],["7.30000000","695.39000000"],["7.31000000","70.00000000"],["7.33000000","326.16000000"],["7.34000000","94.14000000"],["7.35000000","381.40000000"],["7.36000000","5.41000000"],["7.37000000","1.36000000"],["7.39000000","2010.12000000"],["7.40000000","502.61000000"],["7.41000000","6.71000000"],["7.42000000","5.41000000"],["7.44000000","110.02000000"],["7.45000000","221.41000000"],["7.46000000","3.00000000"],["7.47000000","62.58000000"],["7.48000000","7.41000000"],["7.49000000","645.22000000"],["7.50000000","4738.59000000"],["7.51000000","120.87000000"],["7.52000000","1.81000000"],["7.54000000","5.41000000"],["7.55000000","351.19000000"],["7.56000000","14.79000000"],["7.57000000","91.84000000"],["7.58000000","3.77000000"],["7.60000000","153.23000000"],["7.66000000","372.81000000"],["7.67000000","2609.86000000"],["7.69000000","2.60000000"],["7.70000000","110.38000000"],["7.72000000","5.41000000"],["7.75000000","10.00000000"],["7.76000000","10000.00000000"],["7.77000000","33.34000000"],["7.78000000","131.41000000"],["7.79000000","5.69000000"],["7.80000000","621.15000000"],["7.82000000","1.92000000"],["7.84000000","5.41000000"],["7.87000000","17.88000000"],["7.88000000","15.00000000"],["7.89000000","1830.74000000"],["7.90000000","464.64000000"],["7.91000000","28.00000000"],["7.93000000","7.29000000"],["7.94000000","253.97000000"],["7.95000000","44.11000000"],["7.96000000","5.41000000"],["7.97000000","837.53000000"],["7.98000000","3.82000000"],["7.99000000","243.98000000"],["8.00000000","7215.28000000"],["8.03000000","5.41000000"],["8.04000000","96.48000000"],["8.06000000","2.20000000"],["8.09000000","5.41000000"],["8.10000000","256.94000000"],["8.12000000","3.84000000"],["8.15000000","6.65000000"],["8.16000000","509.96000000"],["8.17000000","1651.74000000"],["8.18000000","62.25000000"],["8.19000000","11.57000000"],["8.20000000","195.68000000"],["8.21000000","41.63000000"],["8.22000000","38.63000000"],["8.24000000","504.30000000"],["8.25000000","199.20000000"],["8.27000000","107.85000000"],["8.30000000","350.98000000"],["8.32000000","4.80000000"],["8.33000000","13.38000000"],["8.35000000","41.91000000"],["8.37000000","6.00000000"],["8.38000000","78.00000000"],["8.39000000","1075.91000000"],["8.40000000","3095.15000000"],["8.41000000","10.50000000"],["8.42000000","15.68000000"],["8.43000000","5.79000000"],["8.44000000","20.00000000"],["8.45000000","11.74000000"],["8.46000000","118.92000000"],["8.47000000","13.49000000"],["8.48000000","40.06000000"],["8.49000000","82.85000000"],["8.50000000","1725.80000000"],["8.51000000","7.19000000"],["8.54000000","1.77000000"],["8.55000000","10169.93000000"],["8.57000000","5.41000000"],["8.58000000","7.42000000"],["8.60000000","1.18000000"],["8.63000000","5.41000000"],["8.65000000","11.57000000"],["8.69000000","5.41000000"],["8.70000000","11.49000000"],["8.75000000","34.51000000"],["8.78000000","38.00000000"],["8.79000000","4.00000000"],["8.80000000","2181.72000000"],["8.81000000","5.41000000"],["8.84000000","1.43000000"],["8.87000000","5.41000000"],["8.88000000","111.71000000"],["8.89000000","315.34000000"],["8.90000000","178.85000000"],["8.91000000","2.25000000"],["8.93000000","5.41000000"],["8.94000000","657.78000000"],["8.95000000","16.94000000"],["8.97000000","2.00000000"],["8.98000000","3.34000000"],["8.99000000","279.44000000"],["9.00000000","9330.78000000"],["9.04000000","1.11000000"],["9.05000000","1.11000000"],["9.07000000","60.00000000"],["9.10000000","2770.13000000"],["9.11000000","107.78000000"],["9.14000000","13.89000000"],["9.18000000","9.30000000"],["9.20000000","107.71000000"],["9.25000000","160.49000000"],["9.26000000","54.22000000"],["9.28000000","3.14000000"],["9.30000000","2761.26000000"],["9.32000000","359.20000000"],["9.37000000","10.96000000"],["9.39000000","6.00000000"],["9.40000000","185.04000000"],["9.41000000","30.00000000"],["9.44000000","200.00000000"],["9.45000000","2335.73000000"],["9.46000000","2.92000000"],["9.47000000","4.57000000"],["9.48000000","256.76000000"],["9.50000000","87.92000000"],["9.51000000","27.57000000"],["9.52000000","6.28000000"],["9.53000000","47.23000000"],["9.54000000","5.14000000"],["9.60000000","115.35000000"],["9.64000000","17.33000000"],["9.66000000","299.89000000"],["9.68000000","290.89000000"],["9.70000000","41.46000000"],["9.71000000","245.81000000"],["9.73000000","6.92000000"],["9.75000000","17.02000000"],["9.76000000","5.12000000"],["9.78000000","10000.00000000"],["9.79000000","7.03000000"],["9.80000000","746.84000000"],["9.82000000","7.25000000"],["9.87000000","65.52000000"],["9.88000000","127.62000000"],["9.89000000","31.44000000"],["9.90000000","773.57000000"],["9.97000000","199.46000000"],["9.98000000","283.86000000"],["9.99000000","346.55000000"],["10.00000000","5628.28000000"],["10.01000000","10.55000000"],["10.05000000","113.90000000"],["10.06000000","209.95000000"],["10.07000000","1.56000000"],["10.10000000","45.40000000"],["10.11000000","1.33000000"],["10.16000000","2.95000000"],["10.19000000","19.10000000"],["10.21000000","3.65000000"],["10.23000000","6.00000000"],["10.26000000","4.60000000"],["10.27000000","3.95000000"],["10.30000000","1.31000000"],["10.34000000","1748.04000000"],["10.39000000","1803.00000000"],["10.42000000","9.10000000"],["10.43000000","7.03000000"],["10.44000000","10000.00000000"],["10.45000000","41.58000000"],["10.46000000","53.20000000"],["10.47000000","1.55000000"],["10.50000000","735.18000000"],["10.52000000","2.76000000"],["10.53000000","45.22000000"],["10.54000000","2.64000000"],["10.55000000","17.10000000"],["10.58000000","2.00000000"],["10.60000000","1.14000000"],["10.63000000","2.45000000"],["10.65000000","2.00000000"],["10.67000000","2.13000000"],["10.68000000","6.90000000"],["10.70000000","1.70000000"],["10.74000000","1.05000000"],["10.75000000","18.96000000"],["10.79000000","38.66000000"],["10.80000000","177.13000000"],["10.83000000","9.74000000"],["10.85000000","73.90000000"],["10.86000000","1.00000000"],["10.87000000","297.89000000"],["10.88000000","383.60000000"],["10.90000000","54.04000000"],["10.91000000","249.64000000"],["10.94000000","1803.86000000"],["10.96000000","400.00000000"],["10.98000000","200.17000000"],["10.99000000","151.28000000"],["11.00000000","5897.62000000"],["11.04000000","186.53000000"],["11.05000000","1.02000000"],["11.10000000","238.88000000"],["11.11000000","14.35000000"],["11.12000000","2.80000000"],["11.14000000","2.71000000"],["11.17000000","1.00000000"],["11.20000000","67.46000000"],["11.25000000","49.02000000"],["11.30000000","4.42000000"],["11.35000000","1.15000000"],["11.38000000","8.79000000"],["11.40000000","25.56000000"],["11.42000000","1803.85000000"],["11.43000000","263.52000000"],["11.45000000","793.90000000"],["11.48000000","2.32000000"],["11.49000000","2.00000000"],["11.50000000","696.85000000"],["11.55000000","6724.82000000"],["11.58000000","2.06000000"],["11.60000000","53.62000000"],["11.63000000","1134.47000000"],["11.65000000","1302.86000000"],["11.66000000","6.63000000"],["11.70000000","452.20000000"],["11.75000000","775.54000000"],["11.79000000","1.44000000"],["11.80000000","496.19000000"],["11.83000000","818.82000000"],["11.88000000","115.33000000"],["11.89000000","1.01000000"],["11.90000000","3.68000000"],["11.91000000","70.00000000"],["11.93000000","877.17000000"],["11.96000000","21.53000000"],["11.97000000","30.00000000"],["11.98000000","1.40000000"],["11.99000000","642.19000000"],["12.00000000","10648.43000000"],["12.01000000","2.95000000"],["12.04000000","1274.39000000"],["12.06000000","3.94000000"],["12.10000000","982.66000000"],["12.14000000","1.02000000"],["12.17000000","78.13000000"],["12.20000000","215.25000000"],["12.21000000","844.77000000"],["12.25000000","6.18000000"],["12.26000000","98.76000000"],["12.27000000","2733.72000000"],["12.28000000","74.81000000"],["12.30000000","625.29000000"],["12.34000000","879.96000000"],["12.35000000","0.85000000"],["12.39000000","16.49000000"],["12.40000000","19.60000000"],["12.42000000","4.55000000"],["12.44000000","880.39000000"],["12.45000000","40.23000000"],["12.46000000","6.99000000"],["12.50000000","440.98000000"],["12.54000000","701.43000000"],["12.60000000","1149.39000000"],["12.65000000","723.12000000"],["12.70000000","3.21000000"],["12.71000000","0.85000000"],["12.72000000","2.85000000"],["12.75000000","745.49000000"],["12.80000000","206.22000000"],["12.83000000","67.07000000"],["12.85000000","1.00000000"],["12.87000000","1.00000000"],["12.90000000","259.72000000"],["12.92000000","52.20000000"],["12.97000000","5.00000000"],["12.98000000","34.00000000"],["12.99000000","20.00000000"],["13.00000000","4179.03000000"],["13.01000000","0.80000000"],["13.08000000","0.85000000"],["13.10000000","2.38000000"],["13.11000000","4.19000000"],["13.12000000","13.41000000"],["13.13000000","16.31000000"],["13.20000000","70.69000000"],["13.25000000","2.27000000"],["13.30000000","31.63000000"],["13.31000000","0.92000000"],["13.36000000","10.94000000"],["13.40000000","835.20000000"],["13.41000000","2.92000000"],["13.42000000","3.31000000"],["13.45000000","1.00000000"],["13.47000000","1.85000000"],["13.49000000","3.87000000"],["13.50000000","437.70000000"],["13.57000000","1.00000000"],["13.60000000","16.07000000"],["13.64000000","0.89000000"],["13.65000000","6.00000000"],["13.70000000","3220.18000000"],["13.73000000","1.29000000"],["13.74000000","0.89000000"],["13.80000000","46.05000000"],["13.82000000","71.87000000"],["13.83000000","75.96000000"],["13.86000000","0.85000000"],["13.88000000","2.21000000"],["13.89000000","40.01000000"],["13.90000000","3346.65000000"],["13.92000000","8.19000000"],["13.95000000","729.19000000"],["13.99000000","31.91000000"],["14.00000000","741.47000000"],["14.03000000","27.36000000"],["14.04000000","38.82000000"],["14.06000000","981.02000000"],["14.10000000","10.01000000"],["14.20000000","826.79000000"],["14.24000000","298.21000000"],["14.25000000","104.87000000"],["14.27000000","0.85000000"],["14.29000000","6.13000000"],["14.38000000","367.81000000"],["14.40000000","1.73000000"],["14.44000000","2606.01000000"],["14.45000000","6.44000000"],["14.46000000","72.84000000"],["14.47000000","177.48000000"],["14.50000000","5889.80000000"],["14.52000000","3.51000000"],["14.54000000","275.73000000"],["14.55000000","6.50000000"],["14.59000000","1.00000000"],["14.60000000","4.69000000"],["14.63000000","37.85000000"],["14.65000000","1.00000000"],["14.69000000","0.85000000"],["14.70000000","3.30000000"],["14.74000000","32.64000000"],["14.75000000","2.17000000"],["14.77000000","1687.10000000"],["14.80000000","3.02000000"],["14.81000000","27.71000000"],["14.86000000","26.98000000"],["14.87000000","2.00000000"],["14.88000000","1.99000000"],["14.89000000","22.32000000"],["14.90000000","63.21000000"],["14.93000000","157.49000000"],["14.95000000","15.77000000"],["14.98000000","10.00000000"],["14.99000000","1.60000000"],["15.00000000","6647.58000000"],["15.01000000","60.08000000"],["15.02000000","6.39000000"],["15.10000000","326.22000000"],["15.12000000","0.85000000"],["15.19000000","74.51000000"],["15.20000000","49.35000000"],["15.22000000","1.74000000"],["15.25000000","10.00000000"],["15.28000000","3.15000000"],["15.30000000","6.89000000"],["15.32000000","1.77000000"],["15.35000000","2.15000000"],["15.37000000","0.91000000"],["15.40000000","16.80000000"],["15.45000000","1.00000000"],["15.47000000","314.25000000"],["15.49000000","8.74000000"],["15.50000000","566.93000000"],["15.52000000","41.47000000"],["15.55000000","43.55000000"],["15.56000000","6.66000000"],["15.57000000","3.73000000"],["15.59000000","50.13000000"],["15.60000000","145.36000000"],["15.62000000","30.24000000"],["15.66000000","7.40000000"],["15.68000000","1.34000000"],["15.70000000","6.36000000"],["15.73000000","6.43000000"],["15.75000000","5.26000000"],["15.80000000","87.23000000"],["15.88000000","3.55000000"],["15.90000000","69.10000000"],["15.95000000","1.00000000"],["15.98000000","0.81000000"],["15.99000000","130.78000000"],["16.00000000","19713.74000000"],["16.02000000","3.70000000"],["16.03000000","0.85000000"],["16.06000000","1.13000000"],["16.10000000","857.86000000"],["16.11000000","855.97000000"],["16.12000000","854.27000000"],["16.13000000","853.08000000"],["16.16000000","178.68000000"],["16.20000000","1.93000000"],["16.31000000","1.17000000"],["16.33000000","105.03000000"],["16.35000000","2.13000000"],["16.36000000","1.66000000"],["16.40000000","62.69000000"],["16.41000000","2.94000000"],["16.44000000","200.00000000"],["16.45000000","1.00000000"],["16.49000000","2.92000000"],["16.50000000","1235.97000000"],["16.60000000","264.00000000"],["16.66000000","314.76000000"],["16.69000000","5.87000000"],["16.70000000","287.46000000"],["16.74000000","50.11000000"],["16.75000000","48.94000000"],["16.77000000","0.71000000"],["16.78000000","0.63000000"],["16.80000000","480.88000000"],["16.81000000","158.00000000"],["16.82000000","136.00000000"],["16.83000000","119.61000000"],["16.84000000","20.00000000"],["16.85000000","29.00000000"],["16.86000000","96.00000000"],["16.87000000","88.36000000"],["16.88000000","5.68000000"],["16.89000000","40.81000000"],["16.90000000","1.37000000"],["16.91000000","99.00000000"],["16.92000000","95.00000000"],["16.93000000","47.00000000"],["16.94000000","110.00000000"],["16.95000000","141.00000000"],["16.96000000","91.00000000"],["16.97000000","34.00000000"],["16.98000000","69.46000000"],["16.99000000","102.00000000"],["17.00000000","6531.99000000"],["17.04000000","45.91000000"],["17.06000000","3.08000000"],["17.07000000","9.11000000"],["17.09000000","1.22000000"],["17.10000000","52.04000000"],["17.12000000","108.00000000"],["17.13000000","122.00000000"],["17.14000000","99.00000000"],["17.15000000","68.00000000"],["17.16000000","55.00000000"],["17.17000000","68.00000000"],["17.18000000","87.06000000"],["17.19000000","96.63000000"],["17.20000000","114.26000000"],["17.21000000","117.00000000"],["17.22000000","165.00000000"],["17.23000000","109.00000000"],["17.24000000","86.00000000"],["17.25000000","57.00000000"],["17.27000000","65.36000000"],["17.30000000","403.20000000"],["17.34000000","10.00000000"],["17.36000000","30.61000000"],["17.40000000","6.60000000"],["17.41000000","1.00000000"],["17.44000000","5.00000000"],["17.45000000","892.88000000"],["17.48000000","0.85000000"],["17.50000000","1049.46000000"],["17.55000000","501.09000000"],["17.59000000","2.55000000"],["17.60000000","11.05000000"],["17.65000000","8.00000000"],["17.66000000","2.31000000"],["17.68000000","132.00000000"],["17.69000000","125.83000000"],["17.70000000","108.63000000"],["17.71000000","145.00000000"],["17.72000000","88.00000000"],["17.73000000","77.00000000"],["17.74000000","99.00000000"],["17.75000000","86.00000000"],["17.76000000","102.00000000"],["17.77000000","415.68000000"],["17.78000000","55.00000000"],["17.79000000","158.84000000"],["17.80000000","178.32000000"],["17.81000000","109.00000000"],["17.82000000","98.00000000"],["17.83000000","105.16000000"],["17.84000000","91.45000000"],["17.85000000","76.79000000"],["17.86000000","178.00000000"],["17.87000000","244.35000000"],["17.88000000","304.00000000"],["17.89000000","255.00000000"],["17.90000000","302.48000000"],["17.91000000","178.00000000"],["17.92000000","201.00000000"],["17.93000000","151.00000000"],["17.95000000","47.00000000"],["17.96000000","44.00000000"],["17.97000000","31.90000000"],["17.98000000","2.18000000"],["17.99000000","37.98000000"],["18.00000000","9345.82000000"],["18.02000000","2.24000000"],["18.03000000","4.27000000"],["18.05000000","11.21000000"],["18.09000000","122.67000000"],["18.10000000","72.19000000"],["18.20000000","590.63000000"],["18.22000000","35.16000000"],["18.25000000","8.59000000"],["18.28000000","0.68000000"],["18.30000000","60.74000000"],["18.37000000","4.12000000"],["18.38000000","15.99000000"],["18.40000000","1516.44000000"],["18.41000000","60.95000000"],["18.42000000","3.06000000"],["18.44000000","1219.61000000"],["18.45000000","1.00000000"],["18.50000000","1758.04000000"],["18.55000000","20.00000000"],["18.57000000","0.94000000"],["18.60000000","191.21000000"],["18.65000000","1.00000000"],["18.66000000","319.92000000"],["18.70000000","7.05000000"],["18.72000000","80.15000000"],["18.73000000","3367.66000000"],["18.75000000","48.96000000"],["18.77000000","1.00000000"],["18.78000000","5.65000000"],["18.79000000","5.09000000"],["18.80000000","0.62000000"],["18.81000000","4.59000000"],["18.82000000","250.47000000"],["18.85000000","1.00000000"],["18.87000000","164.87000000"],["18.88000000","51.84000000"],["18.90000000","131.56000000"],["18.91000000","5.10000000"],["18.93000000","1105.00000000"],["18.94000000","2.21000000"],["18.95000000","1.00000000"],["18.96000000","0.78000000"],["18.97000000","1055.82000000"],["18.98000000","8.11000000"],["18.99000000","507.89000000"],["19.00000000","11998.54000000"],["19.01000000","10.94000000"],["19.07000000","13.53000000"],["19.10000000","51.80000000"],["19.16000000","9.20000000"],["19.17000000","37.45000000"],["19.19000000","0.65000000"],["19.20000000","331.21000000"],["19.24000000","17.50000000"],["19.25000000","2.30000000"],["19.26000000","270.03000000"],["19.27000000","5821.23000000"],["19.29000000","0.53000000"],["19.30000000","344.69000000"],["19.31000000","1.05000000"],["19.32000000","41.68000000"],["19.33000000","46.84000000"],["19.34000000","0.74000000"],["19.35000000","5193.68000000"],["19.38000000","141.42000000"],["19.40000000","5.05000000"],["19.41000000","98.06000000"],["19.50000000","1620.36000000"],["19.52000000","1.80000000"],["19.56000000","12.64000000"],["19.60000000","660.22000000"],["19.63000000","0.64000000"],["19.65000000","38.93000000"],["19.67000000","3.61000000"],["19.70000000","573.28000000"],["19.71000000","18.96000000"],["19.80000000","1024.45000000"],["19.81000000","5.00000000"],["19.85000000","4.14000000"],["19.86000000","201.43000000"],["19.90000000","1135.38000000"],["19.92000000","150.60000000"],["19.96000000","100.00000000"],["19.97000000","674.88000000"],["19.98000000","0.64000000"],["19.99000000","971.45000000"],["20.00000000","29049.10000000"],["20.04000000","212.14000000"],["20.09000000","2.78000000"],["20.12000000","755.23000000"],["20.15000000","0.62000000"],["20.16000000","581.55000000"],["20.20000000","111.83000000"],["20.22000000","155.77000000"],["20.23000000","1.00000000"],["20.26000000","3.40000000"],["20.27000000","2.31000000"],["20.28000000","14.80000000"],["20.30000000","532.19000000"],["20.31000000","50.68000000"],["20.36000000","24.13000000"],["20.40000000","207.88000000"],["20.41000000","382.28000000"],["20.43000000","125.00000000"],["20.44000000","40.78000000"],["20.45000000","2.54000000"],["20.46000000","425.00000000"],["20.50000000","200.98000000"],["20.53000000","4.61000000"],["20.55000000","774.14000000"],["20.60000000","24.53000000"],["20.62000000","13.99000000"],["20.63000000","44.99000000"],["20.68000000","1590.60000000"],["20.70000000","222.60000000"],["20.72000000","3.12000000"],["20.75000000","6.27000000"],["20.80000000","61.92000000"],["20.82000000","7.80000000"],["20.90000000","92.91000000"],["20.98000000","29.07000000"],["21.00000000","4768.71000000"],["21.10000000","180.00000000"],["21.12000000","21.33000000"],["21.15000000","2.28000000"],["21.16000000","2.03000000"],["21.19000000","508.51000000"],["21.20000000","51.99000000"],["21.23000000","2.59000000"],["21.25000000","27.97000000"],["21.27000000","5490.97000000"],["21.29000000","7.98000000"],["21.33000000","170.90000000"],["21.34000000","33.75000000"],["21.35000000","33.48000000"],["21.37000000","61.14000000"],["21.38000000","4.00000000"],["21.39000000","24.61000000"],["21.40000000","436.80000000"],["21.41000000","65.70000000"],["21.42000000","42.66000000"],["21.45000000","105.47000000"],["21.50000000","821.40000000"],["21.51000000","265.11000000"],["21.54000000","14.00000000"],["21.55000000","2051.78000000"],["21.58000000","33.59000000"],["21.59000000","45.72000000"],["21.61000000","2.43000000"],["21.66000000","5.54000000"],["21.68000000","313.52000000"],["21.76000000","283.52000000"],["21.80000000","15.48000000"],["21.88000000","49.17000000"],["21.89000000","1.10000000"],["21.90000000","190.30000000"],["21.95000000","10.12000000"],["21.99000000","1.20000000"],["22.00000000","5341.48000000"],["22.02000000","2.33000000"],["22.13000000","227.33000000"],["22.15000000","1.07000000"],["22.17000000","1.47000000"],["22.18000000","21.14000000"],["22.20000000","593.27000000"],["22.22000000","73.06000000"],["22.23000000","0.63000000"],["22.28000000","133.74000000"],["22.29000000","0.45000000"],["22.35000000","0.67000000"],["22.40000000","6.00000000"],["22.41000000","12.62000000"],["22.46000000","1.40000000"],["22.50000000","5.62000000"],["22.56000000","5.96000000"],["22.60000000","2.70000000"],["22.65000000","313.05000000"],["22.68000000","18.40000000"],["22.70000000","15.49000000"],["22.74000000","0.53000000"],["22.77000000","12.00000000"],["22.79000000","20.90000000"],["22.80000000","214.45000000"],["22.82000000","0.99000000"],["22.83000000","2.03000000"],["22.84000000","0.94000000"],["22.85000000","0.88000000"],["22.88000000","6.90000000"],["22.90000000","9.74000000"],["23.00000000","4198.15000000"],["23.19000000","17.03000000"],["23.26000000","1.41000000"],["23.33000000","0.54000000"],["23.35000000","8.96000000"],["23.38000000","2.18000000"],["23.50000000","22.38000000"],["23.51000000","14.17000000"],["23.53000000","1.08000000"],["23.70000000","4.82000000"],["23.80000000","2.99000000"],["23.88000000","3978.29000000"],["23.89000000","6.43000000"],["23.90000000","821.98000000"],["23.95000000","55.13000000"],["23.98000000","9.31000000"],["23.99000000","4.49000000"],["24.00000000","798.49000000"],["24.03000000","6.56000000"],["24.07000000","5.67000000"],["24.10000000","26.49000000"]]}},{"timeToSleep":750,"data":{"e":"depthUpdate","E":1672242116715,"s":"TORNBUSD","U":113354266,"u":113354267,"b":[["4.29000000","491.87000000"]],"a":[["4.69000000","5335.82000000"]]}},{"timeToSleep":977,"data":{"e":"depthUpdate","E":1672242117715,"s":"TORNBUSD","U":113354268,"u":113354274,"b":[["4.29000000","536.87000000"],["4.28000000","1529.95000000"],["4.20000000","2427.63000000"],["4.12000000","2054.13000000"],["4.05000000","3898.84000000"]],"a":[["4.48000000","929.80000000"],["7.25000000","694.68000000"]]}},{"timeToSleep":996,"data":{"e":"depthUpdate","E":1672242118715,"s":"TORNBUSD","U":113354275,"u":113354279,"b":[["4.28000000","1533.24000000"],["4.19000000","595.40000000"],["4.16000000","130.87000000"],["4.15000000","953.12000000"]],"a":[["4.50000000","1352.81000000"]]}},{"timeToSleep":1004,"data":{"e":"depthUpdate","E":1672242119716,"s":"TORNBUSD","U":113354280,"u":113354281,"b":[["4.28000000","1539.95000000"]],"a":[["4.42000000","31.17000000"]]}},{"timeToSleep":998,"data":{"e":"depthUpdate","E":1672242120716,"s":"TORNBUSD","U":113354282,"u":113354283,"b":[["4.17000000","347.87000000"]],"a":[["4.43000000","971.64000000"]]}},{"timeToSleep":1001,"data":{"e":"depthUpdate","E":1672242121716,"s":"TORNBUSD","U":113354284,"u":113354289,"b":[["4.29000000","582.50000000"],["4.25000000","2329.63000000"],["4.18000000","1047.86000000"],["4.12000000","2078.00000000"],["4.05000000","3874.55000000"]],"a":[]}},{"timeToSleep":998,"data":{"e":"depthUpdate","E":1672242122716,"s":"TORNBUSD","U":113354290,"u":113354290,"b":[["4.25000000","2385.62000000"]],"a":[]}},{"timeToSleep":1000,"data":{"e":"depthUpdate","E":1672242123716,"s":"TORNBUSD","U":113354291,"u":113354294,"b":[["4.29000000","592.35000000"],["4.17000000","350.64000000"],["4.15000000","950.33000000"],["4.05000000","1977.20000000"]],"a":[]}},{"timeToSleep":1015,"data":{"e":"depthUpdate","E":1672242124716,"s":"TORNBUSD","U":113354295,"u":113354299,"b":[["4.19000000","506.80000000"],["4.12000000","3943.12000000"],["4.07000000","380.60000000"],["4.04000000","224.42000000"]],"a":[["4.35000000","349.45000000"]]}},{"timeToSleep":1991,"data":{"e":"depthUpdate","E":1672242126716,"s":"TORNBUSD","U":113354300,"u":113354301,"b":[["4.20000000","2516.75000000"]],"a":[["4.37000000","641.54000000"]]}},{"timeToSleep":996,"data":{"e":"depthUpdate","E":1672242127716,"s":"TORNBUSD","U":113354302,"u":113354303,"b":[],"a":[["4.42000000","188.95000000"]]}},{"timeToSleep":1116,"data":{"e":"depthUpdate","E":1672242128716,"s":"TORNBUSD","U":113354304,"u":113354306,"b":[["4.34000000","15.18000000"],["4.16000000","146.81000000"],["4.11000000","381.10000000"]],"a":[]}},{"timeToSleep":916,"data":{"e":"depthUpdate","E":1672242129716,"s":"TORNBUSD","U":113354307,"u":113354308,"b":[["4.30000000","165.82000000"]],"a":[["4.38000000","486.72000000"]]}},{"timeToSleep":970,"data":{"e":"depthUpdate","E":1672242130716,"s":"TORNBUSD","U":113354309,"u":113354319,"b":[["4.34000000","9.80000000"],["4.03000000","644.88000000"],["3.99000000","851.71000000"]],"a":[["4.35000000","346.98000000"],["4.36000000","373.57000000"],["4.41000000","145.62000000"],["4.50000000","1313.41000000"],["4.70000000","1033.69000000"],["4.90000000","4426.10000000"]]}},{"timeToSleep":998,"data":{"e":"depthUpdate","E":1672242131716,"s":"TORNBUSD","U":113354320,"u":113354335,"b":[["4.23000000","810.70000000"],["4.12000000","3971.38000000"],["4.11000000","230.45000000"],["4.09000000","94.49000000"],["4.08000000","120.41000000"],["4.07000000","428.00000000"],["4.06000000","835.22000000"],["4.05000000","1976.95000000"],["4.04000000","147.61000000"],["4.03000000","625.89000000"],["4.01000000","279.33000000"],["3.99000000","822.54000000"]],"a":[]}},{"timeToSleep":999,"data":{"e":"depthUpdate","E":1672242132716,"s":"TORNBUSD","U":113354336,"u":113354409,"b":[["4.34000000","0.00000000"],["4.33000000","0.00000000"],["4.32000000","0.00000000"],["4.31000000","0.00000000"],["4.30000000","59.18000000"],["4.29000000","588.87000000"],["4.28000000","1533.24000000"],["4.27000000","393.74000000"],["4.26000000","372.06000000"],["4.25000000","2365.64000000"],["4.24000000","702.97000000"],["4.23000000","601.48000000"],["4.21000000","1281.31000000"],["4.20000000","2562.46000000"],["4.19000000","613.12000000"],["4.18000000","952.34000000"],["4.17000000","399.11000000"],["4.16000000","62.64000000"],["4.15000000","905.13000000"],["4.14000000","510.11000000"],["4.12000000","4052.09000000"],["4.11000000","314.75000000"],["4.10000000","1288.04000000"],["4.07000000","319.79000000"],["4.06000000","787.70000000"],["4.05000000","2072.23000000"],["4.03000000","687.30000000"],["3.97000000","3176.84000000"],["3.93000000","1477.59000000"]],"a":[["4.32000000","5.53000000"],["4.33000000","18.88000000"],["4.34000000","108.42000000"],["4.35000000","370.53000000"],["4.36000000","383.29000000"]]}},{"timeToSleep":1003,"data":{"e":"depthUpdate","E":1672242133716,"s":"TORNBUSD","U":113354410,"u":113354433,"b":[["4.29000000","547.59000000"],["4.27000000","407.73000000"],["4.26000000","374.51000000"],["4.23000000","721.90000000"],["4.20000000","2350.67000000"],["4.19000000","601.21000000"],["4.18000000","896.32000000"],["4.16000000","324.41000000"],["4.15000000","833.57000000"],["4.14000000","566.67000000"],["4.12000000","2186.97000000"],["4.11000000","399.04000000"],["4.08000000","112.65000000"],["4.05000000","3977.40000000"],["4.00000000","25972.09000000"],["3.96000000","353.59000000"]],"a":[["10.63000000","153.07000000"]]}},{"timeToSleep":996,"data":{"e":"depthUpdate","E":1672242134716,"s":"TORNBUSD","U":113354434,"u":113354438,"b":[["4.15000000","809.71000000"],["4.12000000","2211.00000000"]],"a":[["4.33000000","22.23000000"],["4.36000000","387.02000000"],["10.63000000","2.45000000"]]}},{"timeToSleep":1004,"data":{"e":"depthUpdate","E":1672242135716,"s":"TORNBUSD","U":113354439,"u":113354440,"b":[["4.30000000","61.68000000"]],"a":[["4.35000000","373.87000000"]]}},{"timeToSleep":999,"data":{"e":"depthUpdate","E":1672242136716,"s":"TORNBUSD","U":113354441,"u":113354444,"b":[["4.25000000","2309.59000000"],["4.16000000","347.94000000"]],"a":[["4.32000000","9.26000000"],["4.36000000","383.29000000"]]}},{"timeToSleep":999,"data":{"e":"depthUpdate","E":1672242137716,"s":"TORNBUSD","U":113354445,"u":113354445,"b":[["4.20000000","2647.76000000"]],"a":[]}},{"timeToSleep":1000,"data":{"e":"depthUpdate","E":1672242138716,"s":"TORNBUSD","U":113354446,"u":113354486,"b":[["4.30000000","0.00000000"],["4.29000000","419.55000000"],["4.28000000","1704.72000000"],["4.25000000","2253.54000000"],["4.24000000","414.29000000"],["4.21000000","1572.00000000"],["4.20000000","2578.48000000"],["4.17000000","468.87000000"],["4.11000000","387.00000000"],["4.10000000","1263.89000000"],["4.09000000","66.02000000"],["4.08000000","96.25000000"],["4.07000000","344.12000000"],["4.06000000","816.38000000"],["4.05000000","3929.37000000"],["4.03000000","687.30000000"],["4.00000000","26001.19000000"],["3.98000000","585.26000000"]],"a":[["4.30000000","12.41000000"],["4.32000000","5.53000000"],["4.33000000","47.07000000"],["4.34000000","136.76000000"],["4.35000000","385.58000000"]]}},{"timeToSleep":1000,"data":{"e":"depthUpdate","E":1672242139716,"s":"TORNBUSD","U":113354487,"u":113354510,"b":[["4.29000000","415.82000000"],["4.21000000","1507.81000000"],["4.18000000","960.97000000"],["4.16000000","332.00000000"],["4.12000000","2186.76000000"],["4.11000000","403.13000000"],["4.08000000","56.37000000"],["4.07000000","368.64000000"],["4.06000000","812.69000000"],["4.05000000","3881.73000000"],["4.04000000","195.37000000"],["4.03000000","635.31000000"],["4.01000000","327.44000000"],["4.00000000","26049.42000000"]],"a":[["4.30000000","4.60000000"],["4.33000000","47.07000000"],["4.34000000","136.76000000"],["4.36000000","386.45000000"]]}},{"timeToSleep":1011,"data":{"e":"depthUpdate","E":1672242140716,"s":"TORNBUSD","U":113354511,"u":113354525,"b":[["4.29000000","370.19000000"],["4.26000000","372.06000000"],["4.24000000","416.75000000"],["4.23000000","698.50000000"],["4.20000000","2507.77000000"],["4.18000000","984.65000000"],["4.17000000","540.09000000"]],"a":[["4.30000000","19.96000000"],["4.33000000","22.23000000"],["4.34000000","161.60000000"],["4.38000000","443.01000000"],["4.44000000","326.50000000"]]}},{"timeToSleep":988,"data":{"e":"depthUpdate","E":1672242141716,"s":"TORNBUSD","U":113354526,"u":113354535,"b":[["4.28000000","1471.08000000"],["3.95000000","1066.84000000"]],"a":[["4.30000000","4.60000000"],["4.33000000","22.23000000"],["4.34000000","136.76000000"],["4.40000000","119.25000000"],["4.45000000","459.80000000"]]}},{"timeToSleep":1001,"data":{"e":"depthUpdate","E":1672242142717,"s":"TORNBUSD","U":113354536,"u":113354538,"b":[["4.19000000","596.49000000"],["4.14000000","571.45000000"]],"a":[["4.34000000","161.60000000"]]}},{"timeToSleep":1007,"data":{"e":"depthUpdate","E":1672242143717,"s":"TORNBUSD","U":113354539,"u":113354543,"b":[["4.29000000","354.83000000"],["4.20000000","2450.75000000"],["4.11000000","379.05000000"]],"a":[["4.33000000","47.07000000"],["4.34000000","136.76000000"]]}},{"timeToSleep":993,"data":{"e":"depthUpdate","E":1672242144716,"s":"TORNBUSD","U":113354544,"u":113354548,"b":[],"a":[["4.33000000","47.07000000"],["4.34000000","136.76000000"],["4.70000000","844.27000000"]]}},{"timeToSleep":1118,"data":{"e":"depthUpdate","E":1672242145716,"s":"TORNBUSD","U":113354549,"u":113354577,"b":[["4.30000000","232.85000000"],["4.29000000","0.00000000"],["4.28000000","1407.02000000"],["4.25000000","2250.02000000"],["4.23000000","702.03000000"],["4.21000000","1484.09000000"],["4.19000000","478.56000000"],["4.17000000","682.53000000"],["4.15000000","773.93000000"],["4.14000000","568.66000000"],["4.13000000","316.43000000"],["4.12000000","2080.60000000"],["4.10000000","1852.22000000"],["4.08000000","84.91000000"],["4.05000000","3704.54000000"],["4.03000000","683.18000000"],["4.01000000","458.28000000"]],"a":[["4.30000000","0.00000000"],["4.31000000","4.39000000"],["4.32000000","22.94000000"],["4.33000000","22.23000000"],["4.60000000","2121.30000000"]]}},{"timeToSleep":882,"data":{"e":"depthUpdate","E":1672242146716,"s":"TORNBUSD","U":113354578,"u":113354583,"b":[["4.30000000","229.47000000"],["4.16000000","308.47000000"]],"a":[["4.33000000","47.07000000"],["4.34000000","136.76000000"],["4.35000000","398.63000000"]]}},{"timeToSleep":1001,"data":{"e":"depthUpdate","E":1672242147717,"s":"TORNBUSD","U":113354584,"u":113354598,"b":[["4.27000000","435.77000000"],["4.26000000","440.29000000"],["4.25000000","2253.54000000"],["4.24000000","348.52000000"],["4.23000000","698.50000000"],["4.21000000","1507.81000000"],["4.19000000","454.73000000"],["4.12000000","2189.57000000"],["4.10000000","1742.75000000"]],"a":[["4.33000000","47.07000000"],["4.34000000","136.76000000"],["4.35000000","403.63000000"],["10.63000000","153.07000000"]]}},{"timeToSleep":1005,"data":{"e":"depthUpdate","E":1672242148717,"s":"TORNBUSD","U":113354599,"u":113354611,"b":[["4.30000000","218.02000000"],["4.29000000","23.82000000"],["3.98000000","678.06000000"],["3.80000000","2966.33000000"]],"a":[["4.32000000","47.78000000"],["4.33000000","272.60000000"],["4.34000000","169.00000000"],["4.35000000","271.40000000"]]}},{"timeToSleep":993,"data":{"e":"depthUpdate","E":1672242149717,"s":"TORNBUSD","U":113354612,"u":113354622,"b":[["4.30000000","389.50000000"],["4.28000000","1235.54000000"]],"a":[["4.32000000","108.42000000"],["4.33000000","120.41000000"],["4.34000000","260.55000000"],["4.35000000","391.47000000"]]}},{"timeToSleep":1002,"data":{"e":"depthUpdate","E":1672242150717,"s":"TORNBUSD","U":113354623,"u":113354623,"b":[["4.25000000","2197.49000000"]],"a":[]}},{"timeToSleep":1000,"data":{"e":"depthUpdate","E":1672242151717,"s":"TORNBUSD","U":113354624,"u":113354624,"b":[["4.11000000","362.92000000"]],"a":[]}},{"timeToSleep":1000,"data":{"e":"depthUpdate","E":1672242152717,"s":"TORNBUSD","U":113354625,"u":113354626,"b":[],"a":[["4.31000000","14.24000000"],["4.33000000","236.96000000"]]}},{"timeToSleep":1000,"data":{"e":"depthUpdate","E":1672242153717,"s":"TORNBUSD","U":113354627,"u":113354629,"b":[["4.09000000","82.37000000"]],"a":[["4.32000000","133.26000000"],["4.33000000","212.12000000"]]}},{"timeToSleep":1003,"data":{"e":"depthUpdate","E":1672242154717,"s":"TORNBUSD","U":113354630,"u":113354632,"b":[["4.28000000","1230.72000000"],["4.20000000","2403.26000000"]],"a":[["20.00000000","29001.50000000"]]}},{"timeToSleep":998,"data":{"e":"depthUpdate","E":1672242155717,"s":"TORNBUSD","U":113354633,"u":113354633,"b":[],"a":[["4.35000000","296.82000000"]]}},{"timeToSleep":1076,"data":{"e":"depthUpdate","E":1672242156717,"s":"TORNBUSD","U":113354634,"u":113354635,"b":[["4.28000000","1347.39000000"]],"a":[["4.50000000","1502.83000000"]]}},{"timeToSleep":922,"data":{"e":"depthUpdate","E":1672242157717,"s":"TORNBUSD","U":113354636,"u":113354637,"b":[["4.26000000","444.03000000"],["3.41000000","5055.93000000"]],"a":[]}},{"timeToSleep":1000,"data":{"e":"depthUpdate","E":1672242158717,"s":"TORNBUSD","U":113354638,"u":113354640,"b":[["4.30000000","445.19000000"],["4.26000000","463.26000000"]],"a":[["4.50000000","1717.63000000"]]}},{"timeToSleep":1001,"data":{"e":"depthUpdate","E":1672242159717,"s":"TORNBUSD","U":113354641,"u":113354645,"b":[["4.30000000","514.25000000"],["4.28000000","1415.62000000"],["4.26000000","395.03000000"],["4.21000000","1436.68000000"],["4.17000000","611.31000000"]],"a":[]}},{"timeToSleep":1000,"data":{"e":"depthUpdate","E":1672242160717,"s":"TORNBUSD","U":113354646,"u":113354652,"b":[["4.29000000","28.21000000"],["4.19000000","596.49000000"],["4.17000000","468.87000000"],["4.16000000","380.45000000"],["4.15000000","809.71000000"],["4.13000000","280.48000000"]],"a":[["4.31000000","5.11000000"]]}},{"timeToSleep":1997,"data":{"e":"depthUpdate","E":1672242162717,"s":"TORNBUSD","U":113354653,"u":113354653,"b":[["4.28000000","1893.59000000"]],"a":[]}},{"timeToSleep":2002,"data":{"e":"depthUpdate","E":1672242164717,"s":"TORNBUSD","U":113354654,"u":113354656,"b":[["4.30000000","445.19000000"],["4.29000000","97.44000000"],["4.03000000","621.77000000"]],"a":[]}},{"timeToSleep":1001,"data":{"e":"depthUpdate","E":1672242165717,"s":"TORNBUSD","U":113354657,"u":113354657,"b":[["4.26000000","376.29000000"]],"a":[]}},{"timeToSleep":1006,"data":{"e":"depthUpdate","E":1672242166717,"s":"TORNBUSD","U":113354658,"u":113354660,"b":[["4.26000000","317.73000000"]],"a":[]}},{"timeToSleep":1993,"data":{"e":"depthUpdate","E":1672242168718,"s":"TORNBUSD","U":113354661,"u":113354661,"b":[["4.30000000","451.93000000"]],"a":[]}},{"timeToSleep":1002,"data":{"e":"depthUpdate","E":1672242169718,"s":"TORNBUSD","U":113354662,"u":113354663,"b":[["4.30000000","489.45000000"],["4.20000000","2106.17000000"]],"a":[]}},{"timeToSleep":1002,"data":{"e":"depthUpdate","E":1672242170718,"s":"TORNBUSD","U":113354664,"u":113354667,"b":[["4.30000000","467.85000000"],["4.25000000","1670.92000000"]],"a":[["4.31000000","32.62000000"]]}},{"timeToSleep":1019,"data":{"e":"depthUpdate","E":1672242171718,"s":"TORNBUSD","U":113354668,"u":113354668,"b":[["4.25000000","1284.49000000"]],"a":[]}},{"timeToSleep":1004,"data":{"e":"depthUpdate","E":1672242172718,"s":"TORNBUSD","U":113354669,"u":113354670,"b":[["4.29000000","28.21000000"],["4.07000000","295.06000000"]],"a":[]}},{"timeToSleep":975,"data":{"e":"depthUpdate","E":1672242173718,"s":"TORNBUSD","U":113354671,"u":113354671,"b":[],"a":[["4.41000000","136.57000000"]]}},{"timeToSleep":999,"data":{"e":"depthUpdate","E":1672242174718,"s":"TORNBUSD","U":113354672,"u":113354673,"b":[["4.30000000","471.88000000"]],"a":[["4.34000000","265.49000000"]]}},{"timeToSleep":1003,"data":{"e":"depthUpdate","E":1672242175718,"s":"TORNBUSD","U":113354674,"u":113354674,"b":[["4.29000000","98.01000000"]],"a":[]}},{"timeToSleep":998,"data":{"e":"depthUpdate","E":1672242176718,"s":"TORNBUSD","U":113354675,"u":113354676,"b":[["4.30000000","588.12000000"]],"a":[["19.92000000","0.00000000"]]}},{"timeToSleep":1999,"data":{"e":"depthUpdate","E":1672242178718,"s":"TORNBUSD","U":113354677,"u":113354678,"b":[["4.04000000","325.24000000"],["4.01000000","327.44000000"]],"a":[]}},{"timeToSleep":1000,"data":{"e":"depthUpdate","E":1672242179718,"s":"TORNBUSD","U":113354679,"u":113354679,"b":[],"a":[["4.46000000","316.29000000"]]}},{"timeToSleep":1000,"data":{"e":"depthUpdate","E":1672242180718,"s":"TORNBUSD","U":113354680,"u":113354680,"b":[["3.96000000","23.34000000"]],"a":[]}},{"timeToSleep":1001,"data":{"e":"depthUpdate","E":1672242181718,"s":"TORNBUSD","U":113354681,"u":113354684,"b":[["4.20000000","933.08000000"],["3.96000000","356.34000000"]],"a":[["4.40000000","54.98000000"],["21.57000000","47.60000000"]]}},{"timeToSleep":1000,"data":{"e":"depthUpdate","E":1672242182718,"s":"TORNBUSD","U":113354685,"u":113354687,"b":[["4.04000000","387.01000000"]],"a":[["4.38000000","810.28000000"],["13.20000000","12.71000000"]]}},{"timeToSleep":1001,"data":{"e":"depthUpdate","E":1672242183718,"s":"TORNBUSD","U":113354688,"u":113354698,"b":[["4.30000000","610.90000000"],["4.29000000","115.42000000"],["4.15000000","773.93000000"]],"a":[["4.31000000","0.00000000"],["4.32000000","24.84000000"],["4.34000000","301.73000000"],["4.38000000","793.41000000"],["4.40000000","71.78000000"],["20.00000000","28900.82000000"]]}},{"timeToSleep":1024,"data":{"e":"depthUpdate","E":1672242184718,"s":"TORNBUSD","U":113354699,"u":113354705,"b":[["4.23000000","722.11000000"],["4.21000000","1412.96000000"],["4.15000000","810.01000000"],["4.14000000","677.12000000"],["4.12000000","2080.60000000"],["4.08000000","1968.31000000"],["4.05000000","1807.19000000"]],"a":[]}},{"timeToSleep":975,"data":{"e":"depthUpdate","E":1672242185719,"s":"TORNBUSD","U":113354706,"u":113354707,"b":[["4.30000000","614.94000000"],["4.25000000","1336.85000000"]],"a":[]}},{"timeToSleep":1001,"data":{"e":"depthUpdate","E":1672242186719,"s":"TORNBUSD","U":113354708,"u":113354708,"b":[["4.20000000","8560.54000000"]],"a":[]}},{"timeToSleep":998,"data":{"e":"depthUpdate","E":1672242187719,"s":"TORNBUSD","U":113354709,"u":113354711,"b":[],"a":[["4.36000000","549.24000000"],["4.43000000","637.13000000"],["4.45000000","794.31000000"]]}},{"timeToSleep":1000,"data":{"e":"depthUpdate","E":1672242188719,"s":"TORNBUSD","U":113354712,"u":113354712,"b":[],"a":[["4.58000000","255.53000000"]]}},{"timeToSleep":1003,"data":{"e":"depthUpdate","E":1672242189719,"s":"TORNBUSD","U":113354713,"u":113354715,"b":[["4.29000000","126.47000000"]],"a":[["4.32000000","64.27000000"]]}},{"timeToSleep":999,"data":{"e":"depthUpdate","E":1672242190719,"s":"TORNBUSD","U":113354716,"u":113354717,"b":[["4.14000000","620.56000000"]],"a":[["4.36000000","211.05000000"]]}},{"timeToSleep":999,"data":{"e":"depthUpdate","E":1672242191719,"s":"TORNBUSD","U":113354718,"u":113354726,"b":[["4.30000000","443.46000000"],["4.29000000","303.70000000"],["4.24000000","400.99000000"],["4.11000000","278.62000000"]],"a":[["4.31000000","0.00000000"],["4.32000000","271.08000000"],["4.33000000","183.78000000"],["4.34000000","124.70000000"]]}},{"timeToSleep":1002,"data":{"e":"depthUpdate","E":1672242192719,"s":"TORNBUSD","U":113354727,"u":113354736,"b":[["4.25000000","1321.97000000"],["4.24000000","453.46000000"],["4.14000000","677.59000000"]],"a":[["4.31000000","0.00000000"],["4.32000000","242.74000000"],["4.33000000","212.12000000"],["4.34000000","124.70000000"]]}},{"timeToSleep":1001,"data":{"e":"depthUpdate","E":1672242193719,"s":"TORNBUSD","U":113354737,"u":113354748,"b":[["4.27000000","419.34000000"],["4.25000000","1374.33000000"],["4.12000000","2165.40000000"]],"a":[["4.31000000","24.84000000"],["4.32000000","242.74000000"],["4.33000000","212.12000000"],["4.34000000","124.70000000"]]}},{"timeToSleep":999,"data":{"e":"depthUpdate","E":1672242194719,"s":"TORNBUSD","U":113354749,"u":113354761,"b":[["4.24000000","470.01000000"],["4.19000000","454.73000000"]],"a":[["4.31000000","24.84000000"],["4.32000000","278.98000000"],["4.33000000","212.12000000"],["4.34000000","88.46000000"],["4.50000000","1712.34000000"]]}},{"timeToSleep":999,"data":{"e":"depthUpdate","E":1672242195719,"s":"TORNBUSD","U":113354762,"u":113354772,"b":[["4.13000000","296.54000000"],["4.09000000","66.02000000"]],"a":[["4.31000000","24.84000000"],["4.32000000","278.98000000"],["4.33000000","167.12000000"],["4.34000000","88.46000000"]]}},{"timeToSleep":998,"data":{"e":"depthUpdate","E":1672242196719,"s":"TORNBUSD","U":113354773,"u":113354782,"b":[["4.19000000","597.67000000"],["3.93000000","1339.05000000"]],"a":[["4.31000000","0.00000000"],["4.32000000","125.35000000"],["4.34000000","266.93000000"],["4.38000000","530.84000000"]]}},{"timeToSleep":1003,"data":{"e":"depthUpdate","E":1672242197719,"s":"TORNBUSD","U":113354783,"u":113354785,"b":[["4.16000000","356.66000000"]],"a":[["4.32000000","97.80000000"]]}},{"timeToSleep":1061,"data":{"e":"depthUpdate","E":1672242198719,"s":"TORNBUSD","U":113354786,"u":113354794,"b":[["4.24000000","522.42000000"],["4.11000000","335.28000000"],["4.09000000","37.55000000"],["4.08000000","1939.77000000"],["4.05000000","1854.83000000"],["4.03000000","573.90000000"]],"a":[["4.31000000","0.00000000"]]}},{"timeToSleep":942,"data":{"e":"depthUpdate","E":1672242199719,"s":"TORNBUSD","U":113354795,"u":113354801,"b":[["4.29000000","309.16000000"],["4.08000000","56.37000000"],["4.07000000","2183.09000000"]],"a":[["4.31000000","24.84000000"],["4.38000000","533.13000000"]]}},{"timeToSleep":997,"data":{"e":"depthUpdate","E":1672242200719,"s":"TORNBUSD","U":113354802,"u":113354806,"b":[["4.28000000","1896.98000000"]],"a":[["4.31000000","0.00000000"],["4.32000000","97.80000000"],["4.45000000","459.80000000"]]}},{"timeToSleep":1000,"data":{"e":"depthUpdate","E":1672242201719,"s":"TORNBUSD","U":113354807,"u":113354812,"b":[["4.24000000","574.83000000"]],"a":[["4.31000000","0.00000000"],["4.32000000","122.64000000"],["4.45000000","689.25000000"],["4.46000000","650.80000000"]]}},{"timeToSleep":1000,"data":{"e":"depthUpdate","E":1672242202719,"s":"TORNBUSD","U":113354813,"u":113354817,"b":[["3.94000000","209.29000000"]],"a":[["4.31000000","24.84000000"],["4.32000000","142.80000000"],["4.44000000","312.96000000"]]}},{"timeToSleep":1031,"data":{"e":"depthUpdate","E":1672242203719,"s":"TORNBUSD","U":113354818,"u":113354822,"b":[["4.24000000","627.24000000"]],"a":[["4.31000000","0.00000000"],["4.32000000","142.80000000"],["4.44000000","317.52000000"]]}},{"timeToSleep":968,"data":{"e":"depthUpdate","E":1672242204720,"s":"TORNBUSD","U":113354823,"u":113354830,"b":[["4.16000000","380.65000000"],["4.15000000","798.09000000"],["4.10000000","3616.96000000"],["4.07000000","295.06000000"]],"a":[["4.31000000","24.84000000"],["4.46000000","664.34000000"]]}},{"timeToSleep":2002,"data":{"e":"depthUpdate","E":1672242206720,"s":"TORNBUSD","U":113354831,"u":113354833,"b":[],"a":[["4.31000000","0.00000000"],["4.32000000","167.64000000"],["21.49000000","66.50000000"]]}},{"timeToSleep":999,"data":{"e":"depthUpdate","E":1672242207720,"s":"TORNBUSD","U":113354834,"u":113354838,"b":[["4.31000000","177.23000000"],["4.29000000","131.93000000"]],"a":[["4.32000000","142.80000000"],["4.36000000","578.32000000"],["21.00000000","4663.84000000"]]}},{"timeToSleep":1000,"data":{"e":"depthUpdate","E":1672242208720,"s":"TORNBUSD","U":113354839,"u":113354845,"b":[["4.19000000","668.55000000"],["4.16000000","308.67000000"],["4.13000000","775.95000000"],["4.10000000","3134.04000000"]],"a":[["4.32000000","149.14000000"],["4.44000000","441.65000000"]]}},{"timeToSleep":999,"data":{"e":"depthUpdate","E":1672242209720,"s":"TORNBUSD","U":113354846,"u":113354856,"b":[["4.28000000","1948.98000000"],["4.21000000","1554.05000000"],["4.20000000","8772.68000000"],["4.19000000","525.61000000"],["4.17000000","255.21000000"],["4.15000000","800.88000000"],["4.12000000","2186.61000000"],["4.10000000","3133.85000000"],["4.07000000","270.73000000"]],"a":[]}},{"timeToSleep":1042,"data":{"e":"depthUpdate","E":1672242210720,"s":"TORNBUSD","U":113354857,"u":113354860,"b":[["4.20000000","8837.03000000"],["4.18000000","920.00000000"],["4.10000000","1259.64000000"],["4.07000000","2158.76000000"]],"a":[]}},{"timeToSleep":959,"data":{"e":"depthUpdate","E":1672242211720,"s":"TORNBUSD","U":113354861,"u":113354862,"b":[["4.29000000","141.83000000"]],"a":[["5.33000000","11.49000000"]]}},{"timeToSleep":2108,"data":{"e":"depthUpdate","E":1672242213720,"s":"TORNBUSD","U":113354863,"u":113354864,"b":[["4.28000000","1955.69000000"]],"a":[["4.32000000","210.24000000"]]}},{"timeToSleep":892,"data":{"e":"depthUpdate","E":1672242214720,"s":"TORNBUSD","U":113354865,"u":113354865,"b":[["4.27000000","363.25000000"]],"a":[]}},{"timeToSleep":1000,"data":{"e":"depthUpdate","E":1672242215721,"s":"TORNBUSD","U":113354866,"u":113354869,"b":[["4.17000000","259.95000000"],["4.14000000","672.81000000"]],"a":[["4.40000000","61.55000000"],["5.50000000","7841.19000000"]]}},{"timeToSleep":1000,"data":{"e":"depthUpdate","E":1672242216720,"s":"TORNBUSD","U":113354870,"u":113354870,"b":[["4.26000000","298.50000000"]],"a":[]}},{"timeToSleep":1000,"data":{"e":"depthUpdate","E":1672242217720,"s":"TORNBUSD","U":113354871,"u":113354872,"b":[["4.21000000","1484.28000000"],["4.03000000","533.86000000"]],"a":[]}},{"timeToSleep":2000,"data":{"e":"depthUpdate","E":1672242219720,"s":"TORNBUSD","U":113354873,"u":113354873,"b":[["4.05000000","1895.00000000"]],"a":[]}},{"timeToSleep":1002,"data":{"e":"depthUpdate","E":1672242220720,"s":"TORNBUSD","U":113354874,"u":113354874,"b":[],"a":[["4.42000000","173.28000000"]]}},{"timeToSleep":998,"data":{"e":"depthUpdate","E":1672242221720,"s":"TORNBUSD","U":113354875,"u":113354879,"b":[["4.21000000","1780.67000000"],["4.12000000","2173.88000000"]],"a":[["4.37000000","648.66000000"],["4.41000000","152.47000000"]]}},{"timeToSleep":1000,"data":{"e":"depthUpdate","E":1672242222720,"s":"TORNBUSD","U":113354880,"u":113354883,"b":[["4.19000000","454.73000000"],["4.11000000","280.03000000"]],"a":[["4.32000000","333.23000000"],["4.33000000","138.78000000"]]}},{"timeToSleep":1002,"data":{"e":"depthUpdate","E":1672242223720,"s":"TORNBUSD","U":113354884,"u":113354889,"b":[["4.27000000","382.43000000"],["4.17000000","331.76000000"],["4.07000000","2219.57000000"],["4.05000000","1942.64000000"],["4.04000000","277.48000000"]],"a":[]}},{"timeToSleep":998,"data":{"e":"depthUpdate","E":1672242224721,"s":"TORNBUSD","U":113354890,"u":113354890,"b":[],"a":[["4.48000000","951.94000000"]]}},{"timeToSleep":1001,"data":{"e":"depthUpdate","E":1672242225720,"s":"TORNBUSD","U":113354891,"u":113354906,"b":[["4.31000000","163.18000000"],["4.09000000","66.02000000"],["4.08000000","84.90000000"],["4.06000000","784.01000000"],["4.05000000","1942.64000000"],["4.03000000","581.73000000"],["4.02000000","153.00000000"],["4.01000000","279.33000000"],["4.00000000","25972.09000000"],["3.97000000","3225.44000000"],["3.95000000","1017.59000000"]],"a":[["4.42000000","327.88000000"]]}},{"timeToSleep":1026,"data":{"e":"depthUpdate","E":1672242226721,"s":"TORNBUSD","U":113354907,"u":113354907,"b":[["4.28000000","1477.72000000"]],"a":[]}},{"timeToSleep":985,"data":{"e":"depthUpdate","E":1672242227721,"s":"TORNBUSD","U":113354908,"u":113354911,"b":[["4.30000000","543.51000000"],["4.28000000","1391.90000000"]],"a":[["4.48000000","962.17000000"],["4.95000000","10029.61000000"]]}},{"timeToSleep":986,"data":{"e":"depthUpdate","E":1672242228721,"s":"TORNBUSD","U":113354912,"u":113354912,"b":[["4.21000000","1484.28000000"]],"a":[]}},{"timeToSleep":1005,"data":{"e":"depthUpdate","E":1672242229721,"s":"TORNBUSD","U":113354913,"u":113354914,"b":[["4.31000000","367.71000000"],["4.12000000","2149.85000000"]],"a":[]}},{"timeToSleep":1010,"data":{"e":"depthUpdate","E":1672242230721,"s":"TORNBUSD","U":113354915,"u":113354915,"b":[],"a":[["4.32000000","352.23000000"]]}},{"timeToSleep":987,"data":{"e":"depthUpdate","E":1672242231721,"s":"TORNBUSD","U":113354916,"u":113354916,"b":[["4.25000000","1321.97000000"]],"a":[]}},{"timeToSleep":2001,"data":{"e":"depthUpdate","E":1672242233721,"s":"TORNBUSD","U":113354917,"u":113354917,"b":[],"a":[["4.61000000","163.22000000"]]}},{"timeToSleep":2001,"data":{"e":"depthUpdate","E":1672242235721,"s":"TORNBUSD","U":113354918,"u":113354920,"b":[["4.12000000","2174.08000000"]],"a":[["18.00000000","9342.10000000"],["21.00000000","4768.71000000"]]}},{"timeToSleep":3000,"data":{"e":"depthUpdate","E":1672242238721,"s":"TORNBUSD","U":113354921,"u":113354924,"b":[["4.11000000","251.70000000"],["4.07000000","2266.97000000"],["4.05000000","1895.00000000"],["4.03000000","533.86000000"]],"a":[]}},{"timeToSleep":1014,"data":{"e":"depthUpdate","E":1672242239721,"s":"TORNBUSD","U":113354925,"u":113354934,"b":[["4.25000000","1269.61000000"],["4.13000000","779.95000000"],["4.12000000","2202.34000000"],["4.05000000","1866.26000000"],["4.03000000","582.13000000"]],"a":[["4.32000000","244.59000000"],["4.33000000","167.12000000"],["4.34000000","287.44000000"]]}},{"timeToSleep":985,"data":{"e":"depthUpdate","E":1672242240721,"s":"TORNBUSD","U":113354935,"u":113354939,"b":[["4.30000000","611.74000000"],["4.29000000","130.78000000"],["4.28000000","1323.67000000"],["4.24000000","574.77000000"],["4.03000000","553.25000000"]],"a":[]}},{"timeToSleep":1001,"data":{"e":"depthUpdate","E":1672242241721,"s":"TORNBUSD","U":113354940,"u":113354942,"b":[["4.05000000","1847.60000000"]],"a":[["4.37000000","645.10000000"]]}},{"timeToSleep":999,"data":{"e":"depthUpdate","E":1672242242721,"s":"TORNBUSD","U":113354943,"u":113354944,"b":[["4.06000000","831.93000000"],["4.03000000","582.38000000"]],"a":[]}},{"timeToSleep":1001,"data":{"e":"depthUpdate","E":1672242243721,"s":"TORNBUSD","U":113354945,"u":113354950,"b":[["4.31000000","302.72000000"],["4.23000000","680.25000000"],["4.21000000","1437.77000000"]],"a":[["4.46000000","329.83000000"],["21.00000000","4777.43000000"]]}},{"timeToSleep":999,"data":{"e":"depthUpdate","E":1672242244721,"s":"TORNBUSD","U":113354951,"u":113354954,"b":[["4.24000000","522.30000000"],["4.07000000","378.94000000"]],"a":[["4.43000000","971.64000000"],["5.00000000","5634.37000000"]]}},{"timeToSleep":1000,"data":{"e":"depthUpdate","E":1672242245722,"s":"TORNBUSD","U":113354955,"u":113354957,"b":[["4.25000000","1321.97000000"],["4.13000000","2640.55000000"]],"a":[["4.33000000","258.40000000"]]}},{"timeToSleep":1003,"data":{"e":"depthUpdate","E":1672242246721,"s":"TORNBUSD","U":113354958,"u":113354961,"b":[["4.31000000","245.54000000"],["4.14000000","719.76000000"],["4.13000000","2593.48000000"]],"a":[["4.32000000","272.93000000"],["4.33000000","230.06000000"]]}},{"timeToSleep":1002,"data":{"e":"depthUpdate","E":1672242247722,"s":"TORNBUSD","U":113354962,"u":113354962,"b":[["4.24000000","574.77000000"]],"a":[]}},{"timeToSleep":996,"data":{"e":"depthUpdate","E":1672242248722,"s":"TORNBUSD","U":113354963,"u":113354963,"b":[["4.15000000","798.09000000"]],"a":[]}},{"timeToSleep":1000,"data":{"e":"depthUpdate","E":1672242249722,"s":"TORNBUSD","U":113354964,"u":113354968,"b":[["4.28000000","1794.00000000"],["4.27000000","334.86000000"],["4.11000000","191.49000000"]],"a":[["4.40000000","399.74000000"],["21.00000000","4722.68000000"]]}},{"timeToSleep":999,"data":{"e":"depthUpdate","E":1672242250722,"s":"TORNBUSD","U":113354969,"u":113354970,"b":[["4.15000000","800.90000000"]],"a":[["4.50000000","1701.33000000"]]}},{"timeToSleep":1000,"data":{"e":"depthUpdate","E":1672242251722,"s":"TORNBUSD","U":113354971,"u":113354972,"b":[],"a":[["4.41000000","136.57000000"],["4.80000000","190.56000000"]]}},{"timeToSleep":998,"data":{"e":"depthUpdate","E":1672242252722,"s":"TORNBUSD","U":113354973,"u":113354974,"b":[["4.07000000","331.54000000"]],"a":[["4.38000000","549.14000000"]]}},{"timeToSleep":1008,"data":{"e":"depthUpdate","E":1672242253722,"s":"TORNBUSD","U":113354975,"u":113354977,"b":[["4.30000000","574.22000000"],["4.28000000","1787.29000000"]],"a":[["4.63000000","74.09000000"]]}},{"timeToSleep":995,"data":{"e":"depthUpdate","E":1672242254722,"s":"TORNBUSD","U":113354978,"u":113354981,"b":[["4.24000000","522.36000000"],["4.23000000","683.79000000"],["4.07000000","379.34000000"]],"a":[["4.60000000","2056.08000000"]]}},{"timeToSleep":1004,"data":{"e":"depthUpdate","E":1672242255722,"s":"TORNBUSD","U":113354982,"u":113354984,"b":[["4.31000000","282.97000000"],["4.24000000","469.95000000"],["4.02000000","105.01000000"]],"a":[]}},{"timeToSleep":996,"data":{"e":"depthUpdate","E":1672242256722,"s":"TORNBUSD","U":113354985,"u":113354985,"b":[["4.24000000","467.49000000"]],"a":[]}},{"timeToSleep":1001,"data":{"e":"depthUpdate","E":1672242257722,"s":"TORNBUSD","U":113354986,"u":113354986,"b":[["4.02000000","153.40000000"]],"a":[]}},{"timeToSleep":1007,"data":{"e":"depthUpdate","E":1672242258722,"s":"TORNBUSD","U":113354987,"u":113354989,"b":[["4.31000000","252.96000000"],["4.29000000","125.32000000"]],"a":[]}},{"timeToSleep":1993,"data":{"e":"depthUpdate","E":1672242260722,"s":"TORNBUSD","U":113354990,"u":113354992,"b":[["4.31000000","217.17000000"],["4.30000000","570.19000000"]],"a":[]}},{"timeToSleep":1998,"data":{"e":"depthUpdate","E":1672242262722,"s":"TORNBUSD","U":113354993,"u":113354994,"b":[["4.31000000","221.19000000"]],"a":[["4.33000000","113.51000000"]]}},{"timeToSleep":1001,"data":{"e":"depthUpdate","E":1672242263722,"s":"TORNBUSD","U":113354995,"u":113354995,"b":[],"a":[["4.32000000","244.59000000"],["4.33000000","141.85000000"]]}},{"timeToSleep":1000,"data":{"e":"depthUpdate","E":1672242264722,"s":"TORNBUSD","U":113354996,"u":113354996,"b":[["4.24000000","415.08000000"]],"a":[]}},{"timeToSleep":2000,"data":{"e":"depthUpdate","E":1672242266723,"s":"TORNBUSD","U":113354997,"u":113354997,"b":[["4.20000000","8931.98000000"]],"a":[]}},{"timeToSleep":998,"data":{"e":"depthUpdate","E":1672242267722,"s":"TORNBUSD","U":113354998,"u":113354999,"b":[["4.31000000","104.64000000"]],"a":[["4.32000000","183.49000000"]]}},{"timeToSleep":1003,"data":{"e":"depthUpdate","E":1672242268723,"s":"TORNBUSD","U":113355000,"u":113355000,"b":[["4.27000000","306.82000000"]],"a":[]}},{"timeToSleep":1011,"data":{"e":"depthUpdate","E":1672242269722,"s":"TORNBUSD","U":113355001,"u":113355001,"b":[["4.27000000","311.81000000"]],"a":[]}},{"timeToSleep":990,"data":{"e":"depthUpdate","E":1672242270723,"s":"TORNBUSD","U":113355002,"u":113355003,"b":[["4.31000000","100.10000000"]],"a":[["4.32000000","168.10000000"]]}},{"timeToSleep":998,"data":{"e":"depthUpdate","E":1672242271723,"s":"TORNBUSD","U":113355004,"u":113355005,"b":[["4.31000000","105.09000000"],["4.27000000","306.82000000"]],"a":[]}},{"timeToSleep":2008,"data":{"e":"depthUpdate","E":1672242273723,"s":"TORNBUSD","U":113355006,"u":113355006,"b":[],"a":[["4.38000000","444.44000000"]]}},{"timeToSleep":998,"data":{"e":"depthUpdate","E":1672242274723,"s":"TORNBUSD","U":113355007,"u":113355008,"b":[["4.31000000","100.10000000"]],"a":[["4.32000000","163.11000000"]]}},{"timeToSleep":1995,"data":{"e":"depthUpdate","E":1672242276723,"s":"TORNBUSD","U":113355009,"u":113355009,"b":[["4.30000000","563.45000000"]],"a":[]}},{"timeToSleep":999,"data":{"e":"depthUpdate","E":1672242277723,"s":"TORNBUSD","U":113355010,"u":113355020,"b":[["4.31000000","0.00000000"],["4.30000000","561.16000000"],["4.21000000","1263.36000000"],["4.17000000","262.00000000"],["4.07000000","331.54000000"],["4.05000000","1895.24000000"]],"a":[["4.31000000","24.84000000"],["4.32000000","138.27000000"]]}},{"timeToSleep":1001,"data":{"e":"depthUpdate","E":1672242278723,"s":"TORNBUSD","U":113355021,"u":113355031,"b":[["4.23000000","660.18000000"],["4.21000000","1287.08000000"],["4.14000000","611.30000000"],["4.13000000","732.88000000"],["4.12000000","2311.31000000"],["4.05000000","3792.59000000"]],"a":[["4.31000000","0.00000000"],["4.32000000","158.78000000"],["4.34000000","266.93000000"]]}},{"timeToSleep":1001,"data":{"e":"depthUpdate","E":1672242279723,"s":"TORNBUSD","U":113355032,"u":113355035,"b":[["4.14000000","564.35000000"],["4.13000000","779.95000000"]],"a":[["4.31000000","0.00000000"]]}},{"timeToSleep":1000,"data":{"e":"depthUpdate","E":1672242280723,"s":"TORNBUSD","U":113355036,"u":113355037,"b":[["4.20000000","8719.84000000"]],"a":[["4.31000000","24.84000000"]]}},{"timeToSleep":1014,"data":{"e":"depthUpdate","E":1672242281723,"s":"TORNBUSD","U":113355038,"u":113355043,"b":[["4.19000000","669.15000000"],["4.04000000","147.61000000"]],"a":[["4.31000000","24.84000000"],["4.33000000","141.85000000"]]}},{"timeToSleep":1984,"data":{"e":"depthUpdate","E":1672242283723,"s":"TORNBUSD","U":113355044,"u":113355047,"b":[["4.30000000","623.19000000"],["4.05000000","3923.22000000"]],"a":[["4.31000000","24.84000000"]]}},{"timeToSleep":1005,"data":{"e":"depthUpdate","E":1672242284723,"s":"TORNBUSD","U":113355048,"u":113355054,"b":[["4.15000000","764.82000000"]],"a":[["4.31000000","24.84000000"],["4.32000000","139.78000000"],["4.33000000","141.85000000"],["4.40000000","464.96000000"]]}},{"timeToSleep":997,"data":{"e":"depthUpdate","E":1672242285723,"s":"TORNBUSD","U":113355055,"u":113355059,"b":[["4.15000000","800.90000000"],["4.10000000","1235.49000000"],["4.09000000","90.43000000"]],"a":[["4.31000000","24.84000000"]]}},{"timeToSleep":999,"data":{"e":"depthUpdate","E":1672242286723,"s":"TORNBUSD","U":113355060,"u":113355062,"b":[["4.30000000","370.13000000"]],"a":[["4.31000000","0.00000000"]]}},{"timeToSleep":1001,"data":{"e":"depthUpdate","E":1672242287723,"s":"TORNBUSD","U":113355063,"u":113355069,"b":[["4.15000000","812.92000000"],["4.06000000","2724.61000000"],["4.05000000","2025.87000000"]],"a":[["4.31000000","0.00000000"],["4.33000000","166.69000000"],["4.65000000","204.49000000"]]}},{"timeToSleep":1999,"data":{"e":"depthUpdate","E":1672242289723,"s":"TORNBUSD","U":113355070,"u":113355079,"b":[["4.30000000","312.15000000"],["4.11000000","252.21000000"]],"a":[["4.31000000","0.00000000"],["4.33000000","166.69000000"],["4.34000000","283.35000000"],["21.50000000","827.28000000"]]}},{"timeToSleep":3001,"data":{"e":"depthUpdate","E":1672242292724,"s":"TORNBUSD","U":113355080,"u":113355082,"b":[],"a":[["4.31000000","45.97000000"],["4.32000000","164.62000000"],["4.33000000","141.85000000"]]}},{"timeToSleep":1001,"data":{"e":"depthUpdate","E":1672242293724,"s":"TORNBUSD","U":113355083,"u":113355088,"b":[["4.30000000","314.49000000"],["4.06000000","831.93000000"],["4.05000000","3923.22000000"]],"a":[["4.31000000","45.97000000"],["4.32000000","139.78000000"]]}},{"timeToSleep":1037,"data":{"e":"depthUpdate","E":1672242294724,"s":"TORNBUSD","U":113355089,"u":113355090,"b":[],"a":[["4.31000000","24.84000000"],["4.32000000","139.10000000"]]}},{"timeToSleep":966,"data":{"e":"depthUpdate","E":1672242295725,"s":"TORNBUSD","U":113355091,"u":113355093,"b":[["4.25000000","1269.61000000"]],"a":[["4.31000000","0.00000000"],["4.33000000","166.69000000"]]}},{"timeToSleep":995,"data":{"e":"depthUpdate","E":1672242296724,"s":"TORNBUSD","U":113355094,"u":113355101,"b":[["4.23000000","683.79000000"],["4.21000000","1263.36000000"],["4.14000000","672.81000000"],["4.12000000","4067.46000000"],["4.05000000","2025.87000000"]],"a":[["4.31000000","24.84000000"],["4.33000000","141.85000000"]]}},{"timeToSleep":2000,"data":{"e":"depthUpdate","E":1672242298724,"s":"TORNBUSD","U":113355102,"u":113355102,"b":[],"a":[["4.31000000","0.00000000"],["4.32000000","137.24000000"]]}},{"timeToSleep":1002,"data":{"e":"depthUpdate","E":1672242299724,"s":"TORNBUSD","U":113355103,"u":113355106,"b":[["4.21000000","1559.75000000"]],"a":[["4.32000000","130.15000000"],["4.35000000","534.26000000"],["11.00000000","5874.57000000"]]}},{"timeToSleep":1011,"data":{"e":"depthUpdate","E":1672242300724,"s":"TORNBUSD","U":113355107,"u":113355110,"b":[["4.23000000","605.23000000"],["4.22000000","909.65000000"]],"a":[["4.32000000","191.25000000"]]}},{"timeToSleep":988,"data":{"e":"depthUpdate","E":1672242301724,"s":"TORNBUSD","U":113355111,"u":113355112,"b":[["4.20000000","8624.89000000"]],"a":[["4.84000000","31.88000000"]]}},{"timeToSleep":1001,"data":{"e":"depthUpdate","E":1672242302724,"s":"TORNBUSD","U":113355113,"u":113355116,"b":[["4.26000000","296.10000000"]],"a":[["4.32000000","214.30000000"],["4.44000000","460.15000000"],["5.40000000","3050.19000000"]]}},{"timeToSleep":1012,"data":{"e":"depthUpdate","E":1672242303724,"s":"TORNBUSD","U":113355117,"u":113355118,"b":[["4.23000000","581.62000000"],["4.07000000","307.02000000"]],"a":[]}},{"timeToSleep":988,"data":{"e":"depthUpdate","E":1672242304725,"s":"TORNBUSD","U":113355119,"u":113355119,"b":[["4.05000000","2018.05000000"]],"a":[]}},{"timeToSleep":1003,"data":{"e":"depthUpdate","E":1672242305724,"s":"TORNBUSD","U":113355120,"u":113355120,"b":[],"a":[["17.00000000","6591.01000000"]]}},{"timeToSleep":997,"data":{"e":"depthUpdate","E":1672242306724,"s":"TORNBUSD","U":113355121,"u":113355122,"b":[["4.05000000","2025.93000000"]],"a":[["21.50000000","821.40000000"]]}},{"timeToSleep":1000,"data":{"e":"depthUpdate","E":1672242307724,"s":"TORNBUSD","U":113355123,"u":113355123,"b":[],"a":[["21.00000000","4777.43000000"]]}},{"timeToSleep":1000,"data":{"e":"depthUpdate","E":1672242308724,"s":"TORNBUSD","U":113355124,"u":113355127,"b":[["4.26000000","773.75000000"],["4.11000000","223.88000000"]],"a":[["4.32000000","191.25000000"],["5.40000000","4577.63000000"]]}},{"timeToSleep":999,"data":{"e":"depthUpdate","E":1672242309724,"s":"TORNBUSD","U":113355128,"u":113355129,"b":[["4.24000000","362.61000000"],["4.14000000","505.42000000"]],"a":[]}},{"timeToSleep":1001,"data":{"e":"depthUpdate","E":1672242310724,"s":"TORNBUSD","U":113355130,"u":113355131,"b":[["4.14000000","409.77000000"],["4.11000000","252.44000000"]],"a":[]}},{"timeToSleep":1002,"data":{"e":"depthUpdate","E":1672242311725,"s":"TORNBUSD","U":113355132,"u":113355136,"b":[["4.30000000","291.44000000"],["4.28000000","1794.00000000"],["4.22000000","1409.65000000"],["4.14000000","674.99000000"]],"a":[]}},{"timeToSleep":1013,"data":{"e":"depthUpdate","E":1672242312725,"s":"TORNBUSD","U":113355137,"u":113355142,"b":[["4.23000000","660.18000000"],["4.22000000","1330.90000000"],["4.14000000","566.53000000"],["4.12000000","4176.43000000"],["4.05000000","1985.76000000"]],"a":[["4.38000000","428.43000000"]]}},{"timeToSleep":993,"data":{"e":"depthUpdate","E":1672242313725,"s":"TORNBUSD","U":113355143,"u":113355144,"b":[["4.04000000","187.88000000"]],"a":[["4.41000000","152.47000000"]]}},{"timeToSleep":1991,"data":{"e":"depthUpdate","E":1672242315725,"s":"TORNBUSD","U":113355145,"u":113355145,"b":[["4.29000000","167.18000000"]],"a":[]}},{"timeToSleep":2002,"data":{"e":"depthUpdate","E":1672242317725,"s":"TORNBUSD","U":113355146,"u":113355147,"b":[["4.31000000","110.13000000"],["4.30000000","229.41000000"]],"a":[]}},{"timeToSleep":1012,"data":{"e":"depthUpdate","E":1672242318725,"s":"TORNBUSD","U":113355148,"u":113355149,"b":[["4.13000000","2640.55000000"],["4.12000000","2311.31000000"]],"a":[]}},{"timeToSleep":986,"data":{"e":"depthUpdate","E":1672242319725,"s":"TORNBUSD","U":113355150,"u":113355150,"b":[["4.13000000","2593.48000000"]],"a":[]}},{"timeToSleep":1010,"data":{"e":"depthUpdate","E":1672242320725,"s":"TORNBUSD","U":113355151,"u":113355153,"b":[["4.24000000","346.06000000"],["4.20000000","8535.77000000"],["4.14000000","613.48000000"]],"a":[]}},{"timeToSleep":991,"data":{"e":"depthUpdate","E":1672242321725,"s":"TORNBUSD","U":113355154,"u":113355156,"b":[["4.25000000","1286.12000000"],["4.16000000","398.65000000"]],"a":[["15.00000000","6653.46000000"]]}},{"timeToSleep":1999,"data":{"e":"depthUpdate","E":1672242323725,"s":"TORNBUSD","U":113355157,"u":113355157,"b":[["4.21000000","1263.36000000"]],"a":[]}},{"timeToSleep":1003,"data":{"e":"depthUpdate","E":1672242324726,"s":"TORNBUSD","U":113355158,"u":113355158,"b":[["4.31000000","86.42000000"]],"a":[]}},{"timeToSleep":2998,"data":{"e":"depthUpdate","E":1672242327725,"s":"TORNBUSD","U":113355159,"u":113355160,"b":[["4.26000000","776.95000000"]],"a":[["4.35000000","738.79000000"]]}},{"timeToSleep":1065,"data":{"e":"depthUpdate","E":1672242328725,"s":"TORNBUSD","U":113355161,"u":113355161,"b":[],"a":[["4.60000000","1939.35000000"]]}},{"timeToSleep":1936,"data":{"e":"depthUpdate","E":1672242330726,"s":"TORNBUSD","U":113355162,"u":113355163,"b":[["4.15000000","412.92000000"]],"a":[["4.80000000","307.29000000"]]}},{"timeToSleep":2004,"data":{"e":"depthUpdate","E":1672242332725,"s":"TORNBUSD","U":113355164,"u":113355166,"b":[["4.31000000","193.77000000"],["4.13000000","732.88000000"],["4.12000000","4176.43000000"]],"a":[]}},{"timeToSleep":996,"data":{"e":"depthUpdate","E":1672242333725,"s":"TORNBUSD","U":113355167,"u":113355170,"b":[["4.25000000","1288.59000000"]],"a":[["4.32000000","96.60000000"],["4.45000000","760.39000000"],["4.46000000","258.69000000"]]}},{"timeToSleep":3016,"data":{"e":"depthUpdate","E":1672242336726,"s":"TORNBUSD","U":113355171,"u":113355171,"b":[["4.09000000","61.96000000"]],"a":[]}},{"timeToSleep":984,"data":{"e":"depthUpdate","E":1672242337726,"s":"TORNBUSD","U":113355172,"u":113355174,"b":[["4.13000000","716.82000000"],["4.00000000","25520.54000000"]],"a":[["4.40000000","520.65000000"]]}},{"timeToSleep":1000,"data":{"e":"depthUpdate","E":1672242338726,"s":"TORNBUSD","U":113355175,"u":113355175,"b":[["4.08000000","113.67000000"]],"a":[]}},{"timeToSleep":1003,"data":{"e":"depthUpdate","E":1672242339726,"s":"TORNBUSD","U":113355176,"u":113355178,"b":[["4.16000000","414.72000000"],["4.14000000","566.53000000"],["4.13000000","763.89000000"]],"a":[]}},{"timeToSleep":2034,"data":{"e":"depthUpdate","E":1672242341726,"s":"TORNBUSD","U":113355179,"u":113355179,"b":[["4.31000000","188.48000000"]],"a":[]}},{"timeToSleep":1964,"data":{"e":"depthUpdate","E":1672242343726,"s":"TORNBUSD","U":113355180,"u":113355180,"b":[["4.12000000","4148.17000000"]],"a":[]}},{"timeToSleep":2000,"data":{"e":"depthUpdate","E":1672242345726,"s":"TORNBUSD","U":113355181,"u":113355183,"b":[["4.27000000","362.38000000"],["4.11000000","281.00000000"],["3.35000000","2110.48000000"]],"a":[]}},{"timeToSleep":1126,"data":{"e":"depthUpdate","E":1672242346726,"s":"TORNBUSD","U":113355184,"u":113355184,"b":[],"a":[["4.50000000","1694.38000000"]]}},{"timeToSleep":875,"data":{"e":"depthUpdate","E":1672242347726,"s":"TORNBUSD","U":113355185,"u":113355189,"b":[["4.31000000","244.04000000"],["4.29000000","567.18000000"],["4.27000000","306.82000000"]],"a":[["4.32000000","51.00000000"],["20.00000000","28897.94000000"]]}},{"timeToSleep":998,"data":{"e":"depthUpdate","E":1672242348726,"s":"TORNBUSD","U":113355190,"u":113355192,"b":[["4.13000000","2624.49000000"],["4.12000000","2283.05000000"]],"a":[["4.38000000","423.28000000"]]}},{"timeToSleep":999,"data":{"e":"depthUpdate","E":1672242349726,"s":"TORNBUSD","U":113355193,"u":113355194,"b":[["4.14000000","675.00000000"],["4.12000000","2174.08000000"]],"a":[]}},{"timeToSleep":1002,"data":{"e":"depthUpdate","E":1672242350726,"s":"TORNBUSD","U":113355195,"u":113355199,"b":[["4.31000000","192.87000000"],["4.30000000","235.22000000"]],"a":[["4.32000000","0.00000000"],["4.33000000","131.14000000"]]}},{"timeToSleep":999,"data":{"e":"depthUpdate","E":1672242351726,"s":"TORNBUSD","U":113355200,"u":113355202,"b":[["4.13000000","763.89000000"],["4.12000000","4039.20000000"]],"a":[["4.33000000","102.80000000"],["4.34000000","311.69000000"]]}},{"timeToSleep":1000,"data":{"e":"depthUpdate","E":1672242352726,"s":"TORNBUSD","U":113355203,"u":113355203,"b":[["4.29000000","612.18000000"]],"a":[]}},{"timeToSleep":2003,"data":{"e":"depthUpdate","E":1672242354726,"s":"TORNBUSD","U":113355204,"u":113355204,"b":[],"a":[["4.38000000","430.23000000"]]}},{"timeToSleep":1998,"data":{"e":"depthUpdate","E":1672242356726,"s":"TORNBUSD","U":113355205,"u":113355205,"b":[["4.28000000","1697.40000000"]],"a":[]}},{"timeToSleep":3000,"data":{"e":"depthUpdate","E":1672242359727,"s":"TORNBUSD","U":113355206,"u":113355213,"b":[["4.31000000","20.61000000"],["4.30000000","239.13000000"],["4.12000000","2174.08000000"],["4.06000000","879.45000000"],["4.05000000","1938.12000000"]],"a":[["4.33000000","87.85000000"],["4.37000000","660.21000000"]]}},{"timeToSleep":1050,"data":{"e":"depthUpdate","E":1672242360727,"s":"TORNBUSD","U":113355214,"u":113355225,"b":[["4.31000000","69.95000000"],["4.30000000","242.51000000"],["4.26000000","299.30000000"],["4.14000000","721.95000000"],["4.13000000","2577.42000000"]],"a":[["4.33000000","67.95000000"],["4.37000000","645.10000000"],["4.38000000","423.28000000"]]}},{"timeToSleep":949,"data":{"e":"depthUpdate","E":1672242361727,"s":"TORNBUSD","U":113355226,"u":113355236,"b":[["4.32000000","22.94000000"],["4.17000000","273.87000000"],["4.15000000","400.90000000"],["4.11000000","293.04000000"],["4.08000000","101.54000000"]],"a":[["4.33000000","117.49000000"],["4.34000000","184.91000000"],["4.40000000","503.85000000"],["4.42000000","344.60000000"]]}},{"timeToSleep":1005,"data":{"e":"depthUpdate","E":1672242362727,"s":"TORNBUSD","U":113355237,"u":113355244,"b":[["4.27000000","336.81000000"],["4.25000000","1312.09000000"],["4.18000000","1204.20000000"],["4.16000000","128.96000000"],["4.13000000","716.82000000"],["4.12000000","4039.20000000"]],"a":[]}},{"timeToSleep":999,"data":{"e":"depthUpdate","E":1672242363727,"s":"TORNBUSD","U":113355245,"u":113355249,"b":[["4.16000000","236.93000000"],["4.14000000","613.48000000"],["4.07000000","246.21000000"]],"a":[["4.33000000","0.00000000"]]}},{"timeToSleep":1998,"data":{"e":"depthUpdate","E":1672242365727,"s":"TORNBUSD","U":113355250,"u":113355254,"b":[["4.32000000","0.00000000"],["4.29000000","617.12000000"]],"a":[["4.32000000","65.58000000"],["4.34000000","207.85000000"]]}},{"timeToSleep":1001,"data":{"e":"depthUpdate","E":1672242366727,"s":"TORNBUSD","U":113355255,"u":113355266,"b":[["4.25000000","1285.07000000"],["4.23000000","683.79000000"],["4.17000000","309.48000000"],["4.16000000","128.96000000"],["4.15000000","364.82000000"],["4.14000000","721.94000000"],["4.13000000","776.74000000"],["4.11000000","232.32000000"],["4.03000000","578.67000000"]],"a":[["4.32000000","61.03000000"],["4.40000000","500.92000000"]]}},{"timeToSleep":1113,"data":{"e":"depthUpdate","E":1672242367727,"s":"TORNBUSD","U":113355267,"u":113355271,"b":[["4.18000000","1180.52000000"],["4.06000000","883.14000000"],["3.98000000","1006.65000000"],["3.96000000","23.34000000"]],"a":[["4.42000000","327.88000000"]]}},{"timeToSleep":921,"data":{"e":"depthUpdate","E":1672242368727,"s":"TORNBUSD","U":113355272,"u":113355273,"b":[["4.27000000","340.31000000"]],"a":[["4.40000000","517.72000000"]]}},{"timeToSleep":966,"data":{"e":"depthUpdate","E":1672242369727,"s":"TORNBUSD","U":113355274,"u":113355275,"b":[],"a":[["4.50000000","1701.33000000"],["20.00000000","28423.91000000"]]}},{"timeToSleep":1006,"data":{"e":"depthUpdate","E":1672242370727,"s":"TORNBUSD","U":113355276,"u":113355280,"b":[["4.31000000","3.56000000"]],"a":[["4.33000000","88.12000000"],["5.03000000","18.59000000"]]}},{"timeToSleep":1100,"data":{"e":"depthUpdate","E":1672242371727,"s":"TORNBUSD","U":113355281,"u":113355282,"b":[["4.15000000","864.82000000"]],"a":[["4.36000000","582.87000000"]]}},{"timeToSleep":1027,"data":{"e":"depthUpdate","E":1672242372727,"s":"TORNBUSD","U":113355283,"u":113355284,"b":[["4.28000000","1694.11000000"]],"a":[["4.59000000","28.60000000"]]}},{"timeToSleep":2968,"data":{"e":"depthUpdate","E":1672242375727,"s":"TORNBUSD","U":113355285,"u":113355285,"b":[["4.31000000","64.57000000"]],"a":[]}},{"timeToSleep":1021,"data":{"e":"depthUpdate","E":1672242376728,"s":"TORNBUSD","U":113355286,"u":113355289,"b":[["4.31000000","141.74000000"]],"a":[["4.34000000","224.74000000"],["4.41000000","136.57000000"]]}},{"timeToSleep":1026,"data":{"e":"depthUpdate","E":1672242377728,"s":"TORNBUSD","U":113355290,"u":113355290,"b":[],"a":[["4.39000000","289.04000000"]]}},{"timeToSleep":1852,"data":{"e":"depthUpdate","E":1672242379728,"s":"TORNBUSD","U":113355291,"u":113355292,"b":[["4.30000000","377.85000000"]],"a":[["21.88000000","0.00000000"]]}},{"timeToSleep":1118,"data":{"e":"depthUpdate","E":1672242380728,"s":"TORNBUSD","U":113355293,"u":113355294,"b":[["4.21000000","1122.27000000"],["4.14000000","674.99000000"]],"a":[]}},{"timeToSleep":922,"data":{"e":"depthUpdate","E":1672242381728,"s":"TORNBUSD","U":113355295,"u":113355297,"b":[["4.31000000","418.13000000"],["4.13000000","823.81000000"],["4.12000000","3954.40000000"]],"a":[]}},{"timeToSleep":1074,"data":{"e":"depthUpdate","E":1672242382728,"s":"TORNBUSD","U":113355298,"u":113355302,"b":[["4.31000000","433.30000000"],["4.21000000","1264.53000000"],["4.15000000","862.31000000"],["4.14000000","759.38000000"]],"a":[["4.65000000","251.09000000"]]}},{"timeToSleep":970,"data":{"e":"depthUpdate","E":1672242383728,"s":"TORNBUSD","U":113355303,"u":113355304,"b":[["4.20000000","8559.53000000"]],"a":[["7.50000000","3374.22000000"]]}},{"timeToSleep":1033,"data":{"e":"depthUpdate","E":1672242384728,"s":"TORNBUSD","U":113355305,"u":113355305,"b":[["4.28000000","1822.70000000"]],"a":[]}},{"timeToSleep":916,"data":{"e":"depthUpdate","E":1672242385728,"s":"TORNBUSD","U":113355306,"u":113355308,"b":[["4.31000000","426.20000000"]],"a":[["4.35000000","501.35000000"],["21.56000000","474.03000000"]]}},{"timeToSleep":2150,"data":{"e":"depthUpdate","E":1672242387728,"s":"TORNBUSD","U":113355309,"u":113355309,"b":[["3.50000000","2006.73000000"]],"a":[]}},{"timeToSleep":925,"data":{"e":"depthUpdate","E":1672242388728,"s":"TORNBUSD","U":113355310,"u":113355312,"b":[["4.30000000","373.81000000"],["4.17000000","273.87000000"],["4.08000000","73.01000000"]],"a":[]}},{"timeToSleep":1021,"data":{"e":"depthUpdate","E":1672242389728,"s":"TORNBUSD","U":113355313,"u":113355314,"b":[["4.27000000","324.95000000"]],"a":[["4.39000000","214.04000000"]]}},{"timeToSleep":871,"data":{"e":"depthUpdate","E":1672242390729,"s":"TORNBUSD","U":113355315,"u":113355317,"b":[["4.16000000","164.95000000"],["4.08000000","101.78000000"],["4.06000000","944.60000000"]],"a":[]}},{"timeToSleep":1083,"data":{"e":"depthUpdate","E":1672242391729,"s":"TORNBUSD","U":113355318,"u":113355319,"b":[["4.17000000","262.00000000"]],"a":[["4.36000000","820.31000000"]]}},{"timeToSleep":1118,"data":{"e":"depthUpdate","E":1672242392729,"s":"TORNBUSD","U":113355320,"u":113355320,"b":[["3.94000000","69.95000000"]],"a":[]}},{"timeToSleep":924,"data":{"e":"depthUpdate","E":1672242393728,"s":"TORNBUSD","U":113355321,"u":113355321,"b":[],"a":[["4.34000000","208.32000000"]]}},{"timeToSleep":919,"data":{"e":"depthUpdate","E":1672242394729,"s":"TORNBUSD","U":113355322,"u":113355322,"b":[],"a":[["4.33000000","182.77000000"]]}},{"timeToSleep":957,"data":{"e":"depthUpdate","E":1672242395729,"s":"TORNBUSD","U":113355323,"u":113355326,"b":[["4.12000000","3982.66000000"],["4.11000000","203.76000000"]],"a":[["4.33000000","211.11000000"],["4.34000000","179.98000000"],["21.44000000","49.17000000"]]}},{"timeToSleep":1091,"data":{"e":"depthUpdate","E":1672242396729,"s":"TORNBUSD","U":113355327,"u":113355329,"b":[],"a":[["4.32000000","0.00000000"],["4.33000000","182.77000000"],["4.34000000","208.32000000"],["4.35000000","505.37000000"]]}},{"timeToSleep":1125,"data":{"e":"depthUpdate","E":1672242397729,"s":"TORNBUSD","U":113355330,"u":113355331,"b":[],"a":[["5.55000000","369.72000000"],["21.50000000","2185.77000000"]]}},{"timeToSleep":1845,"data":{"e":"depthUpdate","E":1672242399729,"s":"TORNBUSD","U":113355332,"u":113355334,"b":[["4.31000000","365.17000000"],["4.28000000","1815.99000000"],["4.13000000","776.74000000"]],"a":[]}},{"timeToSleep":2048,"data":{"e":"depthUpdate","E":1672242401729,"s":"TORNBUSD","U":113355335,"u":113355336,"b":[],"a":[["4.33000000","199.19000000"],["4.48000000","940.03000000"]]}},{"timeToSleep":925,"data":{"e":"depthUpdate","E":1672242402729,"s":"TORNBUSD","U":113355337,"u":113355338,"b":[["3.82000000","2815.91000000"]],"a":[["4.34000000","191.43000000"]]}},{"timeToSleep":1023,"data":{"e":"depthUpdate","E":1672242403729,"s":"TORNBUSD","U":113355339,"u":113355341,"b":[["4.29000000","616.55000000"],["4.16000000","176.94000000"]],"a":[]}},{"timeToSleep":1022,"data":{"e":"depthUpdate","E":1672242404729,"s":"TORNBUSD","U":113355342,"u":113355346,"b":[["4.31000000","374.33000000"]],"a":[["4.33000000","215.42000000"],["4.34000000","270.44000000"]]}},{"timeToSleep":1922,"data":{"e":"depthUpdate","E":1672242406729,"s":"TORNBUSD","U":113355347,"u":113355348,"b":[["4.31000000","421.04000000"]],"a":[]}},{"timeToSleep":1047,"data":{"e":"depthUpdate","E":1672242407729,"s":"TORNBUSD","U":113355349,"u":113355350,"b":[],"a":[["4.33000000","276.43000000"],["4.47000000","464.99000000"]]}},{"timeToSleep":1975,"data":{"e":"depthUpdate","E":1672242409729,"s":"TORNBUSD","U":113355351,"u":113355352,"b":[["4.32000000","345.46000000"],["4.31000000","526.25000000"]],"a":[]}},{"timeToSleep":1096,"data":{"e":"depthUpdate","E":1672242410730,"s":"TORNBUSD","U":113355353,"u":113355356,"b":[["4.32000000","362.71000000"],["4.30000000","359.83000000"]],"a":[["4.34000000","830.93000000"]]}},{"timeToSleep":923,"data":{"e":"depthUpdate","E":1672242411729,"s":"TORNBUSD","U":113355357,"u":113355358,"b":[["4.17000000","190.19000000"]],"a":[["4.35000000","510.52000000"]]}},{"timeToSleep":1026,"data":{"e":"depthUpdate","E":1672242412730,"s":"TORNBUSD","U":113355359,"u":113355365,"b":[["4.32000000","0.00000000"],["4.31000000","272.49000000"],["4.04000000","147.61000000"]],"a":[["4.33000000","261.33000000"],["4.34000000","848.18000000"],["4.35000000","440.23000000"]]}},{"timeToSleep":1022,"data":{"e":"depthUpdate","E":1672242413730,"s":"TORNBUSD","U":113355366,"u":113355373,"b":[["4.31000000","210.61000000"],["4.25000000","1458.28000000"],["4.20000000","8628.81000000"],["4.18000000","1252.16000000"]],"a":[]}},{"timeToSleep":1024,"data":{"e":"depthUpdate","E":1672242414730,"s":"TORNBUSD","U":113355374,"u":113355375,"b":[["4.31000000","196.43000000"],["4.05000000","1978.29000000"]],"a":[]}},{"timeToSleep":2970,"data":{"e":"depthUpdate","E":1672242417730,"s":"TORNBUSD","U":113355376,"u":113355377,"b":[],"a":[["4.33000000","348.51000000"]]}},{"timeToSleep":2049,"data":{"e":"depthUpdate","E":1672242419730,"s":"TORNBUSD","U":113355378,"u":113355379,"b":[["4.20000000","8564.46000000"],["3.90000000","4977.83000000"]],"a":[]}},{"timeToSleep":1945,"data":{"e":"depthUpdate","E":1672242421730,"s":"TORNBUSD","U":113355380,"u":113355384,"b":[["4.32000000","46.05000000"],["4.31000000","200.46000000"],["4.20000000","8629.34000000"],["4.03000000","568.67000000"],["4.02000000","143.40000000"]],"a":[]}},{"timeToSleep":1030,"data":{"e":"depthUpdate","E":1672242422730,"s":"TORNBUSD","U":113355385,"u":113355385,"b":[["4.01000000","269.33000000"]],"a":[]}},{"timeToSleep":1031,"data":{"e":"depthUpdate","E":1672242423730,"s":"TORNBUSD","U":113355386,"u":113355386,"b":[["4.06000000","940.91000000"]],"a":[]}},{"timeToSleep":4900,"data":{"e":"depthUpdate","E":1672242428731,"s":"TORNBUSD","U":113355387,"u":113355388,"b":[["4.32000000","0.00000000"],["4.31000000","118.40000000"]],"a":[]}},{"timeToSleep":1028,"data":{"e":"depthUpdate","E":1672242429730,"s":"TORNBUSD","U":113355389,"u":113355392,"b":[["4.31000000","72.12000000"],["4.30000000","259.78000000"]],"a":[["4.33000000","357.67000000"]]}},{"timeToSleep":1023,"data":{"e":"depthUpdate","E":1672242430730,"s":"TORNBUSD","U":113355393,"u":113355395,"b":[["4.15000000","859.50000000"],["4.13000000","776.74000000"]],"a":[]}},{"timeToSleep":912,"data":{"e":"depthUpdate","E":1672242431730,"s":"TORNBUSD","U":113355396,"u":113355426,"b":[["4.31000000","0.00000000"],["4.30000000","137.37000000"],["4.27000000","321.45000000"],["4.25000000","1288.59000000"],["4.23000000","660.18000000"],["4.22000000","1505.31000000"],["4.21000000","1288.25000000"],["4.20000000","8560.06000000"],["4.18000000","1228.48000000"],["4.17000000","259.95000000"],["4.16000000","200.73000000"],["4.14000000","650.92000000"],["4.12000000","4091.62000000"]],"a":[["4.32000000","229.18000000"],["4.33000000","407.28000000"],["4.34000000","690.78000000"]]}},{"timeToSleep":1142,"data":{"e":"depthUpdate","E":1672242432731,"s":"TORNBUSD","U":113355427,"u":113355432,"b":[["4.30000000","196.99000000"],["4.12000000","2226.50000000"],["4.05000000","3875.64000000"]],"a":[["4.32000000","183.23000000"]]}},{"timeToSleep":932,"data":{"e":"depthUpdate","E":1672242433731,"s":"TORNBUSD","U":113355433,"u":113355437,"b":[["4.23000000","683.79000000"],["4.21000000","1264.53000000"],["4.14000000","759.39000000"],["4.12000000","2117.54000000"]],"a":[["4.33000000","410.63000000"]]}},{"timeToSleep":1008,"data":{"e":"depthUpdate","E":1672242434731,"s":"TORNBUSD","U":113355438,"u":113355439,"b":[["3.98000000","678.06000000"]],"a":[["4.42000000","338.89000000"]]}},{"timeToSleep":917,"data":{"e":"depthUpdate","E":1672242435731,"s":"TORNBUSD","U":113355440,"u":113355442,"b":[["4.12000000","3982.66000000"],["4.05000000","1978.29000000"]],"a":[["4.35000000","443.16000000"]]}},{"timeToSleep":1127,"data":{"e":"depthUpdate","E":1672242436731,"s":"TORNBUSD","U":113355443,"u":113355444,"b":[["4.25000000","1336.67000000"],["3.96000000","356.34000000"]],"a":[]}},{"timeToSleep":928,"data":{"e":"depthUpdate","E":1672242437731,"s":"TORNBUSD","U":113355445,"u":113355446,"b":[],"a":[["4.32000000","160.95000000"],["4.36000000","582.87000000"]]}},{"timeToSleep":946,"data":{"e":"depthUpdate","E":1672242438731,"s":"TORNBUSD","U":113355447,"u":113355447,"b":[["4.30000000","297.04000000"]],"a":[]}},{"timeToSleep":1106,"data":{"e":"depthUpdate","E":1672242439731,"s":"TORNBUSD","U":113355448,"u":113355448,"b":[],"a":[["4.33000000","393.74000000"]]}},{"timeToSleep":1019,"data":{"e":"depthUpdate","E":1672242440731,"s":"TORNBUSD","U":113355449,"u":113355449,"b":[],"a":[["4.42000000","196.78000000"]]}},{"timeToSleep":919,"data":{"e":"depthUpdate","E":1672242441731,"s":"TORNBUSD","U":113355450,"u":113355452,"b":[["4.30000000","359.07000000"],["4.21000000","1249.10000000"]],"a":[["17.00000000","6531.99000000"]]}},{"timeToSleep":2049,"data":{"e":"depthUpdate","E":1672242443731,"s":"TORNBUSD","U":113355453,"u":113355453,"b":[],"a":[["4.32000000","177.84000000"]]}},{"timeToSleep":1020,"data":{"e":"depthUpdate","E":1672242444731,"s":"TORNBUSD","U":113355454,"u":113355457,"b":[["3.52000000","351.23000000"],["3.51000000","36.85000000"]],"a":[["4.35000000","680.60000000"],["4.40000000","520.06000000"]]}},{"timeToSleep":925,"data":{"e":"depthUpdate","E":1672242445732,"s":"TORNBUSD","U":113355458,"u":113355458,"b":[["3.53000000","1124.30000000"]],"a":[]}},{"timeToSleep":1025,"data":{"e":"depthUpdate","E":1672242446731,"s":"TORNBUSD","U":113355459,"u":113355460,"b":[["3.54000000","40.89000000"]],"a":[["4.33000000","377.32000000"]]}},{"timeToSleep":1126,"data":{"e":"depthUpdate","E":1672242447731,"s":"TORNBUSD","U":113355461,"u":113355466,"b":[["4.30000000","368.65000000"]],"a":[["4.32000000","223.29000000"],["4.33000000","327.61000000"]]}},{"timeToSleep":1823,"data":{"e":"depthUpdate","E":1672242449731,"s":"TORNBUSD","U":113355467,"u":113355468,"b":[["3.97000000","3176.84000000"]],"a":[["4.39000000","198.07000000"]]}},{"timeToSleep":1042,"data":{"e":"depthUpdate","E":1672242450733,"s":"TORNBUSD","U":113355469,"u":113355471,"b":[["4.26000000","314.70000000"]],"a":[["4.38000000","439.29000000"],["5.00000000","5596.36000000"]]}},{"timeToSleep":1028,"data":{"e":"depthUpdate","E":1672242451732,"s":"TORNBUSD","U":113355472,"u":113355475,"b":[["4.25000000","1320.16000000"],["3.98000000","629.18000000"],["3.97000000","3225.84000000"]],"a":[["4.37000000","641.54000000"]]}},{"timeToSleep":1051,"data":{"e":"depthUpdate","E":1672242452732,"s":"TORNBUSD","U":113355476,"u":113355480,"b":[["4.30000000","336.75000000"],["4.24000000","362.61000000"]],"a":[["4.32000000","239.71000000"]]}},{"timeToSleep":868,"data":{"e":"depthUpdate","E":1672242453732,"s":"TORNBUSD","U":113355481,"u":113355488,"b":[["4.23000000","660.18000000"],["4.21000000","1272.82000000"],["4.14000000","650.92000000"],["4.12000000","2226.51000000"],["4.05000000","3875.64000000"],["3.99000000","871.30000000"]],"a":[["5.94000000","98.45000000"]]}},{"timeToSleep":1049,"data":{"e":"depthUpdate","E":1672242454732,"s":"TORNBUSD","U":113355489,"u":113355490,"b":[["4.30000000","392.45000000"]],"a":[["6.00000000","8478.38000000"]]}},{"timeToSleep":2050,"data":{"e":"depthUpdate","E":1672242456732,"s":"TORNBUSD","U":113355491,"u":113355491,"b":[],"a":[["4.32000000","277.72000000"]]}},{"timeToSleep":1050,"data":{"e":"depthUpdate","E":1672242457732,"s":"TORNBUSD","U":113355492,"u":113355494,"b":[["4.14000000","653.74000000"]],"a":[["4.32000000","260.83000000"],["8.80000000","2240.74000000"]]}},{"timeToSleep":890,"data":{"e":"depthUpdate","E":1672242458732,"s":"TORNBUSD","U":113355495,"u":113355496,"b":[["4.30000000","395.72000000"]],"a":[["4.32000000","257.58000000"]]}},{"timeToSleep":1028,"data":{"e":"depthUpdate","E":1672242459732,"s":"TORNBUSD","U":113355497,"u":113355501,"b":[["4.30000000","333.69000000"],["4.12000000","4091.63000000"],["4.05000000","1978.29000000"]],"a":[["4.32000000","219.57000000"],["4.75000000","1882.96000000"]]}},{"timeToSleep":1025,"data":{"e":"depthUpdate","E":1672242460732,"s":"TORNBUSD","U":113355502,"u":113355506,"b":[["4.23000000","683.79000000"],["4.21000000","1249.10000000"],["4.14000000","762.20000000"],["4.12000000","3982.66000000"]],"a":[["4.32000000","249.44000000"]]}},{"timeToSleep":1022,"data":{"e":"depthUpdate","E":1672242461732,"s":"TORNBUSD","U":113355507,"u":113355507,"b":[],"a":[["4.32000000","254.16000000"]]}},{"timeToSleep":922,"data":{"e":"depthUpdate","E":1672242462733,"s":"TORNBUSD","U":113355508,"u":113355510,"b":[["4.25000000","1323.55000000"],["4.22000000","1801.00000000"],["4.19000000","454.73000000"]],"a":[]}},{"timeToSleep":1024,"data":{"e":"depthUpdate","E":1672242463732,"s":"TORNBUSD","U":113355511,"u":113355512,"b":[["4.19000000","669.15000000"]],"a":[["4.31000000","16.89000000"]]}},{"timeToSleep":1942,"data":{"e":"depthUpdate","E":1672242465732,"s":"TORNBUSD","U":113355513,"u":113355513,"b":[["4.26000000","299.30000000"]],"a":[]}},{"timeToSleep":3072,"data":{"e":"depthUpdate","E":1672242468732,"s":"TORNBUSD","U":113355514,"u":113355514,"b":[],"a":[["21.56000000","486.13000000"]]}},{"timeToSleep":1025,"data":{"e":"depthUpdate","E":1672242469732,"s":"TORNBUSD","U":113355515,"u":113355525,"b":[["4.31000000","54.55000000"],["4.30000000","324.11000000"],["4.22000000","1626.59000000"],["4.17000000","190.19000000"],["4.09000000","37.55000000"]],"a":[["4.31000000","0.00000000"],["4.40000000","517.34000000"]]}},{"timeToSleep":908,"data":{"e":"depthUpdate","E":1672242470732,"s":"TORNBUSD","U":113355526,"u":113355526,"b":[["4.10000000","1259.84000000"]],"a":[]}},{"timeToSleep":1042,"data":{"e":"depthUpdate","E":1672242471732,"s":"TORNBUSD","U":113355527,"u":113355528,"b":[["4.25000000","1338.98000000"]],"a":[["4.45000000","757.02000000"]]}},{"timeToSleep":1023,"data":{"e":"depthUpdate","E":1672242472732,"s":"TORNBUSD","U":113355529,"u":113355529,"b":[["4.23000000","605.23000000"]],"a":[]}},{"timeToSleep":1225,"data":{"e":"depthUpdate","E":1672242473732,"s":"TORNBUSD","U":113355530,"u":113355532,"b":[["4.19000000","598.27000000"],["4.05000000","1847.66000000"]],"a":[["4.36000000","580.12000000"]]}},{"timeToSleep":1744,"data":{"e":"depthUpdate","E":1672242475733,"s":"TORNBUSD","U":113355533,"u":113355534,"b":[["4.29000000","624.55000000"],["4.06000000","1071.22000000"]],"a":[]}},{"timeToSleep":959,"data":{"e":"depthUpdate","E":1672242476733,"s":"TORNBUSD","U":113355535,"u":113355535,"b":[["4.31000000","39.61000000"]],"a":[]}},{"timeToSleep":2728,"data":{"e":"depthUpdate","E":1672242478733,"s":"TORNBUSD","U":113355536,"u":113355536,"b":[["4.31000000","30.77000000"]],"a":[]}},{"timeToSleep":1274,"data":{"e":"depthUpdate","E":1672242480733,"s":"TORNBUSD","U":113355537,"u":113355537,"b":[["4.31000000","28.08000000"]],"a":[]}},{"timeToSleep":1125,"data":{"e":"depthUpdate","E":1672242481733,"s":"TORNBUSD","U":113355538,"u":113355539,"b":[["4.31000000","19.80000000"]],"a":[["4.34000000","130.29000000"]]}},{"timeToSleep":980,"data":{"e":"depthUpdate","E":1672242482733,"s":"TORNBUSD","U":113355540,"u":113355540,"b":[["4.16000000","176.94000000"]],"a":[]}},{"timeToSleep":894,"data":{"e":"depthUpdate","E":1672242483733,"s":"TORNBUSD","U":113355541,"u":113355543,"b":[],"a":[["4.32000000","51.01000000"],["4.33000000","352.70000000"],["4.34000000","294.68000000"]]}},{"timeToSleep":4135,"data":{"e":"depthUpdate","E":1672242487733,"s":"TORNBUSD","U":113355544,"u":113355544,"b":[["4.31000000","11.30000000"]],"a":[]}},{"timeToSleep":2865,"data":{"e":"depthUpdate","E":1672242490734,"s":"TORNBUSD","U":113355545,"u":113355545,"b":[["4.16000000","140.95000000"]],"a":[]}},{"timeToSleep":2066,"data":{"e":"depthUpdate","E":1672242492733,"s":"TORNBUSD","U":113355546,"u":113355547,"b":[["4.31000000","159.69000000"],["4.16000000","176.94000000"]],"a":[]}},{"timeToSleep":998,"data":{"e":"depthUpdate","E":1672242493734,"s":"TORNBUSD","U":113355548,"u":113355548,"b":[["4.31000000","157.95000000"]],"a":[]}},{"timeToSleep":1022,"data":{"e":"depthUpdate","E":1672242494735,"s":"TORNBUSD","U":113355549,"u":113355549,"b":[],"a":[["4.50000000","1669.33000000"]]}},{"timeToSleep":1027,"data":{"e":"depthUpdate","E":1672242495734,"s":"TORNBUSD","U":113355550,"u":113355551,"b":[["4.17000000","192.59000000"],["4.14000000","593.42000000"]],"a":[]}},{"timeToSleep":922,"data":{"e":"depthUpdate","E":1672242496734,"s":"TORNBUSD","U":113355552,"u":113355553,"b":[],"a":[["4.35000000","676.58000000"],["12.00000000","16015.79000000"]]}},{"timeToSleep":1025,"data":{"e":"depthUpdate","E":1672242497734,"s":"TORNBUSD","U":113355554,"u":113355558,"b":[["4.29000000","614.65000000"],["4.25000000","1327.80000000"],["4.16000000","344.91000000"],["4.15000000","955.71000000"],["4.14000000","496.98000000"]],"a":[]}},{"timeToSleep":1022,"data":{"e":"depthUpdate","E":1672242498734,"s":"TORNBUSD","U":113355559,"u":113355562,"b":[["4.31000000","142.57000000"],["4.11000000","175.20000000"]],"a":[["4.33000000","358.89000000"]]}},{"timeToSleep":1023,"data":{"e":"depthUpdate","E":1672242499734,"s":"TORNBUSD","U":113355563,"u":113355566,"b":[["4.13000000","804.93000000"],["4.07000000","293.61000000"],["4.06000000","1023.70000000"]],"a":[["4.32000000","0.32000000"]]}},{"timeToSleep":1027,"data":{"e":"depthUpdate","E":1672242500734,"s":"TORNBUSD","U":113355567,"u":113355570,"b":[["4.30000000","224.06000000"],["4.16000000","332.92000000"]],"a":[["4.40000000","549.34000000"],["5.00000000","5400.29000000"]]}},{"timeToSleep":2967,"data":{"e":"depthUpdate","E":1672242503734,"s":"TORNBUSD","U":113355571,"u":113355571,"b":[["4.27000000","332.58000000"]],"a":[]}},{"timeToSleep":2970,"data":{"e":"depthUpdate","E":1672242506734,"s":"TORNBUSD","U":113355572,"u":113355574,"b":[["4.31000000","242.38000000"],["4.12000000","3718.74000000"]],"a":[["4.35000000","684.63000000"]]}},{"timeToSleep":1023,"data":{"e":"depthUpdate","E":1672242507734,"s":"TORNBUSD","U":113355575,"u":113355576,"b":[["4.19000000","669.74000000"]],"a":[["4.99000000","7802.56000000"]]}},{"timeToSleep":1123,"data":{"e":"depthUpdate","E":1672242508734,"s":"TORNBUSD","U":113355577,"u":113355577,"b":[],"a":[["4.33000000","362.14000000"]]}},{"timeToSleep":820,"data":{"e":"depthUpdate","E":1672242509734,"s":"TORNBUSD","U":113355578,"u":113355579,"b":[["4.30000000","250.80000000"]],"a":[]}},{"timeToSleep":967,"data":{"e":"depthUpdate","E":1672242510734,"s":"TORNBUSD","U":113355580,"u":113355580,"b":[["4.31000000","245.64000000"]],"a":[]}},{"timeToSleep":1084,"data":{"e":"depthUpdate","E":1672242511734,"s":"TORNBUSD","U":113355581,"u":113355581,"b":[["4.05000000","1807.49000000"]],"a":[]}},{"timeToSleep":1021,"data":{"e":"depthUpdate","E":1672242512735,"s":"TORNBUSD","U":113355582,"u":113355582,"b":[],"a":[["7.00000000","5428.76000000"]]}},{"timeToSleep":1061,"data":{"e":"depthUpdate","E":1672242513734,"s":"TORNBUSD","U":113355583,"u":113355584,"b":[["4.16000000","242.94000000"],["4.05000000","1847.66000000"]],"a":[]}},{"timeToSleep":1834,"data":{"e":"depthUpdate","E":1672242515735,"s":"TORNBUSD","U":113355585,"u":113355585,"b":[["4.17000000","282.36000000"]],"a":[]}},{"timeToSleep":1102,"data":{"e":"depthUpdate","E":1672242516735,"s":"TORNBUSD","U":113355586,"u":113355587,"b":[["4.07000000","341.01000000"],["4.06000000","975.78000000"]],"a":[]}},{"timeToSleep":1028,"data":{"e":"depthUpdate","E":1672242517735,"s":"TORNBUSD","U":113355588,"u":113355588,"b":[],"a":[["4.35000000","671.58000000"]]}},{"timeToSleep":1941,"data":{"e":"depthUpdate","E":1672242519735,"s":"TORNBUSD","U":113355589,"u":113355589,"b":[["4.30000000","253.80000000"]],"a":[]}},{"timeToSleep":929,"data":{"e":"depthUpdate","E":1672242520735,"s":"TORNBUSD","U":113355590,"u":113355591,"b":[["4.25000000","1325.33000000"]],"a":[["4.50000000","1675.03000000"]]}},{"timeToSleep":1120,"data":{"e":"depthUpdate","E":1672242521735,"s":"TORNBUSD","U":113355592,"u":113355592,"b":[],"a":[["4.32000000","13.37000000"]]}},{"timeToSleep":2880,"data":{"e":"depthUpdate","E":1672242524735,"s":"TORNBUSD","U":113355593,"u":113355593,"b":[["4.31000000","497.92000000"]],"a":[]}},{"timeToSleep":1113,"data":{"e":"depthUpdate","E":1672242525735,"s":"TORNBUSD","U":113355594,"u":113355594,"b":[["4.31000000","487.02000000"]],"a":[]}},{"timeToSleep":918,"data":{"e":"depthUpdate","E":1672242526735,"s":"TORNBUSD","U":113355595,"u":113355595,"b":[["4.25000000","1327.80000000"]],"a":[]}},{"timeToSleep":1026,"data":{"e":"depthUpdate","E":1672242527735,"s":"TORNBUSD","U":113355596,"u":113355596,"b":[["4.16000000","226.87000000"]],"a":[]}},{"timeToSleep":945,"data":{"e":"depthUpdate","E":1672242528735,"s":"TORNBUSD","U":113355597,"u":113355597,"b":[["4.10000000","1336.67000000"]],"a":[]}},{"timeToSleep":1107,"data":{"e":"depthUpdate","E":1672242529735,"s":"TORNBUSD","U":113355598,"u":113355598,"b":[["4.17000000","298.39000000"]],"a":[]}},{"timeToSleep":2967,"data":{"e":"depthUpdate","E":1672242532735,"s":"TORNBUSD","U":113355599,"u":113355599,"b":[["4.30000000","270.30000000"]],"a":[]}},{"timeToSleep":1026,"data":{"e":"depthUpdate","E":1672242533735,"s":"TORNBUSD","U":113355600,"u":113355600,"b":[["4.25000000","1325.33000000"]],"a":[]}},{"timeToSleep":953,"data":{"e":"depthUpdate","E":1672242534735,"s":"TORNBUSD","U":113355601,"u":113355601,"b":[],"a":[["4.50000000","1670.44000000"]]}},{"timeToSleep":961,"data":{"e":"depthUpdate","E":1672242535736,"s":"TORNBUSD","U":113355602,"u":113355602,"b":[],"a":[["4.60000000","2819.98000000"]]}},{"timeToSleep":4024,"data":{"e":"depthUpdate","E":1672242539736,"s":"TORNBUSD","U":113355603,"u":113355606,"b":[["4.32000000","32.89000000"],["4.31000000","483.76000000"],["4.16000000","283.16000000"],["4.14000000","439.95000000"]],"a":[["4.32000000","0.00000000"]]}},{"timeToSleep":1032,"data":{"e":"depthUpdate","E":1672242540736,"s":"TORNBUSD","U":113355607,"u":113355611,"b":[["4.32000000","36.14000000"],["4.23000000","745.65000000"],["4.21000000","1318.47000000"],["4.19000000","455.32000000"]],"a":[]}},{"timeToSleep":2039,"data":{"e":"depthUpdate","E":1672242542736,"s":"TORNBUSD","U":113355612,"u":113355614,"b":[["4.32000000","32.89000000"],["4.31000000","352.09000000"]],"a":[["4.40000000","553.93000000"]]}},{"timeToSleep":923,"data":{"e":"depthUpdate","E":1672242543736,"s":"TORNBUSD","U":113355615,"u":113355618,"b":[["4.32000000","0.00000000"],["4.31000000","355.35000000"],["4.12000000","1853.62000000"]],"a":[["4.32000000","502.56000000"],["4.33000000","337.05000000"]]}},{"timeToSleep":1026,"data":{"e":"depthUpdate","E":1672242544736,"s":"TORNBUSD","U":113355619,"u":113355623,"b":[["4.27000000","181.60000000"],["4.25000000","1321.81000000"],["4.23000000","722.04000000"],["4.13000000","2665.53000000"]],"a":[]}},{"timeToSleep":986,"data":{"e":"depthUpdate","E":1672242545736,"s":"TORNBUSD","U":113355624,"u":113355624,"b":[["4.05000000","1818.68000000"]],"a":[]}},{"timeToSleep":1063,"data":{"e":"depthUpdate","E":1672242546736,"s":"TORNBUSD","U":113355625,"u":113355627,"b":[["4.30000000","287.69000000"],["4.29000000","682.88000000"],["4.06000000","1004.69000000"]],"a":[]}},{"timeToSleep":1942,"data":{"e":"depthUpdate","E":1672242548736,"s":"TORNBUSD","U":113355628,"u":113355628,"b":[],"a":[["4.95000000","10040.61000000"]]}},{"timeToSleep":2052,"data":{"e":"depthUpdate","E":1672242550736,"s":"TORNBUSD","U":113355629,"u":113355629,"b":[["4.03000000","539.54000000"]],"a":[]}},{"timeToSleep":1020,"data":{"e":"depthUpdate","E":1672242551736,"s":"TORNBUSD","U":113355630,"u":113355632,"b":[["4.29000000","836.64000000"],["4.03000000","520.40000000"]],"a":[]}},{"timeToSleep":921,"data":{"e":"depthUpdate","E":1672242552736,"s":"TORNBUSD","U":113355633,"u":113355634,"b":[["4.31000000","250.30000000"],["4.13000000","804.93000000"]],"a":[]}},{"timeToSleep":1027,"data":{"e":"depthUpdate","E":1672242553736,"s":"TORNBUSD","U":113355635,"u":113355636,"b":[["4.30000000","257.68000000"],["4.04000000","195.76000000"]],"a":[]}},{"timeToSleep":1024,"data":{"e":"depthUpdate","E":1672242554737,"s":"TORNBUSD","U":113355637,"u":113355639,"b":[["4.07000000","2181.64000000"],["4.05000000","1810.80000000"]],"a":[]}},{"timeToSleep":934,"data":{"e":"depthUpdate","E":1672242555736,"s":"TORNBUSD","U":113355640,"u":113355641,"b":[["4.07000000","2229.44000000"]],"a":[["4.33000000","333.80000000"]]}},{"timeToSleep":1011,"data":{"e":"depthUpdate","E":1672242556736,"s":"TORNBUSD","U":113355642,"u":113355642,"b":[["4.07000000","2182.04000000"]],"a":[]}},{"timeToSleep":1030,"data":{"e":"depthUpdate","E":1672242557736,"s":"TORNBUSD","U":113355643,"u":113355644,"b":[["4.02000000","95.01000000"]],"a":[["4.37000000","710.28000000"]]}},{"timeToSleep":1018,"data":{"e":"depthUpdate","E":1672242558736,"s":"TORNBUSD","U":113355645,"u":113355645,"b":[["4.07000000","2229.84000000"]],"a":[]}},{"timeToSleep":1024,"data":{"e":"depthUpdate","E":1672242559737,"s":"TORNBUSD","U":113355646,"u":113355648,"b":[["4.07000000","341.81000000"],["4.03000000","568.67000000"]],"a":[["4.32000000","493.07000000"]]}},{"timeToSleep":921,"data":{"e":"depthUpdate","E":1672242560737,"s":"TORNBUSD","U":113355649,"u":113355649,"b":[["4.13000000","2665.53000000"]],"a":[]}},{"timeToSleep":1027,"data":{"e":"depthUpdate","E":1672242561737,"s":"TORNBUSD","U":113355650,"u":113355651,"b":[["4.27000000","191.54000000"]],"a":[["4.32000000","496.32000000"]]}},{"timeToSleep":1029,"data":{"e":"depthUpdate","E":1672242562737,"s":"TORNBUSD","U":113355652,"u":113355652,"b":[["4.23000000","581.62000000"]],"a":[]}},{"timeToSleep":1015,"data":{"e":"depthUpdate","E":1672242563737,"s":"TORNBUSD","U":113355653,"u":113355653,"b":[["4.25000000","1493.09000000"]],"a":[]}},{"timeToSleep":1024,"data":{"e":"depthUpdate","E":1672242564737,"s":"TORNBUSD","U":113355654,"u":113355654,"b":[["4.22000000","1768.52000000"]],"a":[]}},{"timeToSleep":931,"data":{"e":"depthUpdate","E":1672242565737,"s":"TORNBUSD","U":113355655,"u":113355655,"b":[["4.27000000","172.36000000"]],"a":[]}},{"timeToSleep":2041,"data":{"e":"depthUpdate","E":1672242567737,"s":"TORNBUSD","U":113355656,"u":113355657,"b":[["4.31000000","260.56000000"],["4.12000000","1829.60000000"]],"a":[]}},{"timeToSleep":1022,"data":{"e":"depthUpdate","E":1672242568737,"s":"TORNBUSD","U":113355658,"u":113355658,"b":[["4.06000000","1012.55000000"]],"a":[]}},{"timeToSleep":920,"data":{"e":"depthUpdate","E":1672242569737,"s":"TORNBUSD","U":113355659,"u":113355659,"b":[["4.14000000","355.56000000"]],"a":[]}},{"timeToSleep":2050,"data":{"e":"depthUpdate","E":1672242571737,"s":"TORNBUSD","U":113355660,"u":113355661,"b":[["4.15000000","1039.89000000"]],"a":[["4.46000000","256.41000000"]]}},{"timeToSleep":2045,"data":{"e":"depthUpdate","E":1672242573737,"s":"TORNBUSD","U":113355662,"u":113355663,"b":[],"a":[["4.65000000","297.33000000"],["4.95000000","9892.37000000"]]}},{"timeToSleep":1949,"data":{"e":"depthUpdate","E":1672242575737,"s":"TORNBUSD","U":113355664,"u":113355665,"b":[["4.25000000","1490.07000000"],["3.95000000","1156.58000000"]],"a":[]}},{"timeToSleep":1023,"data":{"e":"depthUpdate","E":1672242576737,"s":"TORNBUSD","U":113355666,"u":113355668,"b":[["4.28000000","1345.66000000"],["4.15000000","899.89000000"]],"a":[["4.32000000","453.07000000"]]}},{"timeToSleep":1038,"data":{"e":"depthUpdate","E":1672242577737,"s":"TORNBUSD","U":113355669,"u":113355669,"b":[["4.06000000","951.09000000"]],"a":[]}},{"timeToSleep":1931,"data":{"e":"depthUpdate","E":1672242579738,"s":"TORNBUSD","U":113355670,"u":113355673,"b":[["4.30000000","725.82000000"]],"a":[["4.32000000","381.49000000"],["5.99000000","1675.42000000"]]}},{"timeToSleep":2971,"data":{"e":"depthUpdate","E":1672242582738,"s":"TORNBUSD","U":113355674,"u":113355675,"b":[["4.25000000","1626.78000000"]],"a":[["4.32000000","378.24000000"]]}},{"timeToSleep":2065,"data":{"e":"depthUpdate","E":1672242584738,"s":"TORNBUSD","U":113355676,"u":113355676,"b":[["4.16000000","247.17000000"]],"a":[]}},{"timeToSleep":1926,"data":{"e":"depthUpdate","E":1672242586738,"s":"TORNBUSD","U":113355677,"u":113355677,"b":[["4.16000000","283.16000000"]],"a":[]}},{"timeToSleep":1023,"data":{"e":"depthUpdate","E":1672242587738,"s":"TORNBUSD","U":113355678,"u":113355679,"b":[],"a":[["4.32000000","353.91000000"],["4.33000000","239.15000000"]]}},{"timeToSleep":1024,"data":{"e":"depthUpdate","E":1672242588738,"s":"TORNBUSD","U":113355680,"u":113355681,"b":[["4.31000000","257.31000000"]],"a":[["4.32000000","357.64000000"]]}},{"timeToSleep":1028,"data":{"e":"depthUpdate","E":1672242589738,"s":"TORNBUSD","U":113355682,"u":113355682,"b":[],"a":[["16.00000000","19919.68000000"]]}},{"timeToSleep":921,"data":{"e":"depthUpdate","E":1672242590738,"s":"TORNBUSD","U":113355683,"u":113355685,"b":[["4.25000000","1485.61000000"],["4.13000000","804.93000000"],["4.07000000","2229.84000000"]],"a":[]}},{"timeToSleep":4098,"data":{"e":"depthUpdate","E":1672242594738,"s":"TORNBUSD","U":113355686,"u":113355686,"b":[],"a":[["4.55000000","143.67000000"]]}},{"timeToSleep":921,"data":{"e":"depthUpdate","E":1672242595738,"s":"TORNBUSD","U":113355687,"u":113355687,"b":[],"a":[["4.32000000","353.91000000"]]}},{"timeToSleep":2948,"data":{"e":"depthUpdate","E":1672242598738,"s":"TORNBUSD","U":113355688,"u":113355689,"b":[["4.31000000","0.00000000"]],"a":[["4.31000000","75.10000000"],["4.32000000","357.17000000"]]}},{"timeToSleep":1002,"data":{"e":"depthUpdate","E":1672242599739,"s":"TORNBUSD","U":113355690,"u":113355694,"b":[["4.21000000","1106.84000000"],["4.19000000","667.96000000"],["4.18000000","1156.84000000"],["4.07000000","341.81000000"],["4.05000000","3708.15000000"]],"a":[]}},{"timeToSleep":1068,"data":{"e":"depthUpdate","E":1672242600739,"s":"TORNBUSD","U":113355695,"u":113355698,"b":[["4.16000000","226.87000000"],["4.14000000","412.12000000"],["4.13000000","776.74000000"],["4.12000000","1857.86000000"]],"a":[]}},{"timeToSleep":1025,"data":{"e":"depthUpdate","E":1672242601739,"s":"TORNBUSD","U":113355699,"u":113355700,"b":[["4.17000000","370.20000000"],["3.34000000","21.32000000"]],"a":[]}},{"timeToSleep":1945,"data":{"e":"depthUpdate","E":1672242603739,"s":"TORNBUSD","U":113355701,"u":113355702,"b":[["4.30000000","722.09000000"],["4.05000000","1810.80000000"]],"a":[]}},{"timeToSleep":976,"data":{"e":"depthUpdate","E":1672242604740,"s":"TORNBUSD","U":113355703,"u":113355710,"b":[["4.30000000","719.54000000"],["4.27000000","168.86000000"],["4.25000000","1489.13000000"],["4.24000000","365.09000000"],["4.14000000","303.66000000"],["4.12000000","1966.82000000"],["4.06000000","2843.77000000"]],"a":[["4.36000000","575.57000000"]]}},{"timeToSleep":2092,"data":{"e":"depthUpdate","E":1672242606739,"s":"TORNBUSD","U":113355711,"u":113355711,"b":[["4.30000000","714.99000000"]],"a":[]}},{"timeToSleep":1894,"data":{"e":"depthUpdate","E":1672242608739,"s":"TORNBUSD","U":113355712,"u":113355712,"b":[["4.05000000","1770.63000000"]],"a":[]}},{"timeToSleep":2102,"data":{"e":"depthUpdate","E":1672242610739,"s":"TORNBUSD","U":113355713,"u":113355715,"b":[["4.12000000","1951.67000000"],["4.08000000","117.04000000"],["4.04000000","236.03000000"]],"a":[]}},{"timeToSleep":1944,"data":{"e":"depthUpdate","E":1672242612739,"s":"TORNBUSD","U":113355716,"u":113355717,"b":[["4.13000000","776.74000000"]],"a":[]}},{"timeToSleep":2049,"data":{"e":"depthUpdate","E":1672242614740,"s":"TORNBUSD","U":113355718,"u":113355720,"b":[["4.12000000","1923.41000000"]],"a":[["4.31000000","0.00000000"],["4.45000000","771.73000000"]]}},{"timeToSleep":1947,"data":{"e":"depthUpdate","E":1672242616740,"s":"TORNBUSD","U":113355721,"u":113355721,"b":[["4.12000000","1951.90000000"]],"a":[]}},{"timeToSleep":1023,"data":{"e":"depthUpdate","E":1672242617740,"s":"TORNBUSD","U":113355722,"u":113355722,"b":[["4.11000000","199.48000000"]],"a":[]}},{"timeToSleep":947,"data":{"e":"depthUpdate","E":1672242618740,"s":"TORNBUSD","U":113355723,"u":113355724,"b":[],"a":[["4.42000000","449.06000000"],["4.78000000","100.66000000"]]}},{"timeToSleep":1102,"data":{"e":"depthUpdate","E":1672242619740,"s":"TORNBUSD","U":113355725,"u":113355725,"b":[["4.10000000","1301.77000000"]],"a":[]}},{"timeToSleep":921,"data":{"e":"depthUpdate","E":1672242620740,"s":"TORNBUSD","U":113355726,"u":113355726,"b":[],"a":[["4.50000000","1664.74000000"]]}},{"timeToSleep":1027,"data":{"e":"depthUpdate","E":1672242621740,"s":"TORNBUSD","U":113355727,"u":113355727,"b":[["4.30000000","711.99000000"]],"a":[]}},{"timeToSleep":2062,"data":{"e":"depthUpdate","E":1672242623740,"s":"TORNBUSD","U":113355728,"u":113355730,"b":[],"a":[["4.32000000","368.00000000"],["4.39000000","758.56000000"],["4.43000000","969.24000000"]]}},{"timeToSleep":1940,"data":{"e":"depthUpdate","E":1672242625740,"s":"TORNBUSD","U":113355731,"u":113355731,"b":[["4.30000000","702.51000000"]],"a":[]}},{"timeToSleep":3078,"data":{"e":"depthUpdate","E":1672242628740,"s":"TORNBUSD","U":113355732,"u":113355732,"b":[],"a":[["4.99000000","7907.26000000"]]}},{"timeToSleep":922,"data":{"e":"depthUpdate","E":1672242629741,"s":"TORNBUSD","U":113355733,"u":113355733,"b":[],"a":[["4.38000000","423.28000000"]]}},{"timeToSleep":1022,"data":{"e":"depthUpdate","E":1672242630741,"s":"TORNBUSD","U":113355734,"u":113355735,"b":[["4.30000000","627.41000000"]],"a":[["4.39000000","774.53000000"]]}},{"timeToSleep":931,"data":{"e":"depthUpdate","E":1672242631740,"s":"TORNBUSD","U":113355736,"u":113355738,"b":[["4.30000000","573.69000000"]],"a":[["4.32000000","373.53000000"]]}},{"timeToSleep":3066,"data":{"e":"depthUpdate","E":1672242634740,"s":"TORNBUSD","U":113355739,"u":113355739,"b":[],"a":[["4.32000000","468.17000000"]]}},{"timeToSleep":1025,"data":{"e":"depthUpdate","E":1672242635741,"s":"TORNBUSD","U":113355740,"u":113355740,"b":[],"a":[["4.36000000","586.56000000"]]}},{"timeToSleep":1026,"data":{"e":"depthUpdate","E":1672242636741,"s":"TORNBUSD","U":113355741,"u":113355741,"b":[],"a":[["4.36000000","575.57000000"]]}},{"timeToSleep":921,"data":{"e":"depthUpdate","E":1672242637741,"s":"TORNBUSD","U":113355742,"u":113355742,"b":[],"a":[["4.32000000","479.16000000"]]}},{"timeToSleep":2046,"data":{"e":"depthUpdate","E":1672242639741,"s":"TORNBUSD","U":113355743,"u":113355744,"b":[["4.25000000","799.53000000"]],"a":[["4.32000000","468.17000000"]]}},{"timeToSleep":1026,"data":{"e":"depthUpdate","E":1672242640741,"s":"TORNBUSD","U":113355745,"u":113355746,"b":[["4.30000000","562.70000000"]],"a":[["4.32000000","501.76000000"]]}},{"timeToSleep":1033,"data":{"e":"depthUpdate","E":1672242641741,"s":"TORNBUSD","U":113355747,"u":113355749,"b":[],"a":[["4.45000000","797.46000000"],["4.46000000","230.68000000"],["5.50000000","7845.21000000"]]}},{"timeToSleep":1943,"data":{"e":"depthUpdate","E":1672242643741,"s":"TORNBUSD","U":113355750,"u":113355751,"b":[["4.28000000","1228.99000000"],["4.08000000","88.27000000"]],"a":[]}},{"timeToSleep":1033,"data":{"e":"depthUpdate","E":1672242644743,"s":"TORNBUSD","U":113355752,"u":113355753,"b":[["4.06000000","951.09000000"],["4.05000000","3667.98000000"]],"a":[]}},{"timeToSleep":1017,"data":{"e":"depthUpdate","E":1672242645741,"s":"TORNBUSD","U":113355754,"u":113355754,"b":[["4.09000000","66.25000000"]],"a":[]}},{"timeToSleep":4923,"data":{"e":"depthUpdate","E":1672242650742,"s":"TORNBUSD","U":113355755,"u":113355766,"b":[["4.12000000","2045.56000000"],["4.09000000","113.42000000"],["4.08000000","135.56000000"],["4.07000000","246.21000000"],["4.05000000","3715.62000000"],["4.04000000","187.88000000"],["4.03000000","568.27000000"],["3.99000000","822.54000000"],["3.97000000","3176.84000000"]],"a":[]}},{"timeToSleep":1014,"data":{"e":"depthUpdate","E":1672242651742,"s":"TORNBUSD","U":113355767,"u":113355767,"b":[["4.14000000","300.84000000"]],"a":[]}},{"timeToSleep":1053,"data":{"e":"depthUpdate","E":1672242652742,"s":"TORNBUSD","U":113355768,"u":113355771,"b":[["4.14000000","303.66000000"],["4.10000000","1301.77000000"]],"a":[["4.32000000","498.51000000"]]}},{"timeToSleep":1035,"data":{"e":"depthUpdate","E":1672242653742,"s":"TORNBUSD","U":113355772,"u":113355774,"b":[["4.12000000","3882.42000000"],["4.05000000","1818.27000000"]],"a":[]}},{"timeToSleep":888,"data":{"e":"depthUpdate","E":1672242654741,"s":"TORNBUSD","U":113355775,"u":113355776,"b":[["4.14000000","412.12000000"],["4.12000000","3773.46000000"]],"a":[]}},{"timeToSleep":1043,"data":{"e":"depthUpdate","E":1672242655741,"s":"TORNBUSD","U":113355777,"u":113355778,"b":[["4.19000000","455.32000000"],["4.12000000","3801.95000000"]],"a":[]}},{"timeToSleep":2024,"data":{"e":"depthUpdate","E":1672242657742,"s":"TORNBUSD","U":113355779,"u":113355779,"b":[["4.19000000","669.74000000"]],"a":[]}},{"timeToSleep":1033,"data":{"e":"depthUpdate","E":1672242658742,"s":"TORNBUSD","U":113355780,"u":113355782,"b":[["4.30000000","559.45000000"],["4.14000000","303.66000000"],["4.12000000","3910.92000000"]],"a":[]}},{"timeToSleep":916,"data":{"e":"depthUpdate","E":1672242659742,"s":"TORNBUSD","U":113355783,"u":113355783,"b":[["4.06000000","820.78000000"]],"a":[]}},{"timeToSleep":1021,"data":{"e":"depthUpdate","E":1672242660742,"s":"TORNBUSD","U":113355784,"u":113355784,"b":[["4.22000000","1472.83000000"]],"a":[]}},{"timeToSleep":1024,"data":{"e":"depthUpdate","E":1672242661742,"s":"TORNBUSD","U":113355785,"u":113355786,"b":[["4.30000000","535.88000000"],["4.05000000","1948.90000000"]],"a":[]}},{"timeToSleep":1025,"data":{"e":"depthUpdate","E":1672242662742,"s":"TORNBUSD","U":113355787,"u":113355787,"b":[["4.30000000","676.00000000"]],"a":[]}},{"timeToSleep":921,"data":{"e":"depthUpdate","E":1672242663742,"s":"TORNBUSD","U":113355788,"u":113355788,"b":[],"a":[["4.42000000","464.06000000"]]}},{"timeToSleep":1022,"data":{"e":"depthUpdate","E":1672242664742,"s":"TORNBUSD","U":113355789,"u":113355791,"b":[["4.30000000","608.26000000"],["4.27000000","172.50000000"]],"a":[]}},{"timeToSleep":1032,"data":{"e":"depthUpdate","E":1672242665744,"s":"TORNBUSD","U":113355792,"u":113355795,"b":[],"a":[["4.32000000","144.59000000"],["4.33000000","264.24000000"]]}},{"timeToSleep":1015,"data":{"e":"depthUpdate","E":1672242666743,"s":"TORNBUSD","U":113355796,"u":113355798,"b":[["4.23000000","645.31000000"]],"a":[["4.33000000","267.50000000"],["4.50000000","1693.74000000"]]}},{"timeToSleep":962,"data":{"e":"depthUpdate","E":1672242667743,"s":"TORNBUSD","U":113355799,"u":113355801,"b":[["4.31000000","68.90000000"],["4.29000000","767.41000000"]],"a":[["10.00000000","5675.86000000"]]}},{"timeToSleep":988,"data":{"e":"depthUpdate","E":1672242668743,"s":"TORNBUSD","U":113355802,"u":113355803,"b":[["4.28000000","1232.62000000"],["4.27000000","168.86000000"]],"a":[]}},{"timeToSleep":1024,"data":{"e":"depthUpdate","E":1672242669742,"s":"TORNBUSD","U":113355804,"u":113355805,"b":[["4.31000000","0.00000000"],["4.30000000","351.59000000"]],"a":[["4.53000000","116.04000000"]]}},{"timeToSleep":1024,"data":{"e":"depthUpdate","E":1672242670742,"s":"TORNBUSD","U":113355806,"u":113355807,"b":[["4.12000000","2045.80000000"]],"a":[["4.65000000","251.09000000"]]}},{"timeToSleep":1024,"data":{"e":"depthUpdate","E":1672242671742,"s":"TORNBUSD","U":113355808,"u":113355809,"b":[["4.30000000","321.71000000"],["4.07000000","2134.24000000"]],"a":[]}},{"timeToSleep":1946,"data":{"e":"depthUpdate","E":1672242673743,"s":"TORNBUSD","U":113355810,"u":113355810,"b":[],"a":[["4.32000000","161.09000000"]]}},{"timeToSleep":2060,"data":{"e":"depthUpdate","E":1672242675743,"s":"TORNBUSD","U":113355811,"u":113355811,"b":[["4.20000000","8536.30000000"]],"a":[]}},{"timeToSleep":910,"data":{"e":"depthUpdate","E":1672242676744,"s":"TORNBUSD","U":113355812,"u":113355812,"b":[["4.06000000","882.24000000"]],"a":[]}},{"timeToSleep":1025,"data":{"e":"depthUpdate","E":1672242677743,"s":"TORNBUSD","U":113355813,"u":113355817,"b":[["4.29000000","771.03000000"],["4.28000000","1228.99000000"],["4.11000000","345.46000000"]],"a":[["4.47000000","533.89000000"],["4.53000000","47.14000000"]]}},{"timeToSleep":1027,"data":{"e":"depthUpdate","E":1672242678743,"s":"TORNBUSD","U":113355818,"u":113355820,"b":[["4.29000000","726.03000000"],["4.08000000","2018.96000000"],["4.07000000","246.21000000"]],"a":[]}},{"timeToSleep":1020,"data":{"e":"depthUpdate","E":1672242679743,"s":"TORNBUSD","U":113355821,"u":113355821,"b":[["4.16000000","190.88000000"]],"a":[]}},{"timeToSleep":918,"data":{"e":"depthUpdate","E":1672242680743,"s":"TORNBUSD","U":113355822,"u":113355823,"b":[],"a":[["4.35000000","771.39000000"],["4.40000000","488.71000000"]]}},{"timeToSleep":1026,"data":{"e":"depthUpdate","E":1672242681744,"s":"TORNBUSD","U":113355824,"u":113355826,"b":[["4.31000000","4.46000000"],["4.15000000","935.97000000"]],"a":[["4.35000000","766.39000000"]]}},{"timeToSleep":1025,"data":{"e":"depthUpdate","E":1672242682744,"s":"TORNBUSD","U":113355827,"u":113355827,"b":[["3.96000000","23.34000000"]],"a":[]}},{"timeToSleep":1025,"data":{"e":"depthUpdate","E":1672242683743,"s":"TORNBUSD","U":113355828,"u":113355828,"b":[["3.97000000","3509.00000000"]],"a":[]}},{"timeToSleep":921,"data":{"e":"depthUpdate","E":1672242684743,"s":"TORNBUSD","U":113355829,"u":113355829,"b":[["4.24000000","362.61000000"]],"a":[]}},{"timeToSleep":1024,"data":{"e":"depthUpdate","E":1672242685743,"s":"TORNBUSD","U":113355830,"u":113355830,"b":[["3.75000000","455.54000000"]],"a":[]}},{"timeToSleep":2049,"data":{"e":"depthUpdate","E":1672242687743,"s":"TORNBUSD","U":113355831,"u":113355833,"b":[["4.25000000","754.53000000"],["4.16000000","22.91000000"],["4.15000000","839.76000000"]],"a":[]}},{"timeToSleep":1025,"data":{"e":"depthUpdate","E":1672242688743,"s":"TORNBUSD","U":113355834,"u":113355834,"b":[["4.14000000","400.10000000"]],"a":[]}},{"timeToSleep":922,"data":{"e":"depthUpdate","E":1672242689743,"s":"TORNBUSD","U":113355835,"u":113355835,"b":[["4.15000000","1008.13000000"]],"a":[]}},{"timeToSleep":2045,"data":{"e":"depthUpdate","E":1672242691743,"s":"TORNBUSD","U":113355836,"u":113355839,"b":[["4.31000000","0.00000000"],["4.30000000","668.62000000"],["4.08000000","135.56000000"]],"a":[["4.35000000","763.46000000"]]}},{"timeToSleep":1024,"data":{"e":"depthUpdate","E":1672242692743,"s":"TORNBUSD","U":113355840,"u":113355840,"b":[["4.06000000","2774.92000000"]],"a":[]}},{"timeToSleep":1950,"data":{"e":"depthUpdate","E":1672242694743,"s":"TORNBUSD","U":113355841,"u":113355841,"b":[["4.06000000","882.24000000"]],"a":[]}},{"timeToSleep":1023,"data":{"e":"depthUpdate","E":1672242695743,"s":"TORNBUSD","U":113355842,"u":113355844,"b":[["4.24000000","346.06000000"],["4.23000000","690.31000000"],["4.08000000","2018.96000000"]],"a":[]}},{"timeToSleep":1051,"data":{"e":"depthUpdate","E":1672242696744,"s":"TORNBUSD","U":113355845,"u":113355846,"b":[["4.30000000","649.62000000"],["4.08000000","1990.19000000"]],"a":[]}},{"timeToSleep":893,"data":{"e":"depthUpdate","E":1672242697743,"s":"TORNBUSD","U":113355847,"u":113355849,"b":[["4.23000000","706.90000000"],["4.08000000","2018.96000000"]],"a":[["4.35000000","819.16000000"]]}},{"timeToSleep":3995,"data":{"e":"depthUpdate","E":1672242701744,"s":"TORNBUSD","U":113355850,"u":113355850,"b":[["4.17000000","280.43000000"]],"a":[]}},{"timeToSleep":1022,"data":{"e":"depthUpdate","E":1672242702744,"s":"TORNBUSD","U":113355851,"u":113355852,"b":[],"a":[["4.32000000","66.45000000"],["4.39000000","758.56000000"]]}},{"timeToSleep":1024,"data":{"e":"depthUpdate","E":1672242703744,"s":"TORNBUSD","U":113355853,"u":113355856,"b":[["4.17000000","370.20000000"]],"a":[["4.32000000","55.62000000"],["4.33000000","270.43000000"],["4.38000000","439.28000000"]]}},{"timeToSleep":1024,"data":{"e":"depthUpdate","E":1672242704744,"s":"TORNBUSD","U":113355857,"u":113355857,"b":[["4.30000000","647.00000000"]],"a":[]}},{"timeToSleep":928,"data":{"e":"depthUpdate","E":1672242705744,"s":"TORNBUSD","U":113355858,"u":113355858,"b":[["4.20000000","8479.17000000"]],"a":[]}},{"timeToSleep":2041,"data":{"e":"depthUpdate","E":1672242707744,"s":"TORNBUSD","U":113355859,"u":113355861,"b":[["3.35000000","2289.88000000"]],"a":[["4.33000000","375.90000000"],["15.00000000","6612.66000000"]]}},{"timeToSleep":3995,"data":{"e":"depthUpdate","E":1672242711744,"s":"TORNBUSD","U":113355862,"u":113355862,"b":[["4.13000000","716.82000000"]],"a":[]}},{"timeToSleep":1024,"data":{"e":"depthUpdate","E":1672242712744,"s":"TORNBUSD","U":113355863,"u":113355864,"b":[["4.11000000","406.18000000"]],"a":[["5.00000000","5425.44000000"],["5.80000000","1444.90000000"]]}},{"timeToSleep":1025,"data":{"e":"depthUpdate","E":1672242713744,"s":"TORNBUSD","U":113355865,"u":113355865,"b":[["4.04000000","147.61000000"]],"a":[]}},{"timeToSleep":1954,"data":{"e":"depthUpdate","E":1672242715745,"s":"TORNBUSD","U":113355866,"u":113355867,"b":[["4.17000000","354.17000000"],["4.04000000","187.88000000"]],"a":[]}},{"timeToSleep":930,"data":{"e":"depthUpdate","E":1672242716744,"s":"TORNBUSD","U":113355868,"u":113355868,"b":[["4.25000000","751.01000000"]],"a":[]}},{"timeToSleep":1002,"data":{"e":"depthUpdate","E":1672242717744,"s":"TORNBUSD","U":113355869,"u":113355869,"b":[["4.16000000","38.98000000"]],"a":[]}},{"timeToSleep":4100,"data":{"e":"depthUpdate","E":1672242721745,"s":"TORNBUSD","U":113355870,"u":113355870,"b":[],"a":[["4.36000000","208.30000000"]]}},{"timeToSleep":901,"data":{"e":"depthUpdate","E":1672242722745,"s":"TORNBUSD","U":113355871,"u":113355871,"b":[],"a":[["4.50000000","1681.74000000"],["4.60000000","2831.98000000"]]}},{"timeToSleep":5007,"data":{"e":"depthUpdate","E":1672242727745,"s":"TORNBUSD","U":113355872,"u":113355872,"b":[],"a":[["19.00000000","11133.04000000"]]}},{"timeToSleep":1057,"data":{"e":"depthUpdate","E":1672242728746,"s":"TORNBUSD","U":113355873,"u":113355875,"b":[["4.30000000","716.15000000"],["4.29000000","722.41000000"]],"a":[]}},{"timeToSleep":3991,"data":{"e":"depthUpdate","E":1672242732745,"s":"TORNBUSD","U":113355876,"u":113355876,"b":[["4.28000000","1176.99000000"]],"a":[]}},{"timeToSleep":3074,"data":{"e":"depthUpdate","E":1672242735745,"s":"TORNBUSD","U":113355877,"u":113355878,"b":[],"a":[["4.35000000","581.72000000"],["4.37000000","756.53000000"]]}},{"timeToSleep":922,"data":{"e":"depthUpdate","E":1672242736745,"s":"TORNBUSD","U":113355879,"u":113355879,"b":[["4.10000000","1296.95000000"]],"a":[]}},{"timeToSleep":1023,"data":{"e":"depthUpdate","E":1672242737746,"s":"TORNBUSD","U":113355880,"u":113355880,"b":[["4.23000000","690.31000000"]],"a":[]}},{"timeToSleep":1024,"data":{"e":"depthUpdate","E":1672242738746,"s":"TORNBUSD","U":113355881,"u":113355881,"b":[],"a":[["4.37000000","710.28000000"]]}},{"timeToSleep":1028,"data":{"e":"depthUpdate","E":1672242739746,"s":"TORNBUSD","U":113355882,"u":113355884,"b":[["4.30000000","719.09000000"],["4.24000000","362.61000000"]],"a":[["4.32000000","52.65000000"]]}},{"timeToSleep":918,"data":{"e":"depthUpdate","E":1672242740746,"s":"TORNBUSD","U":113355885,"u":113355886,"b":[["4.08000000","135.56000000"],["4.06000000","2774.92000000"]],"a":[]}},{"timeToSleep":1030,"data":{"e":"depthUpdate","E":1672242741746,"s":"TORNBUSD","U":113355887,"u":113355889,"b":[["4.30000000","693.69000000"],["4.25000000","754.53000000"]],"a":[["4.40000000","553.93000000"]]}},{"timeToSleep":1017,"data":{"e":"depthUpdate","E":1672242742746,"s":"TORNBUSD","U":113355890,"u":113355891,"b":[["4.06000000","882.24000000"],["4.05000000","3846.25000000"]],"a":[]}},{"timeToSleep":1023,"data":{"e":"depthUpdate","E":1672242743746,"s":"TORNBUSD","U":113355892,"u":113355895,"b":[],"a":[["4.32000000","315.18000000"],["4.33000000","347.55000000"]]}},{"timeToSleep":924,"data":{"e":"depthUpdate","E":1672242744746,"s":"TORNBUSD","U":113355896,"u":113355896,"b":[],"a":[["4.32000000","318.44000000"]]}},{"timeToSleep":1024,"data":{"e":"depthUpdate","E":1672242745746,"s":"TORNBUSD","U":113355897,"u":113355897,"b":[["4.25000000","757.00000000"]],"a":[]}},{"timeToSleep":1023,"data":{"e":"depthUpdate","E":1672242746746,"s":"TORNBUSD","U":113355898,"u":113355898,"b":[],"a":[["4.48000000","929.80000000"]]}},{"timeToSleep":1944,"data":{"e":"depthUpdate","E":1672242748746,"s":"TORNBUSD","U":113355899,"u":113355899,"b":[],"a":[["6.00000000","8590.00000000"]]}},{"timeToSleep":972,"data":{"e":"depthUpdate","E":1672242749746,"s":"TORNBUSD","U":113355900,"u":113355901,"b":[["4.30000000","596.78000000"]],"a":[["4.32000000","685.71000000"]]}},{"timeToSleep":3124,"data":{"e":"depthUpdate","E":1672242752746,"s":"TORNBUSD","U":113355902,"u":113355905,"b":[["4.30000000","247.95000000"]],"a":[["4.32000000","864.18000000"],["4.34000000","22.94000000"]]}},{"timeToSleep":1950,"data":{"e":"depthUpdate","E":1672242754746,"s":"TORNBUSD","U":113355906,"u":113355906,"b":[["4.30000000","189.13000000"]],"a":[]}},{"timeToSleep":1023,"data":{"e":"depthUpdate","E":1672242755746,"s":"TORNBUSD","U":113355907,"u":113355907,"b":[],"a":[["4.33000000","344.62000000"]]}},{"timeToSleep":1026,"data":{"e":"depthUpdate","E":1672242756746,"s":"TORNBUSD","U":113355908,"u":113355911,"b":[["4.30000000","184.05000000"],["4.22000000","1330.90000000"],["4.03000000","520.40000000"]],"a":[["4.60000000","2842.21000000"]]}},{"timeToSleep":919,"data":{"e":"depthUpdate","E":1672242757747,"s":"TORNBUSD","U":113355912,"u":113355913,"b":[["4.15000000","923.95000000"]],"a":[["4.32000000","889.18000000"]]}},{"timeToSleep":1020,"data":{"e":"depthUpdate","E":1672242758746,"s":"TORNBUSD","U":113355914,"u":113355915,"b":[["4.21000000","1249.10000000"],["4.03000000","568.67000000"]],"a":[]}},{"timeToSleep":1024,"data":{"e":"depthUpdate","E":1672242759746,"s":"TORNBUSD","U":113355916,"u":113355916,"b":[["4.14000000","484.49000000"]],"a":[]}},{"timeToSleep":1026,"data":{"e":"depthUpdate","E":1672242760747,"s":"TORNBUSD","U":113355917,"u":113355918,"b":[],"a":[["4.43000000","999.54000000"],["4.62000000","228.53000000"]]}},{"timeToSleep":5020,"data":{"e":"depthUpdate","E":1672242765747,"s":"TORNBUSD","U":113355919,"u":113355919,"b":[["4.05000000","3798.61000000"]],"a":[]}},{"timeToSleep":867,"data":{"e":"depthUpdate","E":1672242766746,"s":"TORNBUSD","U":113355920,"u":113355921,"b":[["4.25000000","754.53000000"]],"a":[["21.50000000","3051.27000000"]]}},{"timeToSleep":1088,"data":{"e":"depthUpdate","E":1672242767746,"s":"TORNBUSD","U":113355922,"u":113355923,"b":[["4.05000000","3846.64000000"]],"a":[["5.65000000","202.11000000"]]}},{"timeToSleep":2036,"data":{"e":"depthUpdate","E":1672242769747,"s":"TORNBUSD","U":113355924,"u":113355925,"b":[["4.25000000","583.25000000"],["3.95000000","1017.59000000"]],"a":[]}},{"timeToSleep":878,"data":{"e":"depthUpdate","E":1672242770747,"s":"TORNBUSD","U":113355926,"u":113355926,"b":[],"a":[["6.66000000","1595.04000000"]]}},{"timeToSleep":1075,"data":{"e":"depthUpdate","E":1672242771747,"s":"TORNBUSD","U":113355927,"u":113355928,"b":[["4.15000000","887.87000000"],["3.94000000","209.29000000"]],"a":[]}},{"timeToSleep":925,"data":{"e":"depthUpdate","E":1672242772747,"s":"TORNBUSD","U":113355929,"u":113355929,"b":[["4.08000000","140.45000000"]],"a":[]}},{"timeToSleep":1120,"data":{"e":"depthUpdate","E":1672242773747,"s":"TORNBUSD","U":113355930,"u":113355930,"b":[["4.15000000","923.95000000"]],"a":[]}},{"timeToSleep":1884,"data":{"e":"depthUpdate","E":1672242775747,"s":"TORNBUSD","U":113355931,"u":113355931,"b":[["4.17000000","351.77000000"]],"a":[]}},{"timeToSleep":1998,"data":{"e":"depthUpdate","E":1672242777747,"s":"TORNBUSD","U":113355932,"u":113355932,"b":[["4.30000000","300.32000000"]],"a":[]}},{"timeToSleep":4002,"data":{"e":"depthUpdate","E":1672242781748,"s":"TORNBUSD","U":113355933,"u":113355933,"b":[],"a":[["4.35000000","461.65000000"]]}},{"timeToSleep":1025,"data":{"e":"depthUpdate","E":1672242782747,"s":"TORNBUSD","U":113355934,"u":113355935,"b":[["4.30000000","251.18000000"]],"a":[["4.35000000","361.84000000"]]}},{"timeToSleep":3069,"data":{"e":"depthUpdate","E":1672242785747,"s":"TORNBUSD","U":113355936,"u":113355936,"b":[],"a":[["4.50000000","1645.97000000"]]}},{"timeToSleep":3902,"data":{"e":"depthUpdate","E":1672242789747,"s":"TORNBUSD","U":113355937,"u":113355939,"b":[["4.30000000","644.24000000"],["4.17000000","279.96000000"]],"a":[["4.42000000","563.87000000"]]}},{"timeToSleep":998,"data":{"e":"depthUpdate","E":1672242790747,"s":"TORNBUSD","U":113355940,"u":113355940,"b":[],"a":[["4.31000000","110.13000000"]]}},{"timeToSleep":1009,"data":{"e":"depthUpdate","E":1672242791748,"s":"TORNBUSD","U":113355941,"u":113355946,"b":[["4.30000000","581.42000000"],["4.18000000","1228.48000000"]],"a":[["4.31000000","138.48000000"],["4.32000000","860.83000000"]]}},{"timeToSleep":994,"data":{"e":"depthUpdate","E":1672242792748,"s":"TORNBUSD","U":113355947,"u":113355948,"b":[["4.30000000","188.36000000"],["4.12000000","2021.57000000"]],"a":[]}},{"timeToSleep":2000,"data":{"e":"depthUpdate","E":1672242794748,"s":"TORNBUSD","U":113355949,"u":113355949,"b":[["4.11000000","430.47000000"]],"a":[]}},{"timeToSleep":2021,"data":{"e":"depthUpdate","E":1672242796748,"s":"TORNBUSD","U":113355950,"u":113355950,"b":[],"a":[["4.32000000","835.83000000"]]}},{"timeToSleep":3990,"data":{"e":"depthUpdate","E":1672242800748,"s":"TORNBUSD","U":113355951,"u":113355952,"b":[["4.29000000","322.41000000"],["4.25000000","579.73000000"]],"a":[]}},{"timeToSleep":987,"data":{"e":"depthUpdate","E":1672242801748,"s":"TORNBUSD","U":113355953,"u":113355953,"b":[],"a":[["6.90000000","936.61000000"]]}},{"timeToSleep":1011,"data":{"e":"depthUpdate","E":1672242802748,"s":"TORNBUSD","U":113355954,"u":113355954,"b":[["4.24000000","346.06000000"]],"a":[]}},{"timeToSleep":994,"data":{"e":"depthUpdate","E":1672242803748,"s":"TORNBUSD","U":113355955,"u":113355957,"b":[["4.13000000","716.82000000"]],"a":[["8.00000000","7089.37000000"]]}},{"timeToSleep":1000,"data":{"e":"depthUpdate","E":1672242804748,"s":"TORNBUSD","U":113355958,"u":113355960,"b":[["4.30000000","68.29000000"],["4.23000000","706.90000000"]],"a":[["4.32000000","838.77000000"]]}},{"timeToSleep":1040,"data":{"e":"depthUpdate","E":1672242805748,"s":"TORNBUSD","U":113355961,"u":113355962,"b":[["4.24000000","348.54000000"]],"a":[["12.00000000","16366.89000000"]]}},{"timeToSleep":955,"data":{"e":"depthUpdate","E":1672242806748,"s":"TORNBUSD","U":113355963,"u":113355963,"b":[["4.04000000","147.61000000"]],"a":[]}},{"timeToSleep":2003,"data":{"e":"depthUpdate","E":1672242808748,"s":"TORNBUSD","U":113355964,"u":113355968,"b":[["4.30000000","65.36000000"],["4.24000000","346.06000000"],["4.19000000","598.27000000"],["4.04000000","187.88000000"],["3.50000000","2011.03000000"]],"a":[]}},{"timeToSleep":1000,"data":{"e":"depthUpdate","E":1672242809748,"s":"TORNBUSD","U":113355969,"u":113355969,"b":[],"a":[["7.00000000","5239.89000000"]]}},{"timeToSleep":1001,"data":{"e":"depthUpdate","E":1672242810748,"s":"TORNBUSD","U":113355970,"u":113355971,"b":[["4.18000000","1300.12000000"]],"a":[["6.00000000","8401.13000000"]]}},{"timeToSleep":998,"data":{"e":"depthUpdate","E":1672242811748,"s":"TORNBUSD","U":113355972,"u":113355972,"b":[["4.20000000","8879.17000000"]],"a":[]}},{"timeToSleep":1001,"data":{"e":"depthUpdate","E":1672242812748,"s":"TORNBUSD","U":113355973,"u":113355973,"b":[],"a":[["15.00000000","6729.70000000"]]}},{"timeToSleep":3001,"data":{"e":"depthUpdate","E":1672242815748,"s":"TORNBUSD","U":113355974,"u":113355978,"b":[["4.30000000","127.76000000"],["4.29000000","350.89000000"]],"a":[["4.31000000","152.25000000"],["4.32000000","585.69000000"]]}},{"timeToSleep":1000,"data":{"e":"depthUpdate","E":1672242816749,"s":"TORNBUSD","U":113355979,"u":113355980,"b":[["4.14000000","592.95000000"],["4.12000000","1912.60000000"]],"a":[]}},{"timeToSleep":1010,"data":{"e":"depthUpdate","E":1672242817749,"s":"TORNBUSD","U":113355981,"u":113355981,"b":[],"a":[["4.77000000","97.56000000"]]}},{"timeToSleep":1992,"data":{"e":"depthUpdate","E":1672242819749,"s":"TORNBUSD","U":113355982,"u":113355982,"b":[["4.25000000","591.10000000"]],"a":[]}},{"timeToSleep":2001,"data":{"e":"depthUpdate","E":1672242821749,"s":"TORNBUSD","U":113355983,"u":113355984,"b":[["4.06000000","874.38000000"]],"a":[["19.00000000","11209.53000000"]]}},{"timeToSleep":7998,"data":{"e":"depthUpdate","E":1672242829749,"s":"TORNBUSD","U":113355985,"u":113355985,"b":[["4.05000000","3854.52000000"]],"a":[]}},{"timeToSleep":2074,"data":{"e":"depthUpdate","E":1672242831750,"s":"TORNBUSD","U":113355986,"u":113355993,"b":[["4.30000000","420.25000000"],["4.29000000","322.41000000"]],"a":[["4.31000000","0.00000000"],["4.32000000","407.22000000"],["4.34000000","170.07000000"]]}},{"timeToSleep":2967,"data":{"e":"depthUpdate","E":1672242834750,"s":"TORNBUSD","U":113355994,"u":113355994,"b":[["4.18000000","1039.60000000"]],"a":[]}},{"timeToSleep":1033,"data":{"e":"depthUpdate","E":1672242835750,"s":"TORNBUSD","U":113355995,"u":113355995,"b":[["4.14000000","590.13000000"]],"a":[]}},{"timeToSleep":1927,"data":{"e":"depthUpdate","E":1672242837750,"s":"TORNBUSD","U":113355996,"u":113355997,"b":[["4.11000000","454.76000000"],["4.10000000","1272.60000000"]],"a":[]}},{"timeToSleep":3084,"data":{"e":"depthUpdate","E":1672242840750,"s":"TORNBUSD","U":113355998,"u":113355998,"b":[],"a":[["4.37000000","756.53000000"]]}},{"timeToSleep":1025,"data":{"e":"depthUpdate","E":1672242841750,"s":"TORNBUSD","U":113355999,"u":113355999,"b":[["4.19000000","383.85000000"]],"a":[]}},{"timeToSleep":1955,"data":{"e":"depthUpdate","E":1672242843750,"s":"TORNBUSD","U":113356000,"u":113356003,"b":[["4.30000000","436.83000000"],["4.19000000","598.27000000"],["4.05000000","1957.17000000"]],"a":[["4.32000000","242.06000000"]]}},{"timeToSleep":1015,"data":{"e":"depthUpdate","E":1672242844750,"s":"TORNBUSD","U":113356004,"u":113356004,"b":[["4.12000000","3777.72000000"]],"a":[]}},{"timeToSleep":2053,"data":{"e":"depthUpdate","E":1672242846750,"s":"TORNBUSD","U":113356005,"u":113356034,"b":[["4.33000000","4.39000000"],["4.32000000","201.40000000"],["4.31000000","120.89000000"],["4.30000000","420.61000000"],["4.29000000","254.18000000"],["4.26000000","322.74000000"],["4.23000000","847.32000000"],["4.21000000","1106.84000000"],["4.17000000","272.31000000"],["4.16000000","95.27000000"],["4.14000000","533.57000000"],["4.13000000","776.74000000"],["4.11000000","394.04000000"]],"a":[["4.32000000","0.00000000"],["4.33000000","0.00000000"],["4.34000000","0.00000000"],["4.35000000","2.83000000"],["4.36000000","225.69000000"],["4.40000000","537.13000000"],["4.43000000","1016.22000000"]]}},{"timeToSleep":921,"data":{"e":"depthUpdate","E":1672242847750,"s":"TORNBUSD","U":113356035,"u":113356047,"b":[["4.31000000","149.24000000"],["4.20000000","8886.77000000"],["4.17000000","415.64000000"],["4.15000000","887.87000000"],["4.14000000","425.11000000"],["4.13000000","824.69000000"],["4.12000000","1912.60000000"],["4.11000000","345.47000000"],["4.06000000","2767.06000000"],["4.05000000","1826.54000000"]],"a":[]}},{"timeToSleep":1020,"data":{"e":"depthUpdate","E":1672242848750,"s":"TORNBUSD","U":113356048,"u":113356050,"b":[["4.33000000","7.74000000"],["4.30000000","423.99000000"],["4.16000000","98.07000000"]],"a":[]}},{"timeToSleep":1024,"data":{"e":"depthUpdate","E":1672242849750,"s":"TORNBUSD","U":113356051,"u":113356053,"b":[["4.07000000","2264.23000000"],["4.06000000","874.38000000"]],"a":[]}},{"timeToSleep":1040,"data":{"e":"depthUpdate","E":1672242850751,"s":"TORNBUSD","U":113356054,"u":113356058,"b":[["4.32000000","288.29000000"],["4.31000000","62.35000000"],["4.25000000","593.57000000"]],"a":[]}},{"timeToSleep":1928,"data":{"e":"depthUpdate","E":1672242852751,"s":"TORNBUSD","U":113356059,"u":113356060,"b":[["4.16000000","41.78000000"]],"a":[["4.37000000","710.28000000"]]}},{"timeToSleep":1127,"data":{"e":"depthUpdate","E":1672242853751,"s":"TORNBUSD","U":113356061,"u":113356068,"b":[["4.33000000","184.98000000"],["4.32000000","1140.62000000"],["4.31000000","37.51000000"],["4.30000000","364.18000000"],["4.21000000","1318.47000000"],["4.19000000","383.85000000"],["4.16000000","98.54000000"]],"a":[["4.35000000","7.83000000"]]}},{"timeToSleep":919,"data":{"e":"depthUpdate","E":1672242854751,"s":"TORNBUSD","U":113356069,"u":113356082,"b":[["4.34000000","165.32000000"],["4.33000000","213.20000000"],["4.32000000","962.16000000"],["4.31000000","9.16000000"],["4.29000000","257.66000000"],["4.20000000","8957.48000000"],["4.18000000","1062.69000000"],["4.14000000","328.67000000"],["4.12000000","1936.84000000"],["4.06000000","845.47000000"],["3.97000000","3646.15000000"],["3.94000000","69.95000000"]],"a":[]}},{"timeToSleep":903,"data":{"e":"depthUpdate","E":1672242855751,"s":"TORNBUSD","U":113356083,"u":113356100,"b":[["4.28000000","1179.42000000"],["4.25000000","730.86000000"],["4.23000000","706.90000000"],["4.20000000","8962.19000000"],["4.17000000","493.99000000"],["4.15000000","976.12000000"],["4.14000000","244.28000000"],["4.13000000","740.80000000"],["4.12000000","3801.96000000"],["4.10000000","1267.78000000"],["4.07000000","376.20000000"],["4.06000000","874.38000000"]],"a":[["4.43000000","681.71000000"]]}},{"timeToSleep":1047,"data":{"e":"depthUpdate","E":1672242856751,"s":"TORNBUSD","U":113356101,"u":113356105,"b":[["4.26000000","391.86000000"],["4.19000000","419.29000000"],["4.17000000","458.38000000"],["4.09000000","66.25000000"]],"a":[["4.44000000","794.66000000"]]}},{"timeToSleep":1024,"data":{"e":"depthUpdate","E":1672242857751,"s":"TORNBUSD","U":113356106,"u":113356107,"b":[],"a":[["4.35000000","67.96000000"],["12.00000000","16362.05000000"]]}},{"timeToSleep":1025,"data":{"e":"depthUpdate","E":1672242858751,"s":"TORNBUSD","U":113356108,"u":113356118,"b":[["4.34000000","153.76000000"],["4.23000000","770.79000000"],["4.20000000","8897.31000000"],["4.17000000","933.20000000"],["4.14000000","268.20000000"],["4.13000000","2117.99000000"],["4.12000000","1936.84000000"],["4.11000000","321.18000000"],["4.10000000","1315.23000000"]],"a":[["4.35000000","523.94000000"]]}},{"timeToSleep":926,"data":{"e":"depthUpdate","E":1672242859751,"s":"TORNBUSD","U":113356119,"u":113356119,"b":[["4.34000000","148.92000000"]],"a":[]}},{"timeToSleep":1124,"data":{"e":"depthUpdate","E":1672242860751,"s":"TORNBUSD","U":113356120,"u":113356124,"b":[["4.23000000","790.27000000"],["4.15000000","999.98000000"],["4.13000000","233.41000000"]],"a":[]}},{"timeToSleep":915,"data":{"e":"depthUpdate","E":1672242861751,"s":"TORNBUSD","U":113356125,"u":113356134,"b":[["4.26000000","459.72000000"],["4.22000000","1263.04000000"],["4.18000000","1118.71000000"],["4.16000000","41.78000000"],["4.12000000","3755.13000000"],["4.09000000","73.99000000"],["4.05000000","1818.66000000"]],"a":[["4.35000000","502.80000000"],["4.38000000","423.28000000"]]}},{"timeToSleep":1024,"data":{"e":"depthUpdate","E":1672242862751,"s":"TORNBUSD","U":113356135,"u":113356141,"b":[["4.12000000","3708.30000000"],["4.08000000","93.16000000"],["4.03000000","539.54000000"],["4.00000000","25847.48000000"],["3.97000000","3313.99000000"]],"a":[["4.35000000","455.98000000"],["4.39000000","774.53000000"]]}},{"timeToSleep":1025,"data":{"e":"depthUpdate","E":1672242863752,"s":"TORNBUSD","U":113356142,"u":113356151,"b":[["4.29000000","299.04000000"],["4.27000000","387.25000000"],["4.23000000","859.23000000"],["4.13000000","280.51000000"]],"a":[["4.35000000","464.65000000"]]}},{"timeToSleep":924,"data":{"e":"depthUpdate","E":1672242864751,"s":"TORNBUSD","U":113356152,"u":113356154,"b":[["4.13000000","327.61000000"],["4.08000000","140.84000000"],["4.03000000","568.67000000"]],"a":[]}},{"timeToSleep":967,"data":{"e":"depthUpdate","E":1672242865751,"s":"TORNBUSD","U":113356155,"u":113356158,"b":[["4.06000000","812.92000000"]],"a":[["4.35000000","458.07000000"],["4.47000000","464.99000000"],["4.50000000","1714.87000000"]]}},{"timeToSleep":986,"data":{"e":"depthUpdate","E":1672242866751,"s":"TORNBUSD","U":113356159,"u":113356159,"b":[["4.34000000","144.66000000"]],"a":[]}},{"timeToSleep":1120,"data":{"e":"depthUpdate","E":1672242867751,"s":"TORNBUSD","U":113356160,"u":113356162,"b":[["4.08000000","202.00000000"]],"a":[["4.35000000","490.64000000"],["4.36000000","232.19000000"]]}},{"timeToSleep":918,"data":{"e":"depthUpdate","E":1672242868751,"s":"TORNBUSD","U":113356163,"u":113356163,"b":[["4.27000000","377.31000000"]],"a":[]}},{"timeToSleep":1029,"data":{"e":"depthUpdate","E":1672242869752,"s":"TORNBUSD","U":113356164,"u":113356165,"b":[],"a":[["4.37000000","716.78000000"],["10.00000000","5791.27000000"]]}},{"timeToSleep":2042,"data":{"e":"depthUpdate","E":1672242871752,"s":"TORNBUSD","U":113356166,"u":113356166,"b":[["4.26000000","1238.73000000"]],"a":[]}},{"timeToSleep":1951,"data":{"e":"depthUpdate","E":1672242873752,"s":"TORNBUSD","U":113356167,"u":113356170,"b":[["4.23000000","842.64000000"],["4.18000000","1119.50000000"]],"a":[["4.40000000","198.94000000"]]}},{"timeToSleep":1021,"data":{"e":"depthUpdate","E":1672242874752,"s":"TORNBUSD","U":113356171,"u":113356181,"b":[["4.34000000","84.82000000"],["4.20000000","8426.60000000"],["4.19000000","584.68000000"],["4.15000000","831.61000000"],["4.14000000","296.32000000"],["4.13000000","355.80000000"],["4.12000000","3651.32000000"]],"a":[["23.00000000","4191.71000000"]]}},{"timeToSleep":1025,"data":{"e":"depthUpdate","E":1672242875752,"s":"TORNBUSD","U":113356182,"u":113356182,"b":[["4.22000000","1333.41000000"]],"a":[]}},{"timeToSleep":1033,"data":{"e":"depthUpdate","E":1672242876752,"s":"TORNBUSD","U":113356183,"u":113356184,"b":[["4.24000000","362.61000000"],["4.19000000","549.24000000"]],"a":[]}},{"timeToSleep":863,"data":{"e":"depthUpdate","E":1672242877752,"s":"TORNBUSD","U":113356185,"u":113356192,"b":[["4.34000000","0.00000000"],["4.33000000","298.02000000"],["4.18000000","1155.32000000"],["4.13000000","402.87000000"]],"a":[["4.35000000","508.03000000"],["4.36000000","552.99000000"],["4.40000000","143.25000000"]]}},{"timeToSleep":1086,"data":{"e":"depthUpdate","E":1672242878752,"s":"TORNBUSD","U":113356193,"u":113356196,"b":[["4.12000000","3658.88000000"],["4.07000000","368.54000000"]],"a":[["4.35000000","514.14000000"],["4.39000000","214.04000000"]]}},{"timeToSleep":1028,"data":{"e":"depthUpdate","E":1672242879752,"s":"TORNBUSD","U":113356197,"u":113356198,"b":[],"a":[["5.20000000","800.20000000"],["11.58000000","24.26000000"]]}},{"timeToSleep":1005,"data":{"e":"depthUpdate","E":1672242880752,"s":"TORNBUSD","U":113356199,"u":113356202,"b":[["4.34000000","151.35000000"]],"a":[["4.35000000","496.75000000"],["4.36000000","570.38000000"],["5.50000000","8097.03000000"]]}},{"timeToSleep":935,"data":{"e":"depthUpdate","E":1672242881752,"s":"TORNBUSD","U":113356203,"u":113356205,"b":[["4.34000000","146.89000000"],["4.29000000","310.21000000"],["4.25000000","719.49000000"]],"a":[]}},{"timeToSleep":1018,"data":{"e":"depthUpdate","E":1672242882752,"s":"TORNBUSD","U":113356206,"u":113356206,"b":[],"a":[["4.36000000","632.61000000"]]}},{"timeToSleep":2048,"data":{"e":"depthUpdate","E":1672242884752,"s":"TORNBUSD","U":113356207,"u":113356209,"b":[["4.19000000","383.85000000"]],"a":[["4.35000000","552.44000000"],["5.00000000","5739.16000000"]]}},{"timeToSleep":1020,"data":{"e":"depthUpdate","E":1672242885752,"s":"TORNBUSD","U":113356210,"u":113356212,"b":[["4.19000000","550.62000000"],["4.17000000","843.43000000"],["3.30000000","2917.29000000"]],"a":[]}},{"timeToSleep":918,"data":{"e":"depthUpdate","E":1672242886752,"s":"TORNBUSD","U":113356213,"u":113356215,"b":[["4.29000000","320.11000000"],["4.20000000","8515.72000000"],["4.00000000","25876.73000000"]],"a":[]}},{"timeToSleep":2047,"data":{"e":"depthUpdate","E":1672242888752,"s":"TORNBUSD","U":113356216,"u":113356218,"b":[["4.34000000","142.33000000"],["4.15000000","826.84000000"]],"a":[["6.00000000","8527.04000000"]]}},{"timeToSleep":925,"data":{"e":"depthUpdate","E":1672242889753,"s":"TORNBUSD","U":113356219,"u":113356231,"b":[["4.34000000","0.00000000"],["4.33000000","120.78000000"],["4.31000000","186.40000000"],["4.12000000","3687.14000000"],["4.11000000","349.50000000"],["4.09000000","92.46000000"],["4.08000000","173.23000000"],["4.06000000","860.44000000"],["4.05000000","1770.63000000"],["4.03000000","520.40000000"]],"a":[["4.34000000","418.16000000"],["4.35000000","569.83000000"],["4.36000000","615.22000000"]]}},{"timeToSleep":3073,"data":{"e":"depthUpdate","E":1672242892753,"s":"TORNBUSD","U":113356232,"u":113356232,"b":[],"a":[["16.10000000","854.06000000"]]}},{"timeToSleep":1023,"data":{"e":"depthUpdate","E":1672242893753,"s":"TORNBUSD","U":113356233,"u":113356234,"b":[["4.24000000","290.73000000"],["3.82000000","994.09000000"]],"a":[]}},{"timeToSleep":919,"data":{"e":"depthUpdate","E":1672242894753,"s":"TORNBUSD","U":113356235,"u":113356235,"b":[],"a":[["4.41000000","141.41000000"]]}},{"timeToSleep":3074,"data":{"e":"depthUpdate","E":1672242897753,"s":"TORNBUSD","U":113356236,"u":113356236,"b":[],"a":[["6.30000000","1869.34000000"]]}},{"timeToSleep":5940,"data":{"e":"depthUpdate","E":1672242903753,"s":"TORNBUSD","U":113356237,"u":113356240,"b":[["4.16000000","25.71000000"],["4.15000000","873.33000000"],["4.13000000","355.77000000"]],"a":[["4.42000000","570.44000000"]]}},{"timeToSleep":1022,"data":{"e":"depthUpdate","E":1672242904753,"s":"TORNBUSD","U":113356241,"u":113356245,"b":[["4.18000000","1171.32000000"],["4.15000000","919.82000000"],["4.13000000","308.67000000"],["4.11000000","396.44000000"],["4.08000000","125.55000000"]],"a":[]}},{"timeToSleep":1027,"data":{"e":"depthUpdate","E":1672242905753,"s":"TORNBUSD","U":113356246,"u":113356246,"b":[["2.80000000","2514.46000000"]],"a":[]}},{"timeToSleep":1945,"data":{"e":"depthUpdate","E":1672242907754,"s":"TORNBUSD","U":113356247,"u":113356249,"b":[["4.30000000","435.06000000"],["4.23000000","921.20000000"],["4.04000000","147.61000000"]],"a":[]}},{"timeToSleep":1036,"data":{"e":"depthUpdate","E":1672242908754,"s":"TORNBUSD","U":113356250,"u":113356250,"b":[["4.00000000","25851.73000000"],["3.80000000","2941.33000000"],["3.37000000","67.35000000"]],"a":[]}},{"timeToSleep":910,"data":{"e":"depthUpdate","E":1672242909754,"s":"TORNBUSD","U":113356251,"u":113356252,"b":[["4.07000000","408.51000000"]],"a":[["20.00000000","28430.35000000"]]}},{"timeToSleep":1001,"data":{"e":"depthUpdate","E":1672242910754,"s":"TORNBUSD","U":113356253,"u":113356253,"b":[],"a":[["4.34000000","402.55000000"]]}},{"timeToSleep":1047,"data":{"e":"depthUpdate","E":1672242911754,"s":"TORNBUSD","U":113356254,"u":113356255,"b":[],"a":[["4.39000000","198.07000000"],["4.41000000","157.31000000"]]}},{"timeToSleep":953,"data":{"e":"depthUpdate","E":1672242912754,"s":"TORNBUSD","U":113356256,"u":113356256,"b":[],"a":[["4.50000000","1016.80000000"]]}},{"timeToSleep":3000,"data":{"e":"depthUpdate","E":1672242915754,"s":"TORNBUSD","U":113356257,"u":113356258,"b":[],"a":[["4.37000000","710.28000000"],["4.44000000","460.15000000"]]}},{"timeToSleep":1073,"data":{"e":"depthUpdate","E":1672242916754,"s":"TORNBUSD","U":113356259,"u":113356263,"b":[["4.14000000","324.44000000"],["4.13000000","280.48000000"]],"a":[["4.34000000","457.72000000"],["4.36000000","608.72000000"],["4.46000000","565.19000000"]]}},{"timeToSleep":1016,"data":{"e":"depthUpdate","E":1672242917754,"s":"TORNBUSD","U":113356264,"u":113356267,"b":[["4.24000000","274.18000000"]],"a":[["4.35000000","505.47000000"],["4.90000000","4418.02000000"]]}},{"timeToSleep":1024,"data":{"e":"depthUpdate","E":1672242918754,"s":"TORNBUSD","U":113356268,"u":113356268,"b":[["4.28000000","1181.82000000"]],"a":[]}},{"timeToSleep":921,"data":{"e":"depthUpdate","E":1672242919754,"s":"TORNBUSD","U":113356269,"u":113356271,"b":[["4.29000000","166.35000000"],["4.26000000","1255.20000000"],["3.50000000","1762.81000000"]],"a":[]}},{"timeToSleep":1022,"data":{"e":"depthUpdate","E":1672242920754,"s":"TORNBUSD","U":113356272,"u":113356272,"b":[],"a":[["4.40000000","841.32000000"]]}},{"timeToSleep":2051,"data":{"e":"depthUpdate","E":1672242922754,"s":"TORNBUSD","U":113356273,"u":113356273,"b":[["4.14000000","296.32000000"]],"a":[]}},{"timeToSleep":1025,"data":{"e":"depthUpdate","E":1672242923755,"s":"TORNBUSD","U":113356274,"u":113356281,"b":[["4.33000000","99.11000000"],["4.26000000","1231.76000000"],["4.24000000","297.73000000"],["4.17000000","735.71000000"],["4.15000000","1028.04000000"],["4.12000000","1822.02000000"]],"a":[["4.34000000","471.65000000"],["4.35000000","509.86000000"]]}},{"timeToSleep":920,"data":{"e":"depthUpdate","E":1672242924755,"s":"TORNBUSD","U":113356282,"u":113356286,"b":[["4.14000000","324.68000000"],["4.07000000","2296.54000000"]],"a":[["4.34000000","472.17000000"],["4.35000000","513.20000000"]]}},{"timeToSleep":3073,"data":{"e":"depthUpdate","E":1672242927755,"s":"TORNBUSD","U":113356287,"u":113356287,"b":[["4.10000000","1312.06000000"]],"a":[]}},{"timeToSleep":2967,"data":{"e":"depthUpdate","E":1672242930755,"s":"TORNBUSD","U":113356288,"u":113356288,"b":[],"a":[["8.50000000","1729.60000000"]]}},{"timeToSleep":1024,"data":{"e":"depthUpdate","E":1672242931755,"s":"TORNBUSD","U":113356289,"u":113356289,"b":[["4.30000000","437.46000000"]],"a":[]}},{"timeToSleep":927,"data":{"e":"depthUpdate","E":1672242932755,"s":"TORNBUSD","U":113356290,"u":113356293,"b":[["4.33000000","95.07000000"]],"a":[["4.34000000","476.21000000"],["4.42000000","563.87000000"],["4.99000000","7993.17000000"]]}},{"timeToSleep":1023,"data":{"e":"depthUpdate","E":1672242933755,"s":"TORNBUSD","U":113356294,"u":113356294,"b":[["4.25000000","788.77000000"]],"a":[]}},{"timeToSleep":1022,"data":{"e":"depthUpdate","E":1672242934755,"s":"TORNBUSD","U":113356295,"u":113356295,"b":[],"a":[["21.58000000","55.79000000"]]}},{"timeToSleep":1026,"data":{"e":"depthUpdate","E":1672242935755,"s":"TORNBUSD","U":113356296,"u":113356296,"b":[["4.00000000","25524.79000000"]],"a":[]}},{"timeToSleep":5938,"data":{"e":"depthUpdate","E":1672242941756,"s":"TORNBUSD","U":113356297,"u":113356298,"b":[["4.28000000","1179.39000000"]],"a":[["4.40000000","853.98000000"]]}},{"timeToSleep":1023,"data":{"e":"depthUpdate","E":1672242942756,"s":"TORNBUSD","U":113356299,"u":113356301,"b":[["4.25000000","719.49000000"],["4.00000000","25854.46000000"]],"a":[["4.74000000","93.17000000"]]}},{"timeToSleep":1124,"data":{"e":"depthUpdate","E":1672242943756,"s":"TORNBUSD","U":113356302,"u":113356303,"b":[["4.33000000","44.38000000"]],"a":[["4.34000000","486.46000000"]]}},{"timeToSleep":925,"data":{"e":"depthUpdate","E":1672242944756,"s":"TORNBUSD","U":113356304,"u":113356304,"b":[["4.20000000","8777.16000000"]],"a":[]}},{"timeToSleep":1941,"data":{"e":"depthUpdate","E":1672242946756,"s":"TORNBUSD","U":113356305,"u":113356305,"b":[["4.33000000","37.81000000"]],"a":[]}},{"timeToSleep":2049,"data":{"e":"depthUpdate","E":1672242948756,"s":"TORNBUSD","U":113356306,"u":113356306,"b":[],"a":[["4.36000000","546.49000000"]]}},{"timeToSleep":925,"data":{"e":"depthUpdate","E":1672242949756,"s":"TORNBUSD","U":113356307,"u":113356314,"b":[["4.33000000","0.00000000"],["4.32000000","875.27000000"],["4.31000000","273.29000000"],["4.15000000","981.55000000"],["4.14000000","371.28000000"]],"a":[]}},{"timeToSleep":1023,"data":{"e":"depthUpdate","E":1672242950756,"s":"TORNBUSD","U":113356315,"u":113356316,"b":[["4.08000000","2008.95000000"],["4.07000000","408.51000000"]],"a":[]}},{"timeToSleep":1028,"data":{"e":"depthUpdate","E":1672242951756,"s":"TORNBUSD","U":113356317,"u":113356322,"b":[["4.29000000","155.18000000"],["4.27000000","388.54000000"],["4.25000000","579.73000000"],["4.23000000","983.06000000"],["4.12000000","1793.76000000"]],"a":[]}},{"timeToSleep":1029,"data":{"e":"depthUpdate","E":1672242952756,"s":"TORNBUSD","U":113356323,"u":113356329,"b":[["4.24000000","297.73000000"],["4.23000000","842.64000000"],["4.18000000","1115.30000000"],["4.17000000","652.62000000"],["4.16000000","82.00000000"]],"a":[["4.43000000","4182.82000000"]]}},{"timeToSleep":918,"data":{"e":"depthUpdate","E":1672242953756,"s":"TORNBUSD","U":113356330,"u":113356333,"b":[["4.23000000","921.20000000"],["4.16000000","165.98000000"],["4.10000000","1340.69000000"]],"a":[["4.46000000","230.68000000"]]}},{"timeToSleep":1017,"data":{"e":"depthUpdate","E":1672242954756,"s":"TORNBUSD","U":113356334,"u":113356336,"b":[["4.23000000","984.23000000"]],"a":[["4.42000000","898.38000000"]]}},{"timeToSleep":957,"data":{"e":"depthUpdate","E":1672242955756,"s":"TORNBUSD","U":113356337,"u":113356337,"b":[["4.24000000","376.10000000"]],"a":[]}},{"timeToSleep":995,"data":{"e":"depthUpdate","E":1672242956756,"s":"TORNBUSD","U":113356338,"u":113356339,"b":[["4.20000000","8596.78000000"],["4.14000000","343.16000000"]],"a":[]}},{"timeToSleep":995,"data":{"e":"depthUpdate","E":1672242957756,"s":"TORNBUSD","U":113356340,"u":113356341,"b":[["4.14000000","371.52000000"]],"a":[["4.33000000","8.29000000"]]}},{"timeToSleep":1003,"data":{"e":"depthUpdate","E":1672242958756,"s":"TORNBUSD","U":113356342,"u":113356348,"b":[["4.08000000","125.55000000"],["4.05000000","3667.98000000"]],"a":[["4.33000000","36.51000000"],["4.34000000","458.24000000"]]}},{"timeToSleep":997,"data":{"e":"depthUpdate","E":1672242959756,"s":"TORNBUSD","U":113356349,"u":113356349,"b":[],"a":[["4.68000000","408.97000000"]]}},{"timeToSleep":2120,"data":{"e":"depthUpdate","E":1672242961757,"s":"TORNBUSD","U":113356350,"u":113356355,"b":[["4.30000000","440.48000000"]],"a":[["4.33000000","8.29000000"],["4.34000000","482.75000000"]]}},{"timeToSleep":882,"data":{"e":"depthUpdate","E":1672242962756,"s":"TORNBUSD","U":113356356,"u":113356358,"b":[],"a":[["4.33000000","36.51000000"],["4.34000000","464.78000000"],["4.69000000","5549.61000000"]]}},{"timeToSleep":1069,"data":{"e":"depthUpdate","E":1672242963756,"s":"TORNBUSD","U":113356359,"u":113356363,"b":[["4.32000000","880.75000000"],["4.07000000","2296.54000000"],["4.05000000","1770.63000000"],["3.97000000","3176.84000000"]],"a":[["4.98000000","526.20000000"]]}},{"timeToSleep":2044,"data":{"e":"depthUpdate","E":1672242965757,"s":"TORNBUSD","U":113356364,"u":113356366,"b":[["3.96000000","161.98000000"]],"a":[["4.70000000","1004.61000000"],["21.50000000","2185.77000000"]]}},{"timeToSleep":2047,"data":{"e":"depthUpdate","E":1672242967757,"s":"TORNBUSD","U":113356367,"u":113356367,"b":[],"a":[["4.80000000","322.90000000"]]}},{"timeToSleep":922,"data":{"e":"depthUpdate","E":1672242968757,"s":"TORNBUSD","U":113356368,"u":113356369,"b":[["4.30000000","616.67000000"]],"a":[["4.71000000","306.89000000"]]}},{"timeToSleep":1024,"data":{"e":"depthUpdate","E":1672242969757,"s":"TORNBUSD","U":113356370,"u":113356376,"b":[["4.24000000","352.55000000"],["4.12000000","1769.52000000"]],"a":[["4.33000000","211.86000000"],["4.41000000","141.41000000"],["4.42000000","563.87000000"],["4.43000000","4517.33000000"]]}},{"timeToSleep":1024,"data":{"e":"depthUpdate","E":1672242970757,"s":"TORNBUSD","U":113356377,"u":113356378,"b":[["4.24000000","274.18000000"]],"a":[["4.38000000","439.29000000"]]}},{"timeToSleep":928,"data":{"e":"depthUpdate","E":1672242971757,"s":"TORNBUSD","U":113356379,"u":113356398,"b":[["4.32000000","869.77000000"],["4.29000000","110.32000000"],["4.27000000","173.65000000"],["4.26000000","1162.64000000"],["4.24000000","447.79000000"],["4.23000000","993.83000000"],["4.20000000","8666.22000000"]],"a":[["4.90000000","4532.77000000"],["4.99000000","7878.42000000"]]}},{"timeToSleep":1015,"data":{"e":"depthUpdate","E":1672242972757,"s":"TORNBUSD","U":113356399,"u":113356401,"b":[["4.07000000","408.51000000"],["4.05000000","3667.98000000"]],"a":[["4.33000000","220.15000000"]]}},{"timeToSleep":933,"data":{"e":"depthUpdate","E":1672242973757,"s":"TORNBUSD","U":113356402,"u":113356402,"b":[["4.26000000","1165.11000000"]],"a":[]}},{"timeToSleep":2040,"data":{"e":"depthUpdate","E":1672242975757,"s":"TORNBUSD","U":113356403,"u":113356403,"b":[],"a":[["21.00000000","4722.68000000"]]}},{"timeToSleep":1030,"data":{"e":"depthUpdate","E":1672242976757,"s":"TORNBUSD","U":113356404,"u":113356404,"b":[],"a":[["4.34000000","402.55000000"]]}},{"timeToSleep":1017,"data":{"e":"depthUpdate","E":1672242977757,"s":"TORNBUSD","U":113356405,"u":113356405,"b":[],"a":[["4.95000000","10071.28000000"]]}},{"timeToSleep":1026,"data":{"e":"depthUpdate","E":1672242978757,"s":"TORNBUSD","U":113356406,"u":113356406,"b":[["4.18000000","1079.48000000"]],"a":[]}},{"timeToSleep":920,"data":{"e":"depthUpdate","E":1672242979757,"s":"TORNBUSD","U":113356407,"u":113356408,"b":[["4.18000000","1007.84000000"],["4.17000000","688.52000000"]],"a":[]}},{"timeToSleep":1024,"data":{"e":"depthUpdate","E":1672242980757,"s":"TORNBUSD","U":113356409,"u":113356409,"b":[],"a":[["4.33000000","211.86000000"]]}},{"timeToSleep":1028,"data":{"e":"depthUpdate","E":1672242981757,"s":"TORNBUSD","U":113356410,"u":113356411,"b":[["4.20000000","8737.52000000"]],"a":[["21.60000000","865.50000000"]]}},{"timeToSleep":1028,"data":{"e":"depthUpdate","E":1672242982757,"s":"TORNBUSD","U":113356412,"u":113356412,"b":[],"a":[["4.67000000","298.59000000"]]}},{"timeToSleep":928,"data":{"e":"depthUpdate","E":1672242983757,"s":"TORNBUSD","U":113356413,"u":113356416,"b":[["4.32000000","861.48000000"],["4.26000000","1162.64000000"]],"a":[["4.34000000","419.96000000"],["4.37000000","768.64000000"]]}},{"timeToSleep":977,"data":{"e":"depthUpdate","E":1672242984757,"s":"TORNBUSD","U":113356417,"u":113356418,"b":[["4.26000000","1146.17000000"]],"a":[["4.33000000","274.09000000"]]}},{"timeToSleep":1075,"data":{"e":"depthUpdate","E":1672242985757,"s":"TORNBUSD","U":113356419,"u":113356425,"b":[["4.32000000","822.50000000"],["4.25000000","596.24000000"]],"a":[["4.33000000","332.45000000"],["4.34000000","425.49000000"],["4.37000000","710.28000000"],["4.69000000","5609.74000000"]]}},{"timeToSleep":1083,"data":{"e":"depthUpdate","E":1672242986758,"s":"TORNBUSD","U":113356426,"u":113356426,"b":[["4.28000000","1550.09000000"]],"a":[]}},{"timeToSleep":971,"data":{"e":"depthUpdate","E":1672242987758,"s":"TORNBUSD","U":113356427,"u":113356427,"b":[["4.05000000","1770.63000000"]],"a":[]}},{"timeToSleep":894,"data":{"e":"depthUpdate","E":1672242988758,"s":"TORNBUSD","U":113356428,"u":113356431,"b":[["4.32000000","764.14000000"],["4.29000000","115.32000000"],["4.07000000","2296.54000000"]],"a":[["4.33000000","274.09000000"]]}},{"timeToSleep":5021,"data":{"e":"depthUpdate","E":1672242993758,"s":"TORNBUSD","U":113356432,"u":113356432,"b":[["4.32000000","761.48000000"]],"a":[]}},{"timeToSleep":933,"data":{"e":"depthUpdate","E":1672242994758,"s":"TORNBUSD","U":113356433,"u":113356435,"b":[["4.28000000","1421.50000000"]],"a":[["4.40000000","978.11000000"],["4.44000000","336.02000000"],["7.11000000","94.10000000"]]}},{"timeToSleep":1120,"data":{"e":"depthUpdate","E":1672242995758,"s":"TORNBUSD","U":113356436,"u":113356437,"b":[["4.30000000","672.47000000"],["3.50000000","1758.51000000"]],"a":[]}},{"timeToSleep":914,"data":{"e":"depthUpdate","E":1672242996758,"s":"TORNBUSD","U":113356438,"u":113356439,"b":[["4.26000000","1050.40000000"],["4.17000000","213.70000000"]],"a":[]}},{"timeToSleep":1028,"data":{"e":"depthUpdate","E":1672242997758,"s":"TORNBUSD","U":113356440,"u":113356444,"b":[["4.32000000","637.64000000"],["4.15000000","1462.63000000"],["4.07000000","408.51000000"],["4.05000000","3667.98000000"]],"a":[["21.00000000","4777.43000000"]]}},{"timeToSleep":5017,"data":{"e":"depthUpdate","E":1672243002758,"s":"TORNBUSD","U":113356445,"u":113356447,"b":[["4.30000000","800.46000000"],["4.11000000","368.12000000"]],"a":[["4.40000000","1033.80000000"]]}},{"timeToSleep":1031,"data":{"e":"depthUpdate","E":1672243003758,"s":"TORNBUSD","U":113356448,"u":113356449,"b":[["4.09000000","121.16000000"],["4.07000000","368.54000000"]],"a":[]}},{"timeToSleep":1889,"data":{"e":"depthUpdate","E":1672243005758,"s":"TORNBUSD","U":113356450,"u":113356450,"b":[["4.06000000","900.51000000"]],"a":[]}},{"timeToSleep":1033,"data":{"e":"depthUpdate","E":1672243006759,"s":"TORNBUSD","U":113356451,"u":113356451,"b":[["3.52000000","65.35000000"]],"a":[]}},{"timeToSleep":8969,"data":{"e":"depthUpdate","E":1672243015759,"s":"TORNBUSD","U":113356452,"u":113356452,"b":[],"a":[["4.35000000","507.09000000"]]}},{"timeToSleep":1034,"data":{"e":"depthUpdate","E":1672243016759,"s":"TORNBUSD","U":113356453,"u":113356453,"b":[],"a":[["10.00000000","5743.69000000"]]}},{"timeToSleep":1966,"data":{"e":"depthUpdate","E":1672243018759,"s":"TORNBUSD","U":113356454,"u":113356454,"b":[],"a":[["4.41000000","72.22000000"]]}},{"timeToSleep":2017,"data":{"e":"depthUpdate","E":1672243020759,"s":"TORNBUSD","U":113356455,"u":113356456,"b":[["4.14000000","347.60000000"]],"a":[["4.42000000","553.92000000"]]}},{"timeToSleep":1050,"data":{"e":"depthUpdate","E":1672243021759,"s":"TORNBUSD","U":113356457,"u":113356458,"b":[["4.12000000","1793.75000000"],["3.52000000","253.96000000"]],"a":[]}},{"timeToSleep":934,"data":{"e":"depthUpdate","E":1672243022759,"s":"TORNBUSD","U":113356459,"u":113356459,"b":[],"a":[["4.37000000","641.54000000"]]}},{"timeToSleep":1001,"data":{"e":"depthUpdate","E":1672243023759,"s":"TORNBUSD","U":113356460,"u":113356461,"b":[["4.05000000","1770.63000000"]],"a":[["4.68000000","405.76000000"]]}},{"timeToSleep":997,"data":{"e":"depthUpdate","E":1672243024759,"s":"TORNBUSD","U":113356462,"u":113356462,"b":[["4.11000000","2237.77000000"]],"a":[]}},{"timeToSleep":2051,"data":{"e":"depthUpdate","E":1672243026759,"s":"TORNBUSD","U":113356463,"u":113356464,"b":[["4.20000000","8732.81000000"],["4.17000000","216.22000000"]],"a":[]}},{"timeToSleep":2022,"data":{"e":"depthUpdate","E":1672243028759,"s":"TORNBUSD","U":113356465,"u":113356465,"b":[],"a":[["4.44000000","339.23000000"]]}},{"timeToSleep":999,"data":{"e":"depthUpdate","E":1672243029759,"s":"TORNBUSD","U":113356466,"u":113356466,"b":[["4.16000000","163.18000000"]],"a":[]}},{"timeToSleep":1929,"data":{"e":"depthUpdate","E":1672243031760,"s":"TORNBUSD","U":113356467,"u":113356469,"b":[["4.32000000","642.47000000"],["4.16000000","165.98000000"]],"a":[["4.33000000","269.27000000"]]}},{"timeToSleep":1001,"data":{"e":"depthUpdate","E":1672243032760,"s":"TORNBUSD","U":113356470,"u":113356471,"b":[],"a":[["4.41000000","88.98000000"],["4.43000000","4500.65000000"]]}},{"timeToSleep":2032,"data":{"e":"depthUpdate","E":1672243034760,"s":"TORNBUSD","U":113356472,"u":113356474,"b":[["4.32000000","124.29000000"],["4.07000000","238.55000000"]],"a":[]}},{"timeToSleep":979,"data":{"e":"depthUpdate","E":1672243035760,"s":"TORNBUSD","U":113356475,"u":113356477,"b":[["4.31000000","278.13000000"],["4.11000000","368.12000000"]],"a":[["4.33000000","293.06000000"]]}},{"timeToSleep":1067,"data":{"e":"depthUpdate","E":1672243036760,"s":"TORNBUSD","U":113356478,"u":113356481,"b":[["4.07000000","368.54000000"],["4.05000000","3667.98000000"]],"a":[["4.33000000","452.07000000"],["4.35000000","474.52000000"]]}},{"timeToSleep":924,"data":{"e":"depthUpdate","E":1672243037760,"s":"TORNBUSD","U":113356482,"u":113356482,"b":[["4.21000000","1106.84000000"]],"a":[]}},{"timeToSleep":2011,"data":{"e":"depthUpdate","E":1672243039760,"s":"TORNBUSD","U":113356483,"u":113356484,"b":[["4.21000000","1320.24000000"],["4.11000000","423.37000000"]],"a":[]}},{"timeToSleep":1055,"data":{"e":"depthUpdate","E":1672243040760,"s":"TORNBUSD","U":113356485,"u":113356485,"b":[["4.15000000","1438.78000000"]],"a":[]}},{"timeToSleep":2014,"data":{"e":"depthUpdate","E":1672243042760,"s":"TORNBUSD","U":113356486,"u":113356486,"b":[["4.13000000","304.65000000"]],"a":[]}},{"timeToSleep":956,"data":{"e":"depthUpdate","E":1672243043760,"s":"TORNBUSD","U":113356487,"u":113356487,"b":[],"a":[["10.00000000","5767.48000000"]]}},{"timeToSleep":3995,"data":{"e":"depthUpdate","E":1672243047760,"s":"TORNBUSD","U":113356488,"u":113356488,"b":[],"a":[["21.00000000","4722.68000000"]]}},{"timeToSleep":969,"data":{"e":"depthUpdate","E":1672243048761,"s":"TORNBUSD","U":113356489,"u":113356489,"b":[["4.25000000","579.73000000"]],"a":[]}},{"timeToSleep":1072,"data":{"e":"depthUpdate","E":1672243049761,"s":"TORNBUSD","U":113356490,"u":113356490,"b":[],"a":[["5.00000000","5760.78000000"]]}},{"timeToSleep":1018,"data":{"e":"depthUpdate","E":1672243050762,"s":"TORNBUSD","U":113356491,"u":113356492,"b":[["4.32000000","119.06000000"],["4.24000000","464.34000000"]],"a":[]}},{"timeToSleep":990,"data":{"e":"depthUpdate","E":1672243051761,"s":"TORNBUSD","U":113356493,"u":113356514,"b":[["4.32000000","0.00000000"],["4.20000000","8471.37000000"],["4.18000000","1268.36000000"],["4.15000000","1392.29000000"],["4.14000000","244.28000000"],["4.13000000","426.26000000"],["4.12000000","1822.01000000"],["4.11000000","376.43000000"],["4.09000000","66.25000000"],["4.08000000","172.84000000"],["4.06000000","908.31000000"],["4.03000000","568.27000000"]],"a":[["4.33000000","469.46000000"],["4.35000000","457.13000000"]]}},{"timeToSleep":968,"data":{"e":"depthUpdate","E":1672243052761,"s":"TORNBUSD","U":113356515,"u":113356518,"b":[["4.19000000","383.85000000"],["4.16000000","332.56000000"],["4.00000000","25524.79000000"],["3.98000000","957.77000000"]],"a":[]}},{"timeToSleep":1024,"data":{"e":"depthUpdate","E":1672243053762,"s":"TORNBUSD","U":113356519,"u":113356523,"b":[["4.23000000","906.35000000"],["4.22000000","1263.04000000"],["4.20000000","8535.72000000"],["4.19000000","454.73000000"]],"a":[]}},{"timeToSleep":933,"data":{"e":"depthUpdate","E":1672243054763,"s":"TORNBUSD","U":113356524,"u":113356527,"b":[["4.15000000","1308.80000000"],["4.12000000","1906.11000000"]],"a":[]}},{"timeToSleep":1077,"data":{"e":"depthUpdate","E":1672243055762,"s":"TORNBUSD","U":113356528,"u":113356528,"b":[],"a":[["4.33000000","445.67000000"]]}},{"timeToSleep":1997,"data":{"e":"depthUpdate","E":1672243057761,"s":"TORNBUSD","U":113356529,"u":113356530,"b":[["4.08000000","111.68000000"]],"a":[["5.22000000","32.07000000"]]}},{"timeToSleep":2012,"data":{"e":"depthUpdate","E":1672243059761,"s":"TORNBUSD","U":113356531,"u":113356534,"b":[["4.18000000","1172.84000000"],["4.16000000","428.54000000"],["4.08000000","172.84000000"],["4.03000000","520.40000000"]],"a":[]}},{"timeToSleep":975,"data":{"e":"depthUpdate","E":1672243060761,"s":"TORNBUSD","U":113356535,"u":113356536,"b":[],"a":[["4.32000000","47.19000000"],["4.33000000","422.27000000"]]}},{"timeToSleep":934,"data":{"e":"depthUpdate","E":1672243061761,"s":"TORNBUSD","U":113356537,"u":113356539,"b":[["4.20000000","8832.81000000"],["4.13000000","379.19000000"],["4.03000000","568.67000000"]],"a":[]}},{"timeToSleep":1001,"data":{"e":"depthUpdate","E":1672243062761,"s":"TORNBUSD","U":113356540,"u":113356542,"b":[["4.31000000","291.56000000"]],"a":[["4.32000000","0.00000000"],["4.33000000","432.27000000"]]}},{"timeToSleep":3999,"data":{"e":"depthUpdate","E":1672243066761,"s":"TORNBUSD","U":113356543,"u":113356544,"b":[["4.30000000","729.58000000"],["4.16000000","261.96000000"]],"a":[]}},{"timeToSleep":1108,"data":{"e":"depthUpdate","E":1672243067762,"s":"TORNBUSD","U":113356545,"u":113356545,"b":[],"a":[["4.71000000","311.03000000"]]}},{"timeToSleep":981,"data":{"e":"depthUpdate","E":1672243068762,"s":"TORNBUSD","U":113356546,"u":113356550,"b":[["4.31000000","281.65000000"],["4.16000000","429.93000000"],["3.75000000","270.68000000"]],"a":[["4.33000000","441.43000000"]]}},{"timeToSleep":959,"data":{"e":"depthUpdate","E":1672243069762,"s":"TORNBUSD","U":113356551,"u":113356554,"b":[["4.17000000","180.32000000"],["4.15000000","1200.58000000"],["4.13000000","487.90000000"],["4.06000000","860.79000000"]],"a":[]}},{"timeToSleep":1057,"data":{"e":"depthUpdate","E":1672243070762,"s":"TORNBUSD","U":113356555,"u":113356555,"b":[],"a":[["4.50000000","947.90000000"]]}},{"timeToSleep":990,"data":{"e":"depthUpdate","E":1672243071762,"s":"TORNBUSD","U":113356556,"u":113356560,"b":[["4.31000000","212.75000000"],["4.16000000","465.92000000"],["4.06000000","908.71000000"]],"a":[["4.32000000","60.80000000"],["4.33000000","431.43000000"]]}},{"timeToSleep":1953,"data":{"e":"depthUpdate","E":1672243073762,"s":"TORNBUSD","U":113356561,"u":113356561,"b":[["4.20000000","8743.69000000"]],"a":[]}},{"timeToSleep":2039,"data":{"e":"depthUpdate","E":1672243075762,"s":"TORNBUSD","U":113356562,"u":113356562,"b":[["4.17000000","270.09000000"]],"a":[]}},{"timeToSleep":2916,"data":{"e":"depthUpdate","E":1672243078762,"s":"TORNBUSD","U":113356563,"u":113356585,"b":[["4.31000000","0.00000000"],["4.30000000","258.03000000"],["4.27000000","158.92000000"],["4.25000000","594.53000000"],["4.23000000","764.76000000"],["4.21000000","1247.93000000"],["4.20000000","8736.09000000"],["4.19000000","667.37000000"],["4.17000000","275.22000000"],["4.15000000","1203.09000000"],["4.13000000","441.19000000"],["4.12000000","1952.94000000"]],"a":[["4.32000000","84.60000000"],["4.33000000","510.65000000"],["4.35000000","488.00000000"]]}},{"timeToSleep":998,"data":{"e":"depthUpdate","E":1672243079762,"s":"TORNBUSD","U":113356586,"u":113356590,"b":[["4.16000000","409.63000000"],["4.14000000","300.84000000"],["4.06000000","900.91000000"]],"a":[["4.33000000","514.00000000"],["10.00000000","5743.69000000"]]}},{"timeToSleep":3050,"data":{"e":"depthUpdate","E":1672243082762,"s":"TORNBUSD","U":113356591,"u":113356591,"b":[],"a":[["4.33000000","451.77000000"]]}},{"timeToSleep":2047,"data":{"e":"depthUpdate","E":1672243084762,"s":"TORNBUSD","U":113356592,"u":113356593,"b":[["4.30000000","199.50000000"],["4.26000000","1055.40000000"]],"a":[]}},{"timeToSleep":1009,"data":{"e":"depthUpdate","E":1672243085763,"s":"TORNBUSD","U":113356594,"u":113356594,"b":[["4.26000000","1050.40000000"]],"a":[]}},{"timeToSleep":939,"data":{"e":"depthUpdate","E":1672243086763,"s":"TORNBUSD","U":113356595,"u":113356597,"b":[["4.30000000","204.50000000"]],"a":[["4.32000000","146.83000000"],["4.99000000","7883.62000000"]]}},{"timeToSleep":1023,"data":{"e":"depthUpdate","E":1672243087763,"s":"TORNBUSD","U":113356598,"u":113356598,"b":[],"a":[["5.40000000","3050.19000000"]]}},{"timeToSleep":1025,"data":{"e":"depthUpdate","E":1672243088763,"s":"TORNBUSD","U":113356599,"u":113356599,"b":[["4.30000000","199.50000000"]],"a":[]}},{"timeToSleep":1013,"data":{"e":"depthUpdate","E":1672243089763,"s":"TORNBUSD","U":113356600,"u":113356600,"b":[],"a":[["4.32000000","141.83000000"]]}},{"timeToSleep":3895,"data":{"e":"depthUpdate","E":1672243093763,"s":"TORNBUSD","U":113356601,"u":113356661,"b":[["4.30000000","0.00000000"],["4.29000000","77.27000000"],["4.24000000","290.73000000"],["4.23000000","986.40000000"],["4.22000000","1379.60000000"],["4.21000000","1306.21000000"],["4.20000000","8666.65000000"],["4.18000000","1156.84000000"],["4.17000000","345.16000000"],["4.16000000","286.86000000"],["4.14000000","336.70000000"],["4.13000000","276.44000000"],["4.12000000","1937.72000000"],["4.11000000","548.88000000"],["4.10000000","1340.07000000"],["4.09000000","61.76000000"],["4.08000000","123.81000000"],["4.07000000","314.56000000"],["4.06000000","852.75000000"],["4.05000000","1770.63000000"],["4.04000000","415.31000000"],["3.96000000","23.34000000"],["3.93000000","1477.59000000"]],"a":[["4.31000000","21.78000000"],["4.32000000","179.84000000"],["4.33000000","450.96000000"],["4.97000000","111.80000000"]]}},{"timeToSleep":1005,"data":{"e":"depthUpdate","E":1672243094763,"s":"TORNBUSD","U":113356662,"u":113356665,"b":[["4.29000000","72.35000000"],["4.13000000","252.27000000"],["4.10000000","1364.21000000"],["4.00000000","27445.86000000"]],"a":[]}},{"timeToSleep":1049,"data":{"e":"depthUpdate","E":1672243095763,"s":"TORNBUSD","U":113356666,"u":113356669,"b":[["4.18000000","896.32000000"],["4.17000000","393.00000000"],["4.16000000","548.63000000"],["4.13000000","236.21000000"]],"a":[]}},{"timeToSleep":947,"data":{"e":"depthUpdate","E":1672243096763,"s":"TORNBUSD","U":113356670,"u":113356670,"b":[],"a":[["4.33000000","434.38000000"]]}},{"timeToSleep":1103,"data":{"e":"depthUpdate","E":1672243097765,"s":"TORNBUSD","U":113356671,"u":113356673,"b":[["4.22000000","1527.58000000"],["4.13000000","252.40000000"]],"a":[]}},{"timeToSleep":931,"data":{"e":"depthUpdate","E":1672243098763,"s":"TORNBUSD","U":113356674,"u":113356674,"b":[["4.22000000","1601.53000000"]],"a":[]}},{"timeToSleep":988,"data":{"e":"depthUpdate","E":1672243099763,"s":"TORNBUSD","U":113356675,"u":113356676,"b":[["4.28000000","1581.50000000"]],"a":[["4.35000000","490.40000000"]]}},{"timeToSleep":1047,"data":{"e":"depthUpdate","E":1672243100763,"s":"TORNBUSD","U":113356677,"u":113356678,"b":[["4.29000000","66.65000000"],["4.22000000","1675.48000000"]],"a":[]}},{"timeToSleep":988,"data":{"e":"depthUpdate","E":1672243101763,"s":"TORNBUSD","U":113356679,"u":113356687,"b":[["4.26000000","982.54000000"],["4.25000000","583.25000000"],["4.23000000","1054.26000000"]],"a":[["4.31000000","31.78000000"],["4.32000000","439.08000000"]]}},{"timeToSleep":1057,"data":{"e":"depthUpdate","E":1672243102763,"s":"TORNBUSD","U":113356688,"u":113356689,"b":[],"a":[["4.31000000","50.05000000"],["4.32000000","401.07000000"]]}},{"timeToSleep":2888,"data":{"e":"depthUpdate","E":1672243105765,"s":"TORNBUSD","U":113356690,"u":113356714,"b":[["4.29000000","0.00000000"],["4.28000000","980.50000000"],["4.25000000","579.73000000"],["4.23000000","1057.79000000"],["4.21000000","1165.12000000"],["4.20000000","8602.30000000"],["4.19000000","596.49000000"],["4.17000000","671.47000000"],["4.16000000","284.68000000"],["4.15000000","722.01000000"],["4.13000000","516.07000000"],["4.12000000","2418.30000000"],["4.11000000","473.61000000"],["4.10000000","1411.27000000"],["4.09000000","90.23000000"],["4.08000000","76.52000000"],["4.05000000","1818.27000000"],["4.03000000","491.27000000"],["4.00000000","27523.19000000"]],"a":[]}},{"timeToSleep":1067,"data":{"e":"depthUpdate","E":1672243106763,"s":"TORNBUSD","U":113356715,"u":113356724,"b":[["4.15000000","719.50000000"],["4.14000000","280.14000000"],["4.13000000","518.59000000"],["4.12000000","2415.06000000"],["4.06000000","812.68000000"],["3.98000000","629.18000000"],["3.95000000","1348.67000000"]],"a":[["4.31000000","119.55000000"],["4.33000000","364.88000000"]]}},{"timeToSleep":972,"data":{"e":"depthUpdate","E":1672243107764,"s":"TORNBUSD","U":113356725,"u":113356731,"b":[["4.22000000","1667.22000000"],["4.19000000","525.61000000"],["4.12000000","2391.03000000"],["4.09000000","174.95000000"],["4.03000000","531.64000000"]],"a":[["9.66000000","0.00000000"]]}},{"timeToSleep":1030,"data":{"e":"depthUpdate","E":1672243108764,"s":"TORNBUSD","U":113356732,"u":113356732,"b":[["4.16000000","356.07000000"]],"a":[]}},{"timeToSleep":1017,"data":{"e":"depthUpdate","E":1672243109763,"s":"TORNBUSD","U":113356733,"u":113356735,"b":[["4.26000000","998.94000000"]],"a":[["4.31000000","129.45000000"],["4.38000000","436.79000000"]]}},{"timeToSleep":1018,"data":{"e":"depthUpdate","E":1672243110764,"s":"TORNBUSD","U":113356736,"u":113356741,"b":[["4.28000000","893.46000000"],["4.26000000","1087.95000000"],["4.06000000","837.26000000"]],"a":[]}},{"timeToSleep":1023,"data":{"e":"depthUpdate","E":1672243111764,"s":"TORNBUSD","U":113356742,"u":113356743,"b":[["4.16000000","284.68000000"]],"a":[["4.34000000","430.43000000"]]}},{"timeToSleep":936,"data":{"e":"depthUpdate","E":1672243112764,"s":"TORNBUSD","U":113356744,"u":113356744,"b":[["4.24000000","274.18000000"]],"a":[]}},{"timeToSleep":938,"data":{"e":"depthUpdate","E":1672243113764,"s":"TORNBUSD","U":113356745,"u":113356746,"b":[["4.16000000","356.66000000"]],"a":[["4.32000000","417.65000000"]]}},{"timeToSleep":999,"data":{"e":"depthUpdate","E":1672243114764,"s":"TORNBUSD","U":113356747,"u":113356747,"b":[["4.23000000","1074.37000000"]],"a":[]}},{"timeToSleep":999,"data":{"e":"depthUpdate","E":1672243115764,"s":"TORNBUSD","U":113356748,"u":113356748,"b":[["4.17000000","623.63000000"]],"a":[]}},{"timeToSleep":1999,"data":{"e":"depthUpdate","E":1672243117764,"s":"TORNBUSD","U":113356749,"u":113356749,"b":[["4.28000000","872.34000000"]],"a":[]}},{"timeToSleep":1001,"data":{"e":"depthUpdate","E":1672243118764,"s":"TORNBUSD","U":113356750,"u":113356751,"b":[["4.28000000","840.44000000"],["3.89000000","96.69000000"]],"a":[]}},{"timeToSleep":3000,"data":{"e":"depthUpdate","E":1672243121764,"s":"TORNBUSD","U":113356752,"u":113356755,"b":[["4.28000000","805.40000000"],["4.23000000","995.81000000"]],"a":[["4.31000000","307.92000000"],["4.33000000","205.87000000"]]}},{"timeToSleep":1000,"data":{"e":"depthUpdate","E":1672243122764,"s":"TORNBUSD","U":113356756,"u":113356761,"b":[["4.26000000","1059.84000000"],["4.22000000","1745.97000000"],["4.12000000","2383.47000000"],["4.05000000","1825.83000000"],["3.15000000","625.21000000"]],"a":[["5.26000000","7.01000000"]]}},{"timeToSleep":999,"data":{"e":"depthUpdate","E":1672243123764,"s":"TORNBUSD","U":113356762,"u":113356765,"b":[["4.28000000","767.39000000"]],"a":[["6.57000000","5.41000000"],["8.21000000","39.41000000"],["8.49000000","382.74000000"]]}},{"timeToSleep":1003,"data":{"e":"depthUpdate","E":1672243124764,"s":"TORNBUSD","U":113356766,"u":113356769,"b":[["4.28000000","817.74000000"],["4.12000000","2379.71000000"],["4.05000000","1829.59000000"]],"a":[["4.35000000","505.41000000"]]}},{"timeToSleep":1007,"data":{"e":"depthUpdate","E":1672243125764,"s":"TORNBUSD","U":113356770,"u":113356773,"b":[["4.29000000","17.81000000"],["4.22000000","1245.97000000"]],"a":[["4.31000000","238.42000000"],["4.32000000","487.15000000"]]}},{"timeToSleep":994,"data":{"e":"depthUpdate","E":1672243126764,"s":"TORNBUSD","U":113356774,"u":113356779,"b":[["4.28000000","821.65000000"],["4.22000000","1167.22000000"],["4.21000000","1244.05000000"],["4.13000000","565.66000000"]],"a":[["4.34000000","437.52000000"],["10.00000000","5767.48000000"]]}},{"timeToSleep":1001,"data":{"e":"depthUpdate","E":1672243127764,"s":"TORNBUSD","U":113356780,"u":113356780,"b":[],"a":[["4.43000000","4166.14000000"]]}},{"timeToSleep":999,"data":{"e":"depthUpdate","E":1672243128764,"s":"TORNBUSD","U":113356781,"u":113356781,"b":[],"a":[["4.39000000","532.58000000"]]}},{"timeToSleep":998,"data":{"e":"depthUpdate","E":1672243129764,"s":"TORNBUSD","U":113356782,"u":113356787,"b":[["4.29000000","0.00000000"],["4.28000000","776.34000000"],["4.21000000","1235.05000000"]],"a":[["4.31000000","312.92000000"],["4.32000000","417.65000000"]]}},{"timeToSleep":1024,"data":{"e":"depthUpdate","E":1672243130766,"s":"TORNBUSD","U":113356788,"u":113356789,"b":[["4.22000000","1245.97000000"]],"a":[["7.97000000","1070.27000000"]]}},{"timeToSleep":3976,"data":{"e":"depthUpdate","E":1672243134765,"s":"TORNBUSD","U":113356790,"u":113356790,"b":[["4.09000000","114.44000000"]],"a":[]}},{"timeToSleep":1000,"data":{"e":"depthUpdate","E":1672243135765,"s":"TORNBUSD","U":113356791,"u":113356791,"b":[["4.24000000","280.71000000"]],"a":[]}},{"timeToSleep":1016,"data":{"e":"depthUpdate","E":1672243136765,"s":"TORNBUSD","U":113356792,"u":113356795,"b":[["4.12000000","2346.42000000"],["4.05000000","1862.88000000"]],"a":[["4.32000000","355.42000000"],["10.34000000","0.00000000"]]}},{"timeToSleep":982,"data":{"e":"depthUpdate","E":1672243137765,"s":"TORNBUSD","U":113356796,"u":113356802,"b":[["4.29000000","4.39000000"],["4.28000000","782.87000000"],["4.24000000","274.18000000"],["4.00000000","25602.12000000"]],"a":[["4.31000000","238.49000000"],["4.32000000","424.92000000"]]}},{"timeToSleep":1001,"data":{"e":"depthUpdate","E":1672243138765,"s":"TORNBUSD","U":113356803,"u":113356809,"b":[["4.13000000","674.38000000"],["4.12000000","2302.34000000"],["4.11000000","364.39000000"],["4.05000000","3804.31000000"]],"a":[["4.39000000","549.42000000"],["4.41000000","72.22000000"]]}},{"timeToSleep":1000,"data":{"e":"depthUpdate","E":1672243139765,"s":"TORNBUSD","U":113356810,"u":113356816,"b":[["4.29000000","10.92000000"],["4.28000000","776.34000000"],["4.24000000","774.18000000"],["4.23000000","848.05000000"],["4.12000000","2278.47000000"],["4.05000000","3828.18000000"]],"a":[]}},{"timeToSleep":1004,"data":{"e":"depthUpdate","E":1672243140766,"s":"TORNBUSD","U":113356817,"u":113356866,"b":[["4.29000000","0.00000000"],["4.28000000","0.00000000"],["4.27000000","0.00000000"],["4.20000000","8305.21000000"],["4.19000000","383.85000000"],["4.18000000","1038.42000000"],["4.17000000","615.98000000"],["4.14000000","251.99000000"],["4.13000000","565.66000000"],["4.12000000","2314.51000000"],["4.10000000","1288.75000000"],["4.09000000","199.97000000"],["4.08000000","199.64000000"],["4.07000000","267.16000000"],["4.05000000","3852.63000000"],["4.04000000","325.24000000"],["4.02000000","143.00000000"],["4.01000000","360.08000000"],["3.93000000","1339.05000000"],["3.90000000","5117.44000000"]],"a":[["4.27000000","798.59000000"],["4.29000000","34.80000000"],["4.30000000","166.79000000"],["4.31000000","202.53000000"],["4.32000000","379.12000000"],["4.33000000","211.28000000"],["4.44000000","321.06000000"],["4.61000000","151.11000000"]]}},{"timeToSleep":1019,"data":{"e":"depthUpdate","E":1672243141765,"s":"TORNBUSD","U":113356867,"u":113356904,"b":[["4.23000000","774.17000000"],["4.22000000","1167.22000000"],["4.21000000","1313.98000000"],["4.20000000","8233.91000000"],["4.18000000","896.32000000"],["4.17000000","402.32000000"],["4.16000000","237.67000000"],["4.15000000","934.19000000"],["4.13000000","898.73000000"],["4.11000000","366.92000000"],["4.10000000","1264.61000000"],["4.09000000","171.50000000"],["4.08000000","223.90000000"],["4.07000000","267.16000000"],["4.06000000","808.59000000"],["4.05000000","1955.28000000"],["4.04000000","224.19000000"],["4.03000000","560.52000000"],["4.01000000","490.92000000"],["4.00000000","27421.59000000"],["3.95000000","1451.56000000"]],"a":[["4.27000000","699.56000000"],["4.28000000","151.54000000"],["4.29000000","213.27000000"],["4.30000000","88.13000000"],["4.31000000","24.06000000"],["4.32000000","309.62000000"],["4.35000000","522.40000000"],["4.39000000","532.58000000"]]}},{"timeToSleep":977,"data":{"e":"depthUpdate","E":1672243142765,"s":"TORNBUSD","U":113356905,"u":113356913,"b":[["4.13000000","895.93000000"],["4.10000000","1267.43000000"],["4.08000000","211.77000000"],["4.05000000","1967.50000000"]],"a":[["4.27000000","30.28000000"],["4.29000000","223.27000000"],["4.40000000","1021.14000000"]]}},{"timeToSleep":999,"data":{"e":"depthUpdate","E":1672243143765,"s":"TORNBUSD","U":113356914,"u":113356918,"b":[["4.23000000","848.05000000"],["4.12000000","2257.68000000"],["4.10000000","1324.54000000"]],"a":[["4.29000000","241.54000000"],["4.32000000","293.04000000"]]}},{"timeToSleep":1002,"data":{"e":"depthUpdate","E":1672243144765,"s":"TORNBUSD","U":113356919,"u":113356919,"b":[["4.22000000","1093.19000000"]],"a":[]}},{"timeToSleep":1000,"data":{"e":"depthUpdate","E":1672243145765,"s":"TORNBUSD","U":113356920,"u":113356958,"b":[["4.26000000","371.71000000"],["4.23000000","844.52000000"],["4.22000000","902.68000000"],["4.21000000","1189.32000000"],["4.18000000","1142.80000000"],["4.17000000","332.38000000"],["4.14000000","322.41000000"],["4.13000000","711.95000000"],["4.11000000","535.53000000"],["4.08000000","199.48000000"],["4.07000000","295.77000000"],["4.00000000","27392.49000000"]],"a":[["4.28000000","238.75000000"],["4.29000000","217.66000000"],["4.30000000","18.63000000"],["4.40000000","1024.11000000"],["4.44000000","297.50000000"],["4.61000000","127.55000000"],["7.97000000","837.53000000"]]}},{"timeToSleep":999,"data":{"e":"depthUpdate","E":1672243146766,"s":"TORNBUSD","U":113356959,"u":113356963,"b":[["4.22000000","1376.61000000"],["4.16000000","94.89000000"],["4.12000000","2173.58000000"],["3.98000000","658.43000000"]],"a":[["4.28000000","257.02000000"]]}},{"timeToSleep":1003,"data":{"e":"depthUpdate","E":1672243147767,"s":"TORNBUSD","U":113356964,"u":113356965,"b":[["4.22000000","1450.64000000"],["4.16000000","238.86000000"]],"a":[]}},{"timeToSleep":998,"data":{"e":"depthUpdate","E":1672243148766,"s":"TORNBUSD","U":113356966,"u":113356969,"b":[["4.25000000","614.19000000"],["4.09000000","256.92000000"],["3.90000000","4977.83000000"]],"a":[["4.31000000","40.64000000"]]}},{"timeToSleep":1001,"data":{"e":"depthUpdate","E":1672243149768,"s":"TORNBUSD","U":113356970,"u":113356971,"b":[["4.21000000","1192.74000000"]],"a":[["4.27000000","22.65000000"]]}},{"timeToSleep":1001,"data":{"e":"depthUpdate","E":1672243150767,"s":"TORNBUSD","U":113356972,"u":113356972,"b":[],"a":[["5.20000000","886.81000000"]]}},{"timeToSleep":999,"data":{"e":"depthUpdate","E":1672243151766,"s":"TORNBUSD","U":113356973,"u":113356973,"b":[],"a":[["4.47000000","461.92000000"]]}},{"timeToSleep":998,"data":{"e":"depthUpdate","E":1672243152766,"s":"TORNBUSD","U":113356974,"u":113356974,"b":[],"a":[["4.35000000","698.59000000"]]}},{"timeToSleep":1001,"data":{"e":"depthUpdate","E":1672243153766,"s":"TORNBUSD","U":113356975,"u":113356975,"b":[],"a":[["4.34000000","34.97000000"]]}},{"timeToSleep":1038,"data":{"e":"depthUpdate","E":1672243154766,"s":"TORNBUSD","U":113356976,"u":113356978,"b":[["4.26000000","368.90000000"],["4.18000000","1213.22000000"],["4.15000000","1234.86000000"]],"a":[]}},{"timeToSleep":963,"data":{"e":"depthUpdate","E":1672243155766,"s":"TORNBUSD","U":113356979,"u":113356980,"b":[["4.17000000","335.19000000"]],"a":[["10.00000000","6000.22000000"]]}},{"timeToSleep":1000,"data":{"e":"depthUpdate","E":1672243156766,"s":"TORNBUSD","U":113356981,"u":113356984,"b":[["4.26000000","373.90000000"],["4.22000000","1376.69000000"]],"a":[["4.35000000","707.14000000"]]}},{"timeToSleep":1030,"data":{"e":"depthUpdate","E":1672243157766,"s":"TORNBUSD","U":113356985,"u":113356986,"b":[["4.26000000","251.12000000"],["4.00000000","27396.23000000"]],"a":[]}},{"timeToSleep":971,"data":{"e":"depthUpdate","E":1672243158766,"s":"TORNBUSD","U":113356987,"u":113356989,"b":[["4.26000000","345.07000000"],["4.22000000","1302.74000000"]],"a":[["20.00000000","28282.71000000"]]}},{"timeToSleep":1004,"data":{"e":"depthUpdate","E":1672243159766,"s":"TORNBUSD","U":113356990,"u":113356992,"b":[["4.26000000","339.59000000"]],"a":[["4.44000000","368.64000000"],["4.45000000","726.32000000"]]}},{"timeToSleep":995,"data":{"e":"depthUpdate","E":1672243160767,"s":"TORNBUSD","U":113356993,"u":113356993,"b":[],"a":[["4.34000000","597.52000000"]]}},{"timeToSleep":1000,"data":{"e":"depthUpdate","E":1672243161766,"s":"TORNBUSD","U":113356994,"u":113356998,"b":[["4.26000000","265.86000000"],["4.23000000","827.94000000"],["4.10000000","1374.54000000"],["4.07000000","357.08000000"]],"a":[["4.38000000","420.78000000"]]}},{"timeToSleep":1005,"data":{"e":"depthUpdate","E":1672243162767,"s":"TORNBUSD","U":113356999,"u":113357002,"b":[["4.26000000","153.34000000"],["4.12000000","2137.54000000"]],"a":[["4.35000000","723.26000000"]]}},{"timeToSleep":995,"data":{"e":"depthUpdate","E":1672243163766,"s":"TORNBUSD","U":113357003,"u":113357003,"b":[["4.22000000","1319.36000000"]],"a":[]}},{"timeToSleep":998,"data":{"e":"depthUpdate","E":1672243164766,"s":"TORNBUSD","U":113357004,"u":113357006,"b":[["4.11000000","571.96000000"],["4.08000000","152.19000000"],["4.04000000","176.43000000"]],"a":[]}},{"timeToSleep":1006,"data":{"e":"depthUpdate","E":1672243165767,"s":"TORNBUSD","U":113357007,"u":113357008,"b":[],"a":[["4.29000000","246.94000000"],["4.35000000","739.65000000"]]}},{"timeToSleep":994,"data":{"e":"depthUpdate","E":1672243166767,"s":"TORNBUSD","U":113357009,"u":113357015,"b":[["4.27000000","0.82000000"],["4.07000000","404.88000000"],["4.04000000","224.58000000"]],"a":[["4.27000000","0.00000000"],["4.28000000","105.48000000"],["4.29000000","68.47000000"],["4.30000000","164.52000000"],["4.31000000","220.99000000"]]}},{"timeToSleep":1004,"data":{"e":"depthUpdate","E":1672243167767,"s":"TORNBUSD","U":113357016,"u":113357033,"b":[["4.01000000","461.89000000"],["4.00000000","25475.16000000"],["3.98000000","629.18000000"]],"a":[["4.28000000","35.98000000"],["4.29000000","6